Workbook

Sheet Resumen
A1: Noesis — Modelo economico
A2: Modelo vivo: las celdas azules son entradas editables y el resto son formulas. Las cifras proceden del analisis interno fechado el 15/07/2026 con fuentes citadas en la hoja Fuentes. Lo que el repositorio no acredita esta en la hoja Datos_Pendientes y NO se ha estimado.
A4: Catalogo adoptado
A5: Concepto | B5: Autonomo | C5: Negocio | D5: Premium | E5: Unidad | F5: Nota
A6: Precio mensual | B6: =Supuestos!B7 -> 29 | C6: =Supuestos!C7 -> 49 | D6: =Supuestos!D7 -> 99 | E6: €/mes + IVA | F6: Catalogo adoptado tras el analisis
A7: Precio anual | B7: 319 | C7: 539 | D7: 1089 | E7: €/ano + IVA | F7: Cobra 11 meses, da acceso 12
A8: Mix de clientes supuesto | B8: =Supuestos!B8 -> 0.55 | C8: =Supuestos!C8 -> 0.35 | D8: =Supuestos!D8 -> 0.1 | E8: % | F8: Hipotesis de escala, a recalibrar
A10: Resultado por plan (modelo Noesis)
A11: Metrica | B11: Autonomo | C11: Negocio | D11: Premium | E11: Unidad | F11: Nota
A12: COGS software | B12: =Unit_Economics!E13 -> 1.4821361 | C12: =Unit_Economics!F13 -> 3.0440186 | D12: =Unit_Economics!G13 -> 18.46973 | E12: €/mes | F12: Stripe, WhatsApp, IA, voz, almacenamiento
A13: Margen bruto | B13: =Unit_Economics!E14 -> 0.94889186 | C13: =Unit_Economics!F14 -> 0.93787717 | D13: =Unit_Economics!G14 -> 0.81343707 | E13: % | F13: Sobre precio neto
A14: Contribucion | B14: =Unit_Economics!E18 -> 21.406197 | C14: =Unit_Economics!F18 -> 35.469315 | D14: =Unit_Economics!G18 -> 57.543603 | E14: €/mes | F14: Ya descuenta soporte, onboarding y fijo
A15: Margen de contribucion | B15: =Unit_Economics!E19 -> 0.73814473 | C15: =Unit_Economics!F19 -> 0.72386357 | D15: =Unit_Economics!G19 -> 0.58124852 | E15: % | F15: Sin CAC
A17: Punto de equilibrio
A18: Metrica | B18: Valor | E18: Unidad | F18: Nota
A19: Contribucion media ponderada | B19: =Unit_Economics!E18*Supuestos!B8+Unit_Economics!F18*Supuestos!C8+Unit_Economics!G18*Supuestos!D8 -> 29.942029 | E19: €/cuenta/mes | F19: Segun el mix de la hoja Supuestos
A20: Opex fijo mensual | B20: =Supuestos!B41 -> 500 | E20: €/mes | F20: HIPOTESIS: 3.500 €. Sustituir por el gasto real
A21: Cuentas para equilibrio | B21: =IF(B19>0,ROUNDUP(B20/B19,0),"") -> 17 | E21: cuentas | F21: Con el opex real este numero cambia
A22: Ingreso mensual en equilibrio | B22: =IF(B21<>"",B21*(Supuestos!B7*Supuestos!B8+Supuestos!C7*Supuestos!C8+Supuestos!D7*Supuestos!D8),"") -> 731 | E22: €/mes | F22: Sin IVA
A24: Aviso
A25: Ninguna cifra de este libro es un resultado observado. Son supuestos de planificacion fechados que el piloto debe recalibrar. El opex fijo, los sueldos, el reparto societario y el CAC no constan en el repositorio: estan en Datos_Pendientes sin rellenar.

Sheet Calculadora
A1: Calculadora: escribe cuantos clientes tienes
A2: Cambia solo las tres celdas naranjas de abajo y todo el libro responde: ingresos, cada linea de coste, resultado mensual y cuanto falta para el equilibrio. Es la hoja para jugar; el resto explica de donde sale cada cifra.
A4: 1 · Cuantos clientes de cada plan
A5: Plan | B5: Clientes | C5: Precio | D5: Ingreso mensual | E5: Ingreso anual | F5: Nota
A6: Autonomo | B6: 0 | C6: =Supuestos!B7 -> 29 | D6: =B6*C6 -> 0 | E6: =D6*12 -> 0
A7: Negocio | B7: 0 | C7: =Supuestos!C7 -> 49 | D7: =B7*C7 -> 0 | E7: =D7*12 -> 0
A8: Premium | B8: 0 | C8: =Supuestos!D7 -> 99 | D8: =B8*C8 -> 0 | E8: =D8*12 -> 0
A9: TOTAL | B9: =SUM(B6:B8) -> 0 | D9: =SUM(D6:D8) -> 0 | E9: =SUM(E6:E8) -> 0 | F9: Ingreso sin IVA
A11: 2 · Costes variables: lo que cuesta servirlos
A12: Concepto | B12: Autonomo | C12: Negocio | D12: Premium | E12: Total | F12: € por cliente
A13: Comisiones de Stripe | B13: =$B$6*Unit_Economics!E6 -> 0 | C13: =$B$7*Unit_Economics!F6 -> 0 | D13: =$B$8*Unit_Economics!G6 -> 0 | E13: =SUM(B13:D13) -> 0 | F13: =IFERROR(E13/$B$9,"")
A14: WhatsApp (plantillas) | B14: =$B$6*Unit_Economics!E7 -> 0 | C14: =$B$7*Unit_Economics!F7 -> 0 | D14: =$B$8*Unit_Economics!G7 -> 0 | E14: =SUM(B14:D14) -> 0 | F14: =IFERROR(E14/$B$9,"")
A15: IA avanzada | B15: =$B$6*Unit_Economics!E8 -> 0 | C15: =$B$7*Unit_Economics!F8 -> 0 | D15: =$B$8*Unit_Economics!G8 -> 0 | E15: =SUM(B15:D15) -> 0 | F15: =IFERROR(E15/$B$9,"")
A16: Transcripcion de voz | B16: =$B$6*Unit_Economics!E9 -> 0 | C16: =$B$7*Unit_Economics!F9 -> 0 | D16: =$B$8*Unit_Economics!G9 -> 0 | E16: =SUM(B16:D16) -> 0 | F16: =IFERROR(E16/$B$9,"")
A17: Extraccion de documentos | B17: =$B$6*Unit_Economics!E10 -> 0 | C17: =$B$7*Unit_Economics!F10 -> 0 | D17: =$B$8*Unit_Economics!G10 -> 0 | E17: =SUM(B17:D17) -> 0 | F17: =IFERROR(E17/$B$9,"")
A18: Almacenamiento | B18: =$B$6*Unit_Economics!E11 -> 0 | C18: =$B$7*Unit_Economics!F11 -> 0 | D18: =$B$8*Unit_Economics!G11 -> 0 | E18: =SUM(B18:D18) -> 0 | F18: =IFERROR(E18/$B$9,"")
A19: Voz telefonica (Premium) | B19: =$B$6*Unit_Economics!E12 -> 0 | C19: =$B$7*Unit_Economics!F12 -> 0 | D19: =$B$8*Unit_Economics!G12 -> 0 | E19: =SUM(B19:D19) -> 0 | F19: =IFERROR(E19/$B$9,"")
A20: TOTAL COSTES VARIABLES | B20: =SUM(B13:B19) -> 0 | C20: =SUM(C13:C19) -> 0 | D20: =SUM(D13:D19) -> 0 | E20: =SUM(E13:E19) -> 0 | F20: =IFERROR(E20/$B$9,"")
A22: 3 · Coste de atender a esos clientes
A23: Concepto | B23: Autonomo | C23: Negocio | D23: Premium | E23: Total | F23: € por cliente
A24: Soporte humano | B24: =$B$6*Unit_Economics!E15 -> 0 | C24: =$B$7*Unit_Economics!F15 -> 0 | D24: =$B$8*Unit_Economics!G15 -> 0 | E24: =SUM(B24:D24) -> 0 | F24: =IFERROR(E24/$B$9,"")
A25: Onboarding amortizado | B25: =$B$6*Unit_Economics!E16 -> 0 | C25: =$B$7*Unit_Economics!F16 -> 0 | D25: =$B$8*Unit_Economics!G16 -> 0 | E25: =SUM(B25:D25) -> 0 | F25: =IFERROR(E25/$B$9,"")
A26: TOTAL SERVICIO | B26: =SUM(B24:B25) -> 0 | C26: =SUM(C24:C25) -> 0 | D26: =SUM(D24:D25) -> 0 | E26: =SUM(E24:E25) -> 0
A28: 4 · Costes fijos: no dependen de cuantos clientes tengas
A29: Concepto | B29: Importe mensual | E29: Anual | F29: Nota
A30: Plataforma (app, correo, copias) | B30: =Supuestos!B40 -> 7 | E30: =B30*12 -> 84 | F30: Escala poco con el numero de cuentas
A31: Opex fijo (founder, legal, herramientas) | B31: =Supuestos!B41 -> 500 | E31: =B31*12 -> 6000 | F31: SUPUESTO de 3.500 €. Sustituir por el real de Datos_Pendientes
A32: Publicidad | B32: =IFERROR(Ads_Captacion!B6,0) | E32: =B32*12 -> 0 | F32: Lo que escribas en la hoja Ads_Captacion
A33: TOTAL FIJOS | B33: =SUM(B30:B32) -> 507 | E33: =SUM(E30:E32) -> 6084
A35: 5 · Resultado
A36: Metrica | B36: Mensual | E36: Anual | F36: Nota
A37: Ingreso | B37: =D9 -> 0 | E37: =B37*12 -> 0 | F37: Sin IVA
A38: (-) Costes variables | B38: =-E20 -> 0 | E38: =B38*12 -> 0 | F38: Escalan con cada cliente nuevo
A39: =Margen bruto -> #ERROR! | B39: =B37+B38 -> 0 | E39: =B39*12 -> 0 | F39: Lo que queda para pagar estructura
A40: (-) Coste de servicio | B40: =-E26 -> 0 | E40: =B40*12 -> 0 | F40: Soporte y onboarding
A41: (-) Costes fijos | B41: =-B33 -> -507 | E41: =B41*12 -> -6084 | F41: Plataforma, opex y publicidad
A42: =RESULTADO -> #NAME? | B42: =B39+B40+B41 -> -507 | E42: =B42*12 -> -6084 | F42: Lo que gana o pierde la empresa cada mes
A43: Margen sobre ingreso | B43: =IFERROR(B42/B37,"")
A45: 6 · Cuanto falta para el equilibrio
A46: Metrica | B46: Valor | E46: Unidad | F46: Nota
...

Sheet Supuestos
A1: Supuestos
A2: Celdas azules = entradas editables. Cambiar aqui recalcula todo el libro. Cada driver lleva fecha y fuente; los marcados como Supuesto no estan verificados.
A4: Supuestos por plan
A5: Driver | B5: Autonomo | C5: Negocio | D5: Premium | E5: Unidad | F5: Fuente / criterio
A6: Precio actual | B6: 29 | C6: 39 | D6: 79 | E6: €/mes + IVA | F6: Catalogo anterior
A7: Precio adoptado | B7: 29 | C7: 49 | D7: 99 | E7: €/mes + IVA | F7: Recomendacion de unit economics
A8: Mix de clientes | B8: 0.55 | C8: 0.35 | D8: 0.1 | E8: % | F8: Supuesto de escala
A9: Creditos avanzados incluidos | B9: 75 | C9: 300 | D9: 1500 | E9: acciones/mes | F9: Catalogo actual
A10: Uso esperado del limite | B10: 0.35 | C10: 0.4 | D10: 0.25 | E10: % | F10: Supuesto conservador
A11: Resolucion por cerebro interno | B11: 0.6 | C11: 0.6 | D11: 0.6 | E11: % | F11: Objetivo tras piloto
A12: WhatsApp utility enviados | B12: 30 | C12: 80 | D12: 200 | E12: mensajes/mes | F12: Supuesto operativo
A13: WhatsApp service recibidos | B13: 100 | C13: 300 | D13: 1000 | E13: mensajes/mes | F13: Gratis hoy; sensibilidad futura
A14: Audio transcrito | B14: 15 | C14: 60 | D14: 200 | E14: min/mes | F14: Supuesto operativo
A15: Documentos procesados | B15: 15 | C15: 50 | D15: 200 | E15: docs/mes | F15: Supuesto operativo
A16: Documentos que escalan fuera | B16: 0.2 | C16: 0.2 | D16: 0.2 | E16: % | F16: OCR local primero
A17: Almacenamiento | B17: 0.25 | C17: 1 | D17: 3 | E17: GB/cuenta | F17: Supuesto operativo
... A20: Onboarding inicial | B20: 30 | C20: 60 | D20: 120 | E20: min/cuenta | F20: Amortizado en 12 meses
A23: Supuestos globales
A24: Driver | B24: Valor | C24: Unidad | D24: Fecha | E24: Fuente | F24: Nota
A25: EUR por USD | B25: 0.87680842 | C25: EUR/USD | D25: 14/07/2026 | E25: ECB | F25: 1 EUR = 1,1405 USD
A26: Stripe Payments | B26: 0.015 | C26: % ingreso | D26: 15/07/2026 | E26: Stripe | F26: Tarjeta EEE estandar
A27: Stripe Billing | B27: 0.007 | C27: % ingreso | D27: 15/07/2026 | E27: Stripe | F27: Pago por uso
A28: Stripe fijo | B28: 0.25 | C28: €/transaccion | D28: 15/07/2026 | E28: Stripe | F28: Una renovacion mensual
A29: WhatsApp utility Espana | B29: 0.0166 | C29: €/mensaje | D29: 15/07/2026 | E29: Meta / rate card | F29: Mensaje entregado
A30: WhatsApp service futuro | B30: 0.0166 | C30: €/mensaje | D30: 15/07/2026 | E30: Sensibilidad | F30: Actualmente 0 €
A31: Haiku 4.5 por interaccion | B31: 0.014 | C31: USD/interaccion | D31: 15/07/2026 | E31: Anthropic | F31: 8k input + 1,2k output
A32: Qwen3 32B por interaccion | B32: 0.003028 | C32: USD/interaccion | D32: 15/07/2026 | E32: Groq | F32: Mismo supuesto de tokens
A33: Peso Qwen en fallback | B33: 0.8 | C33: % | D33: 15/07/2026 | E33: Arquitectura hibrida | F33: Resto Haiku
A34: Whisper Turbo | B34: 0.04 | C34: USD/hora | D34: 15/07/2026 | E34: Groq | F34: Solo transcripcion
A35: Extraccion externa documento | B35: 0.012 | C35: €/documento | D35: 15/07/2026 | E35: Supuesto | F35: Validar con corpus real
A36: Object storage | B36: 0.015 | C36: USD/GB-mes | D36: 15/07/2026 | E36: Railway | F36: Sin egress
... A44: Cuentas para repartir fijo | B44: 100 | C44: cuentas | D44: 15/07/2026 | E44: Escenario base | F44: Solo unit economics por plan

Sheet Unit_Economics
A1: Unit economics por plan
A2: Escenario base hibrido: cerebro interno resuelve el 60%; del resto, 80% Qwen y 20% Haiku. Columnas B-D = catalogo anterior (29/39/79). Columnas E-G = catalogo adoptado (29/49/99).
A4: Metrica | B4: Autonomo ant. | C4: Negocio ant. | D4: Premium ant. | E4: Autonomo adop. | F4: Negocio adop. | G4: Premium adop. | H4: Unidad
A5: Precio neto | B5: =Supuestos!B$6 -> 29 | C5: =Supuestos!C$6 -> 39 | D5: =Supuestos!D$6 -> 79 | E5: =Supuestos!B$7 -> 29 | F5: =Supuestos!C$7 -> 49 | G5: =Supuestos!D$7 -> 99 | H5: €/mes
A6: Stripe | B6: =B5*(Supuestos!$B$26+Supuestos!$B$27)+Supuestos!$B$28 -> 0.888 | C6: =C5*(Supuestos!$B$26+Supuestos!$B$27)+Supuestos!$B$28 -> 1.108 | D6: =D5*(Supuestos!$B$26+Supuestos!$B$27)+Supuestos!$B$28 -> 1.988 | E6: =E5*(Supuestos!$B$26+Supuestos!$B$27)+Supuestos!$B$28 -> 0.888 | F6: =F5*(Supuestos!$B$26+Supuestos!$B$27)+Supuestos!$B$28 -> 1.328 | G6: =G5*(Supuestos!$B$26+Supuestos!$B$27)+Supuestos!$B$28 -> 2.428 | H6: €/mes
A7: WhatsApp utility | B7: =Supuestos!B$12*Supuestos!$B$29 -> 0.498 | C7: =Supuestos!C$12*Supuestos!$B$29 -> 1.328 | D7: =Supuestos!D$12*Supuestos!$B$29 -> 3.32 | E7: =Supuestos!B$12*Supuestos!$B$29 -> 0.498 | F7: =Supuestos!C$12*Supuestos!$B$29 -> 1.328 | G7: =Supuestos!D$12*Supuestos!$B$29 -> 3.32 | H7: €/mes
A8: IA avanzada | B8: =Supuestos!B$9*Supuestos!B$10*(1-Supuestos!B$11)*(Supuestos!$B$33*Supuestos!$B$32+(1-Supuestos!$B$33)*Supuestos!$B$31)*Supuestos!$B$25 -> 0.048079965 | C8: =Supuestos!C$9*Supuestos!C$10*(1-Supuestos!C$11)*(Supuestos!$B$33*Supuestos!$B$32+(1-Supuestos!$B$33)*Supuestos!$B$31)*Supuestos!$B$25 -> 0.21979413 | D8: =Supuestos!D$9*Supuestos!D$10*(1-Supuestos!D$11)*(Supuestos!$B$33*Supuestos!$B$32+(1-Supuestos!$B$33)*Supuestos!$B$31)*Supuestos!$B$25 -> 0.68685664 | E8: =Supuestos!B$9*Supuestos!B$10*(1-Supuestos!B$11)*(Supuestos!$B$33*Supuestos!$B$32+(1-Supuestos!$B$33)*Supuestos!$B$31)*Supuestos!$B$25 -> 0.048079965 | F8: =Supuestos!C$9*Supuestos!C$10*(1-Supuestos!C$11)*(Supuestos!$B$33*Supuestos!$B$32+(1-Supuestos!$B$33)*Supuestos!$B$31)*Supuestos!$B$25 -> 0.21979413 | G8: =Supuestos!D$9*Supuestos!D$10*(1-Supuestos!D$11)*(Supuestos!$B$33*Supuestos!$B$32+(1-Supuestos!$B$33)*Supuestos!$B$31)*Supuestos!$B$25 -> 0.68685664 | H8: €/mes
A9: Transcripcion | B9: =Supuestos!B$14/60*Supuestos!$B$34*Supuestos!$B$25 -> 0.0087680842 | C9: =Supuestos!C$14/60*Supuestos!$B$34*Supuestos!$B$25 -> 0.035072337 | D9: =Supuestos!D$14/60*Supuestos!$B$34*Supuestos!$B$25 -> 0.11690779 | E9: =Supuestos!B$14/60*Supuestos!$B$34*Supuestos!$B$25 -> 0.0087680842 | F9: =Supuestos!C$14/60*Supuestos!$B$34*Supuestos!$B$25 -> 0.035072337 | G9: =Supuestos!D$14/60*Supuestos!$B$34*Supuestos!$B$25 -> 0.11690779 | H9: €/mes
A10: Extraccion externa | B10: =Supuestos!B$15*Supuestos!B$16*Supuestos!$B$35 -> 0.036 | C10: =Supuestos!C$15*Supuestos!C$16*Supuestos!$B$35 -> 0.12 | D10: =Supuestos!D$15*Supuestos!D$16*Supuestos!$B$35 -> 0.48 | E10: =Supuestos!B$15*Supuestos!B$16*Supuestos!$B$35 -> 0.036 | F10: =Supuestos!C$15*Supuestos!C$16*Supuestos!$B$35 -> 0.12 | G10: =Supuestos!D$15*Supuestos!D$16*Supuestos!$B$35 -> 0.48 | H10: €/mes
A11: Almacenamiento | B11: =Supuestos!B$17*Supuestos!$B$36*Supuestos!$B$25 -> 0.0032880316 | C11: =Supuestos!C$17*Supuestos!$B$36*Supuestos!$B$25 -> 0.013152126 | D11: =Supuestos!D$17*Supuestos!$B$36*Supuestos!$B$25 -> 0.039456379 | E11: =Supuestos!B$17*Supuestos!$B$36*Supuestos!$B$25 -> 0.0032880316 | F11: =Supuestos!C$17*Supuestos!$B$36*Supuestos!$B$25 -> 0.013152126 | G11: =Supuestos!D$17*Supuestos!$B$36*Supuestos!$B$25 -> 0.039456379 | H11: €/mes
A12: Voz Premium | B12: =IF(Supuestos!B$18>0,Supuestos!B$18*Supuestos!$B$37*Supuestos!$B$25+Supuestos!$B$38*Supuestos!$B$25,0) -> 0 | C12: =IF(Supuestos!C$18>0,Supuestos!C$18*Supuestos!$B$37*Supuestos!$B$25+Supuestos!$B$38*Supuestos!$B$25,0) -> 0 | D12: =IF(Supuestos!D$18>0,Supuestos!D$18*Supuestos!$B$37*Supuestos!$B$25+Supuestos!$B$38*Supuestos!$B$25,0) -> 11.398509 | E12: =IF(Supuestos!B$18>0,Supuestos!B$18*Supuestos!$B$37*Supuestos!$B$25+Supuestos!$B$38*Supuestos!$B$25,0) -> 0 | F12: =IF(Supuestos!C$18>0,Supuestos!C$18*Supuestos!$B$37*Supuestos!$B$25+Supuestos!$B$38*Supuestos!$B$25,0) -> 0 | G12: =IF(Supuestos!D$18>0,Supuestos!D$18*Supuestos!$B$37*Supuestos!$B$25+Supuestos!$B$38*Supuestos!$B$25,0) -> 11.398509 | H12: €/mes
A13: COGS software | B13: =SUM(B6:B12) -> 1.4821361 | C13: =SUM(C6:C12) -> 2.8240186 | D13: =SUM(D6:D12) -> 18.02973 | E13: =SUM(E6:E12) -> 1.4821361 | F13: =SUM(F6:F12) -> 3.0440186 | G13: =SUM(G6:G12) -> 18.46973 | H13: €/mes
A14: Margen bruto software | B14: =(B5-B13)/B5 -> 0.94889186 | C14: =(C5-C13)/C5 -> 0.92758927 | D14: =(D5-D13)/D5 -> 0.77177557 | E14: =(E5-E13)/E5 -> 0.94889186 | F14: =(F5-F13)/F5 -> 0.93787717 | G14: =(G5-G13)/G5 -> 0.81343707 | H14: %
A15: Soporte humano | B15: =Supuestos!B$19/60*Supuestos!$B$39 -> 5 | C15: =Supuestos!C$19/60*Supuestos!$B$39 -> 8.3333333 | D15: =Supuestos!D$19/60*Supuestos!$B$39 -> 18.75 | E15: =Supuestos!B$19/60*Supuestos!$B$39 -> 5 | F15: =Supuestos!C$19/60*Supuestos!$B$39 -> 8.3333333 | G15: =Supuestos!D$19/60*Supuestos!$B$39 -> 18.75 | H15: €/mes
A16: Onboarding amortizado | B16: =Supuestos!B$20/60*Supuestos!$B$39/12 -> 1.0416667 | C16: =Supuestos!C$20/60*Supuestos!$B$39/12 -> 2.0833333 | D16: =Supuestos!D$20/60*Supuestos!$B$39/12 -> 4.1666667 | E16: =Supuestos!B$20/60*Supuestos!$B$39/12 -> 1.0416667 | F16: =Supuestos!C$20/60*Supuestos!$B$39/12 -> 2.0833333 | G16: =Supuestos!D$20/60*Supuestos!$B$39/12 -> 4.1666667 | H16: €/mes
A17: Fijo asignado | B17: =Supuestos!$B$40/Supuestos!$B$44 -> 0.07 | C17: =Supuestos!$B$40/Supuestos!$B$44 -> 0.07 | D17: =Supuestos!$B$40/Supuestos!$B$44 -> 0.07 | E17: =Supuestos!$B$40/Supuestos!$B$44 -> 0.07 | F17: =Supuestos!$B$40/Supuestos!$B$44 -> 0.07 | G17: =Supuestos!$B$40/Supuestos!$B$44 -> 0.07 | H17: €/mes
A18: Contribucion | B18: =B5-B13-B15-B16-B17 -> 21.406197 | C18: =C5-C13-C15-C16-C17 -> 25.689315 | D18: =D5-D13-D15-D16-D17 -> 37.983603 | E18: =E5-E13-E15-E16-E17 -> 21.406197 | F18: =F5-F13-F15-F16-F17 -> 35.469315 | G18: =G5-G13-G15-G16-G17 -> 57.543603 | H18: €/mes
A19: Margen de contribucion | B19: =B18/B5 -> 0.73814473 | C19: =C18/C5 -> 0.65870038 | D19: =D18/D5 -> 0.4808051 | E19: =E18/E5 -> 0.73814473 | F19: =F18/F5 -> 0.72386357 | G19: =G18/G5 -> 0.58124852 | H19: %
A20: Ingreso si el precio incluyera IVA | B20: =B5/(1+Supuestos!$B$43) -> 23.966942 | C20: =C5/(1+Supuestos!$B$43) -> 32.231405 | D20: =D5/(1+Supuestos!$B$43) -> 65.289256 | E20: =E5/(1+Supuestos!$B$43) -> 23.966942 | F20: =F5/(1+Supuestos!$B$43) -> 40.495868 | G20: =G5/(1+Supuestos!$B$43) -> 81.818182 | H20: €/mes
A21: Contribucion si incluyera IVA | B21: =B20-B13-B15-B16-B17 -> 16.373139 | C21: =C20-C13-C15-C16-C17 -> 18.92072 | D21: =D20-D13-D15-D16-D17 -> 24.272859 | E21: =E20-E13-E15-E16-E17 -> 16.373139 | F21: =F20-F13-F15-F16-F17 -> 26.965183 | G21: =G20-G13-G15-G16-G17 -> 40.361785 | H21: €/mes
A22: IA: 100% de creditos con Haiku | B22: =Supuestos!B$9*Supuestos!$B$31*Supuestos!$B$25 -> 0.92064884 | C22: =Supuestos!C$9*Supuestos!$B$31*Supuestos!$B$25 -> 3.6825954 | D22: =Supuestos!D$9*Supuestos!$B$31*Supuestos!$B$25 -> 18.412977 | E22: =Supuestos!B$9*Supuestos!$B$31*Supuestos!$B$25 -> 0.92064884 | F22: =Supuestos!C$9*Supuestos!$B$31*Supuestos!$B$25 -> 3.6825954 | G22: =Supuestos!D$9*Supuestos!$B$31*Supuestos!$B$25 -> 18.412977 | H22: €/mes
A23: Margen bruto en peor caso IA | B23: =(B5-(B13-B8+B22))/B5 -> 0.91880328 | C23: =(C5-(C13-C8+C22))/C5 -> 0.83879949 | D23: =(D5-(D13-D8+D22))/D5 -> 0.5473943 | E23: =(E5-(E13-E8+E22))/E5 -> 0.91880328 | F23: =(F5-(F13-F8+F22))/F5 -> 0.86720776 | G23: =(G5-(G13-G8+G22))/G5 -> 0.63438535 | H23: %

Sheet Hipotesis_Externa
A1: Hipotesis de coste del documento externo
A2: Reproduccion literal de la tabla recibida. Su propio encabezado la titula 'Calculo (Hipotesis)': no lleva fuente ni fecha, y aplica el mismo coste a todos los planes independientemente del uso.
A4: Tabla recibida
A5: Concepto de gasto | B5: Calculo (hipotesis) | C5: Coste mensual/usuario | F5: Contraste con el modelo Noesis
A6: API de Meta (WhatsApp) | B6: 150 mensajes enviados x 0,0166 € | C6: =150*Supuestos!B29 -> 2.49 | F6: El modelo Noesis usa 30/80/200 mensajes segun plan, no 150 fijos
A7: Inteligencia Artificial (LLM) | B7: 150 procesamientos x ~0,02 € | C7: 3 | F7: El modelo Noesis estima 0,05/0,22/0,69 €: el cerebro interno resuelve el 60%
A8: Servidor y base de datos | B8: Prorrateo basico por usuario | C8: 1 | F8: El modelo Noesis reparte 65 € de plataforma entre las cuentas activas
A9: COSTE TOTAL VARIABLE | B9: Mensual por usuario | C9: =SUM(C6:C8) -> 6.49
A11: Margen resultante con esta hipotesis
A12: Plan | B12: Precio adoptado | C12: Coste variable | D12: Contribucion bruta | E12: Margen | F12: Nota
A13: Autonomo | B13: =Supuestos!B7 -> 29 | C13: =$C$9 -> 6.49 | D13: =B13-C13 -> 22.51 | E13: =D13/B13 -> 0.7762069 | F13: No descuenta soporte, onboarding ni fijo: no es comparable con la contribucion de Unit_Economics
A14: Negocio | B14: =Supuestos!C7 -> 49 | C14: =$C$9 -> 6.49 | D14: =B14-C14 -> 42.51 | E14: =D14/B14 -> 0.86755102 | F14: No descuenta soporte, onboarding ni fijo: no es comparable con la contribucion de Unit_Economics
A15: Premium | B15: =Supuestos!D7 -> 99 | C15: =$C$9 -> 6.49 | D15: =B15-C15 -> 92.51 | E15: =D15/B15 -> 0.93444444 | F15: No descuenta soporte, onboarding ni fijo: no es comparable con la contribucion de Unit_Economics

Sheet Comparador
A1: Comparador de escenarios de coste
A2: Que pasa con el margen si el coste real por usuario resulta ser el del documento externo en lugar del estimado internamente. Solo compara COGS variable, para que la base sea la misma.
A4: COGS software por plan
A5: Escenario | B5: Autonomo | C5: Negocio | D5: Premium
A6: Modelo Noesis (con fuentes) | B6: =Unit_Economics!E13 -> 1.4821361 | C6: =Unit_Economics!F13 -> 3.0440186 | D6: =Unit_Economics!G13 -> 18.46973
A7: Hipotesis externa | B7: =Hipotesis_Externa!$C$9 -> 6.49 | C7: =Hipotesis_Externa!$C$9 -> 6.49 | D7: =Hipotesis_Externa!$C$9 -> 6.49
A8: Diferencia | B8: =B7-B6 -> 5.0078639 | C8: =C7-C6 -> 3.4459814 | D8: =D7-D6 -> -11.97973
A9: Multiplicador | B9: =IF(B6>0,B7/B6,"") -> 4.3788152 | C9: =IF(C6>0,C7/C6,"") -> 2.1320501 | D9: =IF(D6>0,D7/D6,"") -> 0.35138575
A11: Margen bruto comparado
A12: Escenario | B12: Autonomo | C12: Negocio | D12: Premium
A13: Modelo Noesis | B13: =Unit_Economics!E14 -> 0.94889186 | C13: =Unit_Economics!F14 -> 0.93787717 | D13: =Unit_Economics!G14 -> 0.81343707
A14: Hipotesis externa | B14: =(Supuestos!B7-Hipotesis_Externa!$C$9)/Supuestos!B7 -> 0.7762069 | C14: =(Supuestos!C7-Hipotesis_Externa!$C$9)/Supuestos!C7 -> 0.86755102 | D14: =(Supuestos!D7-Hipotesis_Externa!$C$9)/Supuestos!D7 -> 0.93444444
A15: Puntos perdidos | B15: =B13-B14 -> 0.17268496 | C15: =C13-C14 -> 0.070326151 | D15: =D13-D14 -> -0.12100738
A17: Como leerlo
A18: La hipotesis externa aplica un coste plano por usuario, asi que penaliza mucho al plan barato y apenas al caro, mientras que el modelo Noesis escala el coste con el uso incluido en cada plan. Si el piloto midiera un consumo parecido al de la hipotesis, el plan Autonomo seria el primero en sufrir. Es el escenario que conviene vigilar durante los primeros 30 dias.

Sheet Anual_vs_Mensual
A1: Tarifa anual frente a mensual
A2: El anual cobra 11 meses y da acceso 12: un descuento real del 8,3%. Se eligio este nivel, y no dos meses gratis, para proteger el margen de Premium mientras el piloto no ha medido voz y soporte reales.
A4: Plan | B4: Mensual | C4: Cobro anual | D4: Equivalente/mes | E4: Ahorro/ano | F4: Contribucion mensual | G4: Margen contribucion
A5: Autonomo | B5: =Supuestos!B7 -> 29 | C5: 319 | D5: =C5/12 -> 26.583333 | E5: =B5*12-C5 -> 29 | F5: 18.69 | G5: =F5/D5 -> 0.7030721
A6: Negocio | B6: =Supuestos!C7 -> 49 | C6: 539 | D6: =C6/12 -> 44.916667 | E6: =B6*12-C6 -> 49 | F6: 31.12 | G6: =F6/D6 -> 0.69283859
A7: Premium | B7: =Supuestos!D7 -> 99 | C7: 1089 | D7: =C7/12 -> 90.75 | E7: =B7*12-C7 -> 99 | F7: 49.12 | G7: =F7/D7 -> 0.54126722
A9: La contribucion anual es una estimacion del analisis del 15/07/2026 con el mismo uso, soporte y onboarding del escenario base y una sola comision Stripe prorrateada. El anual mejora caja y reduce comisiones, pero obliga a reservar capacidad de servicio durante doce meses.

Sheet Escala_Breakeven
A1: Escala y punto de equilibrio
A2: Ingreso y resultado segun numero de cuentas, con el mix y el opex de la hoja Supuestos. El opex de 3.500 € es una hipotesis de planificacion, NO el gasto contable actual.
A4: Cuentas | B4: Ingreso mensual | C4: Contribucion total | D4: Opex fijo | E4: Resultado | F4: Margen sobre ingreso
A5: 10 | B5: =A5*(Supuestos!$B$7*Supuestos!$B$8+Supuestos!$C$7*Supuestos!$C$8+Supuestos!$D$7*Supuestos!$D$8) -> 430 | C5: =A5*(Unit_Economics!$E$18*Supuestos!$B$8+Unit_Economics!$F$18*Supuestos!$C$8+Unit_Economics!$G$18*Supuestos!$D$8) -> 299.42029 | D5: =Supuestos!$B$41 -> 500 | E5: =C5-D5 -> -200.57971 | F5: =IF(B5>0,E5/B5,"") -> -0.46646444
A6: 25 | B6: =A6*(Supuestos!$B$7*Supuestos!$B$8+Supuestos!$C$7*Supuestos!$C$8+Supuestos!$D$7*Supuestos!$D$8) -> 1075 | C6: =A6*(Unit_Economics!$E$18*Supuestos!$B$8+Unit_Economics!$F$18*Supuestos!$C$8+Unit_Economics!$G$18*Supuestos!$D$8) -> 748.55072 | D6: =Supuestos!$B$41 -> 500 | E6: =C6-D6 -> 248.55072 | F6: =IF(B6>0,E6/B6,"") -> 0.23120998
A7: 50 | B7: =A7*(Supuestos!$B$7*Supuestos!$B$8+Supuestos!$C$7*Supuestos!$C$8+Supuestos!$D$7*Supuestos!$D$8) -> 2150 | C7: =A7*(Unit_Economics!$E$18*Supuestos!$B$8+Unit_Economics!$F$18*Supuestos!$C$8+Unit_Economics!$G$18*Supuestos!$D$8) -> 1497.1014 | D7: =Supuestos!$B$41 -> 500 | E7: =C7-D7 -> 997.10145 | F7: =IF(B7>0,E7/B7,"") -> 0.46376812
A8: 100 | B8: =A8*(Supuestos!$B$7*Supuestos!$B$8+Supuestos!$C$7*Supuestos!$C$8+Supuestos!$D$7*Supuestos!$D$8) -> 4300 | C8: =A8*(Unit_Economics!$E$18*Supuestos!$B$8+Unit_Economics!$F$18*Supuestos!$C$8+Unit_Economics!$G$18*Supuestos!$D$8) -> 2994.2029 | D8: =Supuestos!$B$41 -> 500 | E8: =C8-D8 -> 2494.2029 | F8: =IF(B8>0,E8/B8,"") -> 0.58004719
A9: 120 | B9: =A9*(Supuestos!$B$7*Supuestos!$B$8+Supuestos!$C$7*Supuestos!$C$8+Supuestos!$D$7*Supuestos!$D$8) -> 5160 | C9: =A9*(Unit_Economics!$E$18*Supuestos!$B$8+Unit_Economics!$F$18*Supuestos!$C$8+Unit_Economics!$G$18*Supuestos!$D$8) -> 3593.0435 | D9: =Supuestos!$B$41 -> 500 | E9: =C9-D9 -> 3093.0435 | F9: =IF(B9>0,E9/B9,"") -> 0.59942703
A10: 150 | B10: =A10*(Supuestos!$B$7*Supuestos!$B$8+Supuestos!$C$7*Supuestos!$C$8+Supuestos!$D$7*Supuestos!$D$8) -> 6450 | C10: =A10*(Unit_Economics!$E$18*Supuestos!$B$8+Unit_Economics!$F$18*Supuestos!$C$8+Unit_Economics!$G$18*Supuestos!$D$8) -> 4491.3043 | D10: =Supuestos!$B$41 -> 500 | E10: =C10-D10 -> 3991.3043 | F10: =IF(B10>0,E10/B10,"") -> 0.61880687
A11: 200 | B11: =A11*(Supuestos!$B$7*Supuestos!$B$8+Supuestos!$C$7*Supuestos!$C$8+Supuestos!$D$7*Supuestos!$D$8) -> 8600 | C11: =A11*(Unit_Economics!$E$18*Supuestos!$B$8+Unit_Economics!$F$18*Supuestos!$C$8+Unit_Economics!$G$18*Supuestos!$D$8) -> 5988.4058 | D11: =Supuestos!$B$41 -> 500 | E11: =C11-D11 -> 5488.4058 | F11: =IF(B11>0,E11/B11,"") -> 0.63818672
A12: 300 | B12: =A12*(Supuestos!$B$7*Supuestos!$B$8+Supuestos!$C$7*Supuestos!$C$8+Supuestos!$D$7*Supuestos!$D$8) -> 12900 | C12: =A12*(Unit_Economics!$E$18*Supuestos!$B$8+Unit_Economics!$F$18*Supuestos!$C$8+Unit_Economics!$G$18*Supuestos!$D$8) -> 8982.6087 | D12: =Supuestos!$B$41 -> 500 | E12: =C12-D12 -> 8482.6087 | F12: =IF(B12>0,E12/B12,"") -> 0.65756656
A13: 500 | B13: =A13*(Supuestos!$B$7*Supuestos!$B$8+Supuestos!$C$7*Supuestos!$C$8+Supuestos!$D$7*Supuestos!$D$8) -> 21500 | C13: =A13*(Unit_Economics!$E$18*Supuestos!$B$8+Unit_Economics!$F$18*Supuestos!$C$8+Unit_Economics!$G$18*Supuestos!$D$8) -> 14971.014 | D13: =Supuestos!$B$41 -> 500 | E13: =C13-D13 -> 14471.014 | F13: =IF(B13>0,E13/B13,"") -> 0.67307044
A14: 750 | B14: =A14*(Supuestos!$B$7*Supuestos!$B$8+Supuestos!$C$7*Supuestos!$C$8+Supuestos!$D$7*Supuestos!$D$8) -> 32250 | C14: =A14*(Unit_Economics!$E$18*Supuestos!$B$8+Unit_Economics!$F$18*Supuestos!$C$8+Unit_Economics!$G$18*Supuestos!$D$8) -> 22456.522 | D14: =Supuestos!$B$41 -> 500 | E14: =C14-D14 -> 21956.522 | F14: =IF(B14>0,E14/B14,"") -> 0.68082238
A15: 1000 | B15: =A15*(Supuestos!$B$7*Supuestos!$B$8+Supuestos!$C$7*Supuestos!$C$8+Supuestos!$D$7*Supuestos!$D$8) -> 43000 | C15: =A15*(Unit_Economics!$E$18*Supuestos!$B$8+Unit_Economics!$F$18*Supuestos!$C$8+Unit_Economics!$G$18*Supuestos!$D$8) -> 29942.029 | D15: =Supuestos!$B$41 -> 500 | E15: =C15-D15 -> 29442.029 | F15: =IF(B15>0,E15/B15,"") -> 0.68469835
A17: Punto de equilibrio exacto
A18: Cuentas necesarias | B18: =ROUNDUP(Supuestos!B41/(Unit_Economics!E18*Supuestos!B8+Unit_Economics!F18*Supuestos!C8+Unit_Economics!G18*Supuestos!D8),0) -> 17 | C18: Con el catalogo adoptado y el mix 55/35/10. El analisis del 15/07/2026 lo situo en unas 120 cuentas.
A20: Cuantos clientes de cada plan hacen falta
A21: Plan | B21: Mix | C21: Clientes | D21: Precio | E21: Ingreso mensual | F21: Contribucion mensual
A22: Autonomo | B22: =Supuestos!B8 -> 0.55 | C22: =ROUND($B$18*B22,0) -> 9 | D22: =Supuestos!B7 -> 29 | E22: =C22*D22 -> 261 | F22: =C22*Unit_Economics!E18 -> 192.65578
A23: Negocio | B23: =Supuestos!C8 -> 0.35 | C23: =ROUND($B$18*B23,0) -> 6 | D23: =Supuestos!C7 -> 49 | E23: =C23*D23 -> 294 | F23: =C23*Unit_Economics!F18 -> 212.81589
A24: Premium | B24: =Supuestos!D8 -> 0.1 | C24: =ROUND($B$18*B24,0) -> 2 | D24: =Supuestos!D7 -> 99 | E24: =C24*D24 -> 198 | F24: =C24*Unit_Economics!G18 -> 115.08721
A25: TOTAL | B25: =SUM(B22:B24) -> 1 | C25: =SUM(C22:C24) -> 17 | E25: =SUM(E22:E24) -> 753 | F25: =SUM(F22:F24) -> 520.55887
A27: Y si toda la cartera fuera de un solo plan
A28: Plan | B28: Contribucion/cliente | C28: Clientes necesarios | D28: Ingreso mensual
A29: Autonomo | B29: =Unit_Economics!E18 -> 21.406197 | C29: =IFERROR(ROUNDUP(Supuestos!$B$41/B29,0),"") -> 24 | D29: =IFERROR(C29*Supuestos!B7,"") -> 696
A30: Negocio | B30: =Unit_Economics!F18 -> 35.469315 | C30: =IFERROR(ROUNDUP(Supuestos!$B$41/B30,0),"") -> 15 | D30: =IFERROR(C30*Supuestos!C7,"") -> 735
A31: Premium | B31: =Unit_Economics!G18 -> 57.543603 | C31: =IFERROR(ROUNDUP(Supuestos!$B$41/B31,0),"") -> 9 | D31: =IFERROR(C31*Supuestos!D7,"") -> 891
A33: Leer las dos tablas juntas: la primera reparte el equilibrio segun el mix que esperas; la segunda dice cuantos clientes harian falta si solo vendieras un plan. La distancia entre ambas cifras es el valor real de vender el plan caro, y es el argumento para decidir a quien dedicar el esfuerzo comercial.

Sheet Ads_Captacion
A1: Publicidad y coste de captacion
A2: Gasto variable: la publicidad no escala con los clientes que ya tienes, sino con los que quieres captar. Las celdas naranjas estan VACIAS a proposito: ninguna cifra de embudo consta en el repositorio. En cuanto escribas presupuesto y conversiones, el resto se calcula solo.
A4: Entradas de campana
A5: Driver | B5: Valor | D5: Unidad | F5: Nota
A6: Presupuesto mensual de ads | D6: €/mes | F6: El gasto variable principal. Sin el, el resto no calcula
A7: Coste por clic | D7: €/clic | F7: Meta Ads y Google Ads dan medias distintas: usa la tuya
A8: Conversion clic -> lead | D8: % | F8: Visitas que dejan datos en Solicitar acceso
A9: Conversion lead -> prueba | D9: % | F9: Leads que activan la prueba de 14 dias
A10: Conversion prueba -> pago | D10: % | F10: El dato que mas mueve el CAC
A11: Churn mensual | D11: % | F11: Bajas sobre cartera. Necesario para el LTV
A12: Altas que vienen de ads | D12: % | F12: El resto llega por boca a boca y no cuesta ads
A14: Embudo resultante
A15: Metrica | B15: Valor | D15: Unidad | F15: Formula
A16: Clics al mes | B16: =IFERROR(B6/B7,"") | D16: clics | F16: Presupuesto / coste por clic
A17: Leads al mes | B17: =IFERROR(B16*B8,"") -> 0 | D17: leads | F17: Clics x conversion a lead
A18: Pruebas iniciadas | B18: =IFERROR(B17*B9,"") -> 0 | D18: pruebas | F18: Leads x conversion a prueba
A19: Clientes nuevos de ads | B19: =IFERROR(B18*B10,"") -> 0 | D19: clientes/mes | F19: Pruebas x conversion a pago
A20: Altas totales estimadas | B20: =IFERROR(IF(B12>0,B19/B12,B19),"") -> 0 | D20: clientes/mes | F20: Incluye las que no vienen de ads
A21: CAC real | B21: =IFERROR(B6/B19,"") | D21: €/cliente | F21: Presupuesto / clientes captados por ads
A22: CAC supuesto en el modelo | B22: =Supuestos!B42 -> 150 | D22: €/cliente | F22: 150 € sin validar, para contraste
A23: Desviacion frente al supuesto | B23: =IFERROR(B21-B22,"") -> -150 | D23: €/cliente | F23: Positivo = captar sale mas caro de lo previsto
A25: Salud de la captacion
A26: Metrica | B26: Valor | D26: Unidad | F26: Referencia habitual
A27: Contribucion media ponderada | B27: =Unit_Economics!E18*Supuestos!B8+Unit_Economics!F18*Supuestos!C8+Unit_Economics!G18*Supuestos!D8 -> 29.942029 | D27: €/mes | F27: La que ya calcula el modelo
A28: Meses para recuperar el CAC | B28: =IFERROR(B21/B27,"") -> 0 | D28: meses | F28: Por debajo de 12 se considera sano
A29: Vida media del cliente | B29: =IFERROR(1/B11,"") | D29: meses | F29: 1 / churn mensual
A30: LTV (contribucion x vida) | B30: =IFERROR(B27*B29,"") -> 0 | D30: € | F30: Sin descuento financiero
A31: LTV / CAC | B31: =IFERROR(B30/B21,"") | D31: veces | F31: Referencia SaaS: 3x o mas
A32: Veredicto | B32: =IF(B31="","Faltan datos",IF(AND(B31>=3,B28<=12),"Sano",IF(B31>=1,"Ajustado: revisar precio o embudo","Insostenible: cada cliente pierde dinero"))) -> Faltan datos | F32: Se calcula solo al rellenar las entradas
A34: Impacto de los ads en el punto de equilibrio
A35: Metrica | B35: Sin ads | C35: Con ads | D35: Unidad | F35: Nota
A36: Coste fijo mensual | B36: =Supuestos!B41 -> 500 | C36: =Supuestos!B41+IFERROR(B6,0) -> 500 | F36: El presupuesto de ads se suma al opex mientras dure la campana
A37: Clientes para equilibrio | B37: =IFERROR(ROUNDUP(B36/$B$27,0),"") -> 17 | C37: =IFERROR(ROUNDUP(C36/$B$27,0),"") -> 17 | F37: Con la contribucion media ponderada
A38: Clientes adicionales que exige el ads | C38: =IFERROR(C37-B37,"") -> 0 | F38: Los que la campana debe traer solo para pagarse
A39: Meses para conseguirlos | C39: =IFERROR(C38/B19,"") | F39: Al ritmo de captacion calculado arriba
A41: Por que los ads van en su propia hoja
A42: El resto del libro mide lo que cuesta SERVIR a un cliente que ya tienes. La publicidad mide lo que cuesta CONSEGUIRLO, y se comporta al reves: si cortas la campana manana, el gasto desaparece pero los clientes captados siguen pagando. Por eso no se mezcla con el COGS ni con el margen de contribucion: se trata como una inversion con un plazo de recuperacion, que es la fila 'Meses para recuperar el CAC'. Si ese plazo supera la vida media del cliente, la campana destruye valor aunque el margen por cuenta sea excelente.

Sheet Escenarios
A1: Escenarios de planificacion
A2: Tres futuros con los mismos costes unitarios y distinta velocidad comercial. El selector de la celda B5 alimenta la hoja PyG_Proyeccion. Las celdas naranjas estan vacias: la velocidad comercial es una decision del founder, no un dato del repositorio.
A5: Escenario activo | B5: Base | C5: Elige de la lista desplegable
A7: Palancas por escenario
A8: Palanca | B8: Pesimista | C8: Base | D8: Optimista | E8: Unidad | F8: Nota
A9: Altas netas mes 1 | C9: 4 | E9: clientes | F9: Base = el piloto de 3-5 comprometido en Tareas-vivas
A10: Crecimiento mensual de altas | E10: % | F10: PENDIENTE: depende del presupuesto de ads y del boca a boca
A11: Churn mensual | E11: % | F11: PENDIENTE: solo se sabra tras dos cierres del piloto
A12: Mix Autonomo | C12: 0.55 | E12: % | F12: Base = mix del analisis
A13: Mix Negocio | C13: 0.35 | E13: % | F13: Base = mix del analisis
A14: Mix Premium | C14: 0.1 | E14: % | F14: Base = mix del analisis
A15: Opex fijo mensual | C15: 3500 | E15: €/mes | F15: SUPUESTO hasta rellenar Datos_Pendientes
A16: Presupuesto de ads | E16: €/mes | F16: PENDIENTE: enlaza con la hoja Ads_Captacion
A19: Valores activos (los que usa la proyeccion)
A20: Palanca | B20: Valor activo | D20: Unidad
A21: Altas netas mes 1 | B21: =IF($B$5="Pesimista",B9,IF($B$5="Optimista",D9,C9)) -> 4 | D21: clientes
A22: Crecimiento mensual de altas | B22: =IF($B$5="Pesimista",B10,IF($B$5="Optimista",D10,C10)) | D22: %
A23: Churn mensual | B23: =IF($B$5="Pesimista",B11,IF($B$5="Optimista",D11,C11)) | D23: %
A24: Mix Autonomo | B24: =IF($B$5="Pesimista",B12,IF($B$5="Optimista",D12,C12)) -> 0.55 | D24: %
A25: Mix Negocio | B25: =IF($B$5="Pesimista",B13,IF($B$5="Optimista",D13,C13)) -> 0.35 | D25: %
A26: Mix Premium | B26: =IF($B$5="Pesimista",B14,IF($B$5="Optimista",D14,C14)) -> 0.1 | D26: %
A27: Opex fijo mensual | B27: =IF($B$5="Pesimista",B15,IF($B$5="Optimista",D15,C15)) -> 3500 | D27: €/mes
A28: Presupuesto de ads | B28: =IF($B$5="Pesimista",B16,IF($B$5="Optimista",D16,C16)) | D28: €/mes

Sheet PyG_Proyeccion
A1: Proyeccion a 24 meses
A2: Cuenta de resultados mensual y caja acumulada, gobernada por el escenario activo de la hoja Escenarios. Mientras el crecimiento y el churn esten vacios, la cartera se queda plana: es lo honesto, no un fallo.
A4: Mes | B4: Cartera inicio | C4: Altas | D4: Bajas | E4: Cartera fin | F4: MRR | G4: COGS | H4: Margen bruto | I4: Opex fijo | J4: Ads | K4: Resultado | L4: Caja acumulada | M4: ARR
A5: 0 | B5: 0 | C5: 0 | D5: 0 | E5: =B5+C5-D5 -> 0 | L5: =Datos_Pendientes!B15
A6: 1 | B6: =E5 -> 0 | C6: =IFERROR(ROUND(Escenarios!$B$21*(1+Escenarios!$B$22)^0,1),0) -> 4 | D6: =IFERROR(ROUND(B6*Escenarios!$B$23,1),0) -> 0 | E6: =B6+C6-D6 -> 4 | F6: =E6*(Supuestos!$B$7*Escenarios!$B$24+Supuestos!$C$7*Escenarios!$B$25+Supuestos!$D$7*Escenarios!$B$26) -> 172 | G6: =E6*(Unit_Economics!$E$13*Escenarios!$B$24+Unit_Economics!$F$13*Escenarios!$B$25+Unit_Economics!$G$13*Escenarios!$B$26) -> 14.910217 | H6: =F6-G6 -> 157.08978 | I6: =Escenarios!$B$27 -> 3500 | J6: =IFERROR(Escenarios!$B$28,0) | K6: =H6-I6-J6 -> -3342.9102 | L6: =L5+K6 -> -3342.9102 | M6: =F6*12 -> 2064
A7: 2 | B7: =E6 -> 4 | C7: =IFERROR(ROUND(Escenarios!$B$21*(1+Escenarios!$B$22)^1,1),0) -> 4 | D7: =IFERROR(ROUND(B7*Escenarios!$B$23,1),0) -> 0 | E7: =B7+C7-D7 -> 8 | F7: =E7*(Supuestos!$B$7*Escenarios!$B$24+Supuestos!$C$7*Escenarios!$B$25+Supuestos!$D$7*Escenarios!$B$26) -> 344 | G7: =E7*(Unit_Economics!$E$13*Escenarios!$B$24+Unit_Economics!$F$13*Escenarios!$B$25+Unit_Economics!$G$13*Escenarios!$B$26) -> 29.820435 | H7: =F7-G7 -> 314.17957 | I7: =Escenarios!$B$27 -> 3500 | J7: =IFERROR(Escenarios!$B$28,0) | K7: =H7-I7-J7 -> -3185.8204 | L7: =L6+K7 -> -6528.7307 | M7: =F7*12 -> 4128
A8: 3 | B8: =E7 -> 8 | C8: =IFERROR(ROUND(Escenarios!$B$21*(1+Escenarios!$B$22)^2,1),0) -> 4 | D8: =IFERROR(ROUND(B8*Escenarios!$B$23,1),0) -> 0 | E8: =B8+C8-D8 -> 12 | F8: =E8*(Supuestos!$B$7*Escenarios!$B$24+Supuestos!$C$7*Escenarios!$B$25+Supuestos!$D$7*Escenarios!$B$26) -> 516 | G8: =E8*(Unit_Economics!$E$13*Escenarios!$B$24+Unit_Economics!$F$13*Escenarios!$B$25+Unit_Economics!$G$13*Escenarios!$B$26) -> 44.730652 | H8: =F8-G8 -> 471.26935 | I8: =Escenarios!$B$27 -> 3500 | J8: =IFERROR(Escenarios!$B$28,0) | K8: =H8-I8-J8 -> -3028.7307 | L8: =L7+K8 -> -9557.4613 | M8: =F8*12 -> 6192
A9: 4 | B9: =E8 -> 12 | C9: =IFERROR(ROUND(Escenarios!$B$21*(1+Escenarios!$B$22)^3,1),0) -> 4 | D9: =IFERROR(ROUND(B9*Escenarios!$B$23,1),0) -> 0 | E9: =B9+C9-D9 -> 16 | F9: =E9*(Supuestos!$B$7*Escenarios!$B$24+Supuestos!$C$7*Escenarios!$B$25+Supuestos!$D$7*Escenarios!$B$26) -> 688 | G9: =E9*(Unit_Economics!$E$13*Escenarios!$B$24+Unit_Economics!$F$13*Escenarios!$B$25+Unit_Economics!$G$13*Escenarios!$B$26) -> 59.64087 | H9: =F9-G9 -> 628.35913 | I9: =Escenarios!$B$27 -> 3500 | J9: =IFERROR(Escenarios!$B$28,0) | K9: =H9-I9-J9 -> -2871.6409 | L9: =L8+K9 -> -12429.102 | M9: =F9*12 -> 8256
A10: 5 | B10: =E9 -> 16 | C10: =IFERROR(ROUND(Escenarios!$B$21*(1+Escenarios!$B$22)^4,1),0) -> 4 | D10: =IFERROR(ROUND(B10*Escenarios!$B$23,1),0) -> 0 | E10: =B10+C10-D10 -> 20 | F10: =E10*(Supuestos!$B$7*Escenarios!$B$24+Supuestos!$C$7*Escenarios!$B$25+Supuestos!$D$7*Escenarios!$B$26) -> 860 | G10: =E10*(Unit_Economics!$E$13*Escenarios!$B$24+Unit_Economics!$F$13*Escenarios!$B$25+Unit_Economics!$G$13*Escenarios!$B$26) -> 74.551087 | H10: =F10-G10 -> 785.44891 | I10: =Escenarios!$B$27 -> 3500 | J10: =IFERROR(Escenarios!$B$28,0) | K10: =H10-I10-J10 -> -2714.5511 | L10: =L9+K10 -> -15143.653 | M10: =F10*12 -> 10320
A11: 6 | B11: =E10 -> 20 | C11: =IFERROR(ROUND(Escenarios!$B$21*(1+Escenarios!$B$22)^5,1),0) -> 4 | D11: =IFERROR(ROUND(B11*Escenarios!$B$23,1),0) -> 0 | E11: =B11+C11-D11 -> 24 | F11: =E11*(Supuestos!$B$7*Escenarios!$B$24+Supuestos!$C$7*Escenarios!$B$25+Supuestos!$D$7*Escenarios!$B$26) -> 1032 | G11: =E11*(Unit_Economics!$E$13*Escenarios!$B$24+Unit_Economics!$F$13*Escenarios!$B$25+Unit_Economics!$G$13*Escenarios!$B$26) -> 89.461305 | H11: =F11-G11 -> 942.53869 | I11: =Escenarios!$B$27 -> 3500 | J11: =IFERROR(Escenarios!$B$28,0) | K11: =H11-I11-J11 -> -2557.4613 | L11: =L10+K11 -> -17701.115 | M11: =F11*12 -> 12384
A12: 7 | B12: =E11 -> 24 | C12: =IFERROR(ROUND(Escenarios!$B$21*(1+Escenarios!$B$22)^6,1),0) -> 4 | D12: =IFERROR(ROUND(B12*Escenarios!$B$23,1),0) -> 0 | E12: =B12+C12-D12 -> 28 | F12: =E12*(Supuestos!$B$7*Escenarios!$B$24+Supuestos!$C$7*Escenarios!$B$25+Supuestos!$D$7*Escenarios!$B$26) -> 1204 | G12: =E12*(Unit_Economics!$E$13*Escenarios!$B$24+Unit_Economics!$F$13*Escenarios!$B$25+Unit_Economics!$G$13*Escenarios!$B$26) -> 104.37152 | H12: =F12-G12 -> 1099.6285 | I12: =Escenarios!$B$27 -> 3500 | J12: =IFERROR(Escenarios!$B$28,0) | K12: =H12-I12-J12 -> -2400.3715 | L12: =L11+K12 -> -20101.486 | M12: =F12*12 -> 14448
A13: 8 | B13: =E12 -> 28 | C13: =IFERROR(ROUND(Escenarios!$B$21*(1+Escenarios!$B$22)^7,1),0) -> 4 | D13: =IFERROR(ROUND(B13*Escenarios!$B$23,1),0) -> 0 | E13: =B13+C13-D13 -> 32 | F13: =E13*(Supuestos!$B$7*Escenarios!$B$24+Supuestos!$C$7*Escenarios!$B$25+Supuestos!$D$7*Escenarios!$B$26) -> 1376 | G13: =E13*(Unit_Economics!$E$13*Escenarios!$B$24+Unit_Economics!$F$13*Escenarios!$B$25+Unit_Economics!$G$13*Escenarios!$B$26) -> 119.28174 | H13: =F13-G13 -> 1256.7183 | I13: =Escenarios!$B$27 -> 3500 | J13: =IFERROR(Escenarios!$B$28,0) | K13: =H13-I13-J13 -> -2243.2817 | L13: =L12+K13 -> -22344.768 | M13: =F13*12 -> 16512
A14: 9 | B14: =E13 -> 32 | C14: =IFERROR(ROUND(Escenarios!$B$21*(1+Escenarios!$B$22)^8,1),0) -> 4 | D14: =IFERROR(ROUND(B14*Escenarios!$B$23,1),0) -> 0 | E14: =B14+C14-D14 -> 36 | F14: =E14*(Supuestos!$B$7*Escenarios!$B$24+Supuestos!$C$7*Escenarios!$B$25+Supuestos!$D$7*Escenarios!$B$26) -> 1548 | G14: =E14*(Unit_Economics!$E$13*Escenarios!$B$24+Unit_Economics!$F$13*Escenarios!$B$25+Unit_Economics!$G$13*Escenarios!$B$26) -> 134.19196 | H14: =F14-G14 -> 1413.808 | I14: =Escenarios!$B$27 -> 3500 | J14: =IFERROR(Escenarios!$B$28,0) | K14: =H14-I14-J14 -> -2086.192 | L14: =L13+K14 -> -24430.96 | M14: =F14*12 -> 18576
A15: 10 | B15: =E14 -> 36 | C15: =IFERROR(ROUND(Escenarios!$B$21*(1+Escenarios!$B$22)^9,1),0) -> 4 | D15: =IFERROR(ROUND(B15*Escenarios!$B$23,1),0) -> 0 | E15: =B15+C15-D15 -> 40 | F15: =E15*(Supuestos!$B$7*Escenarios!$B$24+Supuestos!$C$7*Escenarios!$B$25+Supuestos!$D$7*Escenarios!$B$26) -> 1720 | G15: =E15*(Unit_Economics!$E$13*Escenarios!$B$24+Unit_Economics!$F$13*Escenarios!$B$25+Unit_Economics!$G$13*Escenarios!$B$26) -> 149.10217 | H15: =F15-G15 -> 1570.8978 | I15: =Escenarios!$B$27 -> 3500 | J15: =IFERROR(Escenarios!$B$28,0) | K15: =H15-I15-J15 -> -1929.1022 | L15: =L14+K15 -> -26360.062 | M15: =F15*12 -> 20640
A16: 11 | B16: =E15 -> 40 | C16: =IFERROR(ROUND(Escenarios!$B$21*(1+Escenarios!$B$22)^10,1),0) -> 4 | D16: =IFERROR(ROUND(B16*Escenarios!$B$23,1),0) -> 0 | E16: =B16+C16-D16 -> 44 | F16: =E16*(Supuestos!$B$7*Escenarios!$B$24+Supuestos!$C$7*Escenarios!$B$25+Supuestos!$D$7*Escenarios!$B$26) -> 1892 | G16: =E16*(Unit_Economics!$E$13*Escenarios!$B$24+Unit_Economics!$F$13*Escenarios!$B$25+Unit_Economics!$G$13*Escenarios!$B$26) -> 164.01239 | H16: =F16-G16 -> 1727.9876 | I16: =Escenarios!$B$27 -> 3500 | J16: =IFERROR(Escenarios!$B$28,0) | K16: =H16-I16-J16 -> -1772.0124 | L16: =L15+K16 -> -28132.074 | M16: =F16*12 -> 22704
A17: 12 | B17: =E16 -> 44 | C17: =IFERROR(ROUND(Escenarios!$B$21*(1+Escenarios!$B$22)^11,1),0) -> 4 | D17: =IFERROR(ROUND(B17*Escenarios!$B$23,1),0) -> 0 | E17: =B17+C17-D17 -> 48 | F17: =E17*(Supuestos!$B$7*Escenarios!$B$24+Supuestos!$C$7*Escenarios!$B$25+Supuestos!$D$7*Escenarios!$B$26) -> 2064 | G17: =E17*(Unit_Economics!$E$13*Escenarios!$B$24+Unit_Economics!$F$13*Escenarios!$B$25+Unit_Economics!$G$13*Escenarios!$B$26) -> 178.92261 | H17: =F17-G17 -> 1885.0774 | I17: =Escenarios!$B$27 -> 3500 | J17: =IFERROR(Escenarios!$B$28,0) | K17: =H17-I17-J17 -> -1614.9226 | L17: =L16+K17 -> -29746.997 | M17: =F17*12 -> 24768
A18: 13 | B18: =E17 -> 48 | C18: =IFERROR(ROUND(Escenarios!$B$21*(1+Escenarios!$B$22)^12,1),0) -> 4 | D18: =IFERROR(ROUND(B18*Escenarios!$B$23,1),0) -> 0 | E18: =B18+C18-D18 -> 52 | F18: =E18*(Supuestos!$B$7*Escenarios!$B$24+Supuestos!$C$7*Escenarios!$B$25+Supuestos!$D$7*Escenarios!$B$26) -> 2236 | G18: =E18*(Unit_Economics!$E$13*Escenarios!$B$24+Unit_Economics!$F$13*Escenarios!$B$25+Unit_Economics!$G$13*Escenarios!$B$26) -> 193.83283 | H18: =F18-G18 -> 2042.1672 | I18: =Escenarios!$B$27 -> 3500 | J18: =IFERROR(Escenarios!$B$28,0) | K18: =H18-I18-J18 -> -1457.8328 | L18: =L17+K18 -> -31204.83 | M18: =F18*12 -> 26832
A19: 14 | B19: =E18 -> 52 | C19: =IFERROR(ROUND(Escenarios!$B$21*(1+Escenarios!$B$22)^13,1),0) -> 4 | D19: =IFERROR(ROUND(B19*Escenarios!$B$23,1),0) -> 0 | E19: =B19+C19-D19 -> 56 | F19: =E19*(Supuestos!$B$7*Escenarios!$B$24+Supuestos!$C$7*Escenarios!$B$25+Supuestos!$D$7*Escenarios!$B$26) -> 2408 | G19: =E19*(Unit_Economics!$E$13*Escenarios!$B$24+Unit_Economics!$F$13*Escenarios!$B$25+Unit_Economics!$G$13*Escenarios!$B$26) -> 208.74304 | H19: =F19-G19 -> 2199.257 | I19: =Escenarios!$B$27 -> 3500 | J19: =IFERROR(Escenarios!$B$28,0) | K19: =H19-I19-J19 -> -1300.743 | L19: =L18+K19 -> -32505.573 | M19: =F19*12 -> 28896
A20: 15 | B20: =E19 -> 56 | C20: =IFERROR(ROUND(Escenarios!$B$21*(1+Escenarios!$B$22)^14,1),0) -> 4 | D20: =IFERROR(ROUND(B20*Escenarios!$B$23,1),0) -> 0 | E20: =B20+C20-D20 -> 60 | F20: =E20*(Supuestos!$B$7*Escenarios!$B$24+Supuestos!$C$7*Escenarios!$B$25+Supuestos!$D$7*Escenarios!$B$26) -> 2580 | G20: =E20*(Unit_Economics!$E$13*Escenarios!$B$24+Unit_Economics!$F$13*Escenarios!$B$25+Unit_Economics!$G$13*Escenarios!$B$26) -> 223.65326 | H20: =F20-G20 -> 2356.3467 | I20: =Escenarios!$B$27 -> 3500 | J20: =IFERROR(Escenarios!$B$28,0) | K20: =H20-I20-J20 -> -1143.6533 | L20: =L19+K20 -> -33649.226 | M20: =F20*12 -> 30960
A21: 16 | B21: =E20 -> 60 | C21: =IFERROR(ROUND(Escenarios!$B$21*(1+Escenarios!$B$22)^15,1),0) -> 4 | D21: =IFERROR(ROUND(B21*Escenarios!$B$23,1),0) -> 0 | E21: =B21+C21-D21 -> 64 | F21: =E21*(Supuestos!$B$7*Escenarios!$B$24+Supuestos!$C$7*Escenarios!$B$25+Supuestos!$D$7*Escenarios!$B$26) -> 2752 | G21: =E21*(Unit_Economics!$E$13*Escenarios!$B$24+Unit_Economics!$F$13*Escenarios!$B$25+Unit_Economics!$G$13*Escenarios!$B$26) -> 238.56348 | H21: =F21-G21 -> 2513.4365 | I21: =Escenarios!$B$27 -> 3500 | J21: =IFERROR(Escenarios!$B$28,0) | K21: =H21-I21-J21 -> -986.56348 | L21: =L20+K21 -> -34635.79 | M21: =F21*12 -> 33024
A22: 17 | B22: =E21 -> 64 | C22: =IFERROR(ROUND(Escenarios!$B$21*(1+Escenarios!$B$22)^16,1),0) -> 4 | D22: =IFERROR(ROUND(B22*Escenarios!$B$23,1),0) -> 0 | E22: =B22+C22-D22 -> 68 | F22: =E22*(Supuestos!$B$7*Escenarios!$B$24+Supuestos!$C$7*Escenarios!$B$25+Supuestos!$D$7*Escenarios!$B$26) -> 2924 | G22: =E22*(Unit_Economics!$E$13*Escenarios!$B$24+Unit_Economics!$F$13*Escenarios!$B$25+Unit_Economics!$G$13*Escenarios!$B$26) -> 253.4737 | H22: =F22-G22 -> 2670.5263 | I22: =Escenarios!$B$27 -> 3500 | J22: =IFERROR(Escenarios!$B$28,0) | K22: =H22-I22-J22 -> -829.4737 | L22: =L21+K22 -> -35465.263 | M22: =F22*12 -> 35088
A23: 18 | B23: =E22 -> 68 | C23: =IFERROR(ROUND(Escenarios!$B$21*(1+Escenarios!$B$22)^17,1),0) -> 4 | D23: =IFERROR(ROUND(B23*Escenarios!$B$23,1),0) -> 0 | E23: =B23+C23-D23 -> 72 | F23: =E23*(Supuestos!$B$7*Escenarios!$B$24+Supuestos!$C$7*Escenarios!$B$25+Supuestos!$D$7*Escenarios!$B$26) -> 3096 | G23: =E23*(Unit_Economics!$E$13*Escenarios!$B$24+Unit_Economics!$F$13*Escenarios!$B$25+Unit_Economics!$G$13*Escenarios!$B$26) -> 268.38391 | H23: =F23-G23 -> 2827.6161 | I23: =Escenarios!$B$27 -> 3500 | J23: =IFERROR(Escenarios!$B$28,0) | K23: =H23-I23-J23 -> -672.38391 | L23: =L22+K23 -> -36137.647 | M23: =F23*12 -> 37152
A24: 19 | B24: =E23 -> 72 | C24: =IFERROR(ROUND(Escenarios!$B$21*(1+Escenarios!$B$22)^18,1),0) -> 4 | D24: =IFERROR(ROUND(B24*Escenarios!$B$23,1),0) -> 0 | E24: =B24+C24-D24 -> 76 | F24: =E24*(Supuestos!$B$7*Escenarios!$B$24+Supuestos!$C$7*Escenarios!$B$25+Supuestos!$D$7*Escenarios!$B$26) -> 3268 | G24: =E24*(Unit_Economics!$E$13*Escenarios!$B$24+Unit_Economics!$F$13*Escenarios!$B$25+Unit_Economics!$G$13*Escenarios!$B$26) -> 283.29413 | H24: =F24-G24 -> 2984.7059 | I24: =Escenarios!$B$27 -> 3500 | J24: =IFERROR(Escenarios!$B$28,0) | K24: =H24-I24-J24 -> -515.29413 | L24: =L23+K24 -> -36652.941 | M24: =F24*12 -> 39216
A25: 20 | B25: =E24 -> 76 | C25: =IFERROR(ROUND(Escenarios!$B$21*(1+Escenarios!$B$22)^19,1),0) -> 4 | D25: =IFERROR(ROUND(B25*Escenarios!$B$23,1),0) -> 0 | E25: =B25+C25-D25 -> 80 | F25: =E25*(Supuestos!$B$7*Escenarios!$B$24+Supuestos!$C$7*Escenarios!$B$25+Supuestos!$D$7*Escenarios!$B$26) -> 3440 | G25: =E25*(Unit_Economics!$E$13*Escenarios!$B$24+Unit_Economics!$F$13*Escenarios!$B$25+Unit_Economics!$G$13*Escenarios!$B$26) -> 298.20435 | H25: =F25-G25 -> 3141.7957 | I25: =Escenarios!$B$27 -> 3500 | J25: =IFERROR(Escenarios!$B$28,0) | K25: =H25-I25-J25 -> -358.20435 | L25: =L24+K25 -> -37011.146 | M25: =F25*12 -> 41280
A26: 21 | B26: =E25 -> 80 | C26: =IFERROR(ROUND(Escenarios!$B$21*(1+Escenarios!$B$22)^20,1),0) -> 4 | D26: =IFERROR(ROUND(B26*Escenarios!$B$23,1),0) -> 0 | E26: =B26+C26-D26 -> 84 | F26: =E26*(Supuestos!$B$7*Escenarios!$B$24+Supuestos!$C$7*Escenarios!$B$25+Supuestos!$D$7*Escenarios!$B$26) -> 3612 | G26: =E26*(Unit_Economics!$E$13*Escenarios!$B$24+Unit_Economics!$F$13*Escenarios!$B$25+Unit_Economics!$G$13*Escenarios!$B$26) -> 313.11457 | H26: =F26-G26 -> 3298.8854 | I26: =Escenarios!$B$27 -> 3500 | J26: =IFERROR(Escenarios!$B$28,0) | K26: =H26-I26-J26 -> -201.11457 | L26: =L25+K26 -> -37212.26 | M26: =F26*12 -> 43344
A27: 22 | B27: =E26 -> 84 | C27: =IFERROR(ROUND(Escenarios!$B$21*(1+Escenarios!$B$22)^21,1),0) -> 4 | D27: =IFERROR(ROUND(B27*Escenarios!$B$23,1),0) -> 0 | E27: =B27+C27-D27 -> 88 | F27: =E27*(Supuestos!$B$7*Escenarios!$B$24+Supuestos!$C$7*Escenarios!$B$25+Supuestos!$D$7*Escenarios!$B$26) -> 3784 | G27: =E27*(Unit_Economics!$E$13*Escenarios!$B$24+Unit_Economics!$F$13*Escenarios!$B$25+Unit_Economics!$G$13*Escenarios!$B$26) -> 328.02478 | H27: =F27-G27 -> 3455.9752 | I27: =Escenarios!$B$27 -> 3500 | J27: =IFERROR(Escenarios!$B$28,0) | K27: =H27-I27-J27 -> -44.024785 | L27: =L26+K27 -> -37256.285 | M27: =F27*12 -> 45408
A28: 23 | B28: =E27 -> 88 | C28: =IFERROR(ROUND(Escenarios!$B$21*(1+Escenarios!$B$22)^22,1),0) -> 4 | D28: =IFERROR(ROUND(B28*Escenarios!$B$23,1),0) -> 0 | E28: =B28+C28-D28 -> 92 | F28: =E28*(Supuestos!$B$7*Escenarios!$B$24+Supuestos!$C$7*Escenarios!$B$25+Supuestos!$D$7*Escenarios!$B$26) -> 3956 | G28: =E28*(Unit_Economics!$E$13*Escenarios!$B$24+Unit_Economics!$F$13*Escenarios!$B$25+Unit_Economics!$G$13*Escenarios!$B$26) -> 342.935 | H28: =F28-G28 -> 3613.065 | I28: =Escenarios!$B$27 -> 3500 | J28: =IFERROR(Escenarios!$B$28,0) | K28: =H28-I28-J28 -> 113.065 | L28: =L27+K28 -> -37143.22 | M28: =F28*12 -> 47472
A29: 24 | B29: =E28 -> 92 | C29: =IFERROR(ROUND(Escenarios!$B$21*(1+Escenarios!$B$22)^23,1),0) -> 4 | D29: =IFERROR(ROUND(B29*Escenarios!$B$23,1),0) -> 0 | E29: =B29+C29-D29 -> 96 | F29: =E29*(Supuestos!$B$7*Escenarios!$B$24+Supuestos!$C$7*Escenarios!$B$25+Supuestos!$D$7*Escenarios!$B$26) -> 4128 | G29: =E29*(Unit_Economics!$E$13*Escenarios!$B$24+Unit_Economics!$F$13*Escenarios!$B$25+Unit_Economics!$G$13*Escenarios!$B$26) -> 357.84522 | H29: =F29-G29 -> 3770.1548 | I29: =Escenarios!$B$27 -> 3500 | J29: =IFERROR(Escenarios!$B$28,0) | K29: =H29-I29-J29 -> 270.15478 | L29: =L28+K29 -> -36873.065 | M29: =F29*12 -> 49536
A31: Indicadores derivados
A32: Mes en que el resultado se vuelve positivo | C32: {=IFERROR(INDEX($A$6:$A$29,MATCH(TRUE,INDEX($K$6:$K$29>=0,0),0)),"No llega en 24 meses")} -> 23
A33: Caja minima alcanzada | C33: =MIN(L6:L29) -> -37256.285
A34: Mes de caja minima | C34: {=IFERROR(INDEX($A$6:$A$29,MATCH(MIN($L$6:$L$29),$L$6:$L$29,0)),"")} -> 22
A35: Cartera al mes 24 | C35: =E29 -> 96
A36: ARR al mes 24 | C36: =M29 -> 49536
A38: La caja minima es la cifra que decide si el proyecto sobrevive: es el dinero que hay que tener disponible antes de empezar. Si supera el capital aportado, el plan no es financiable tal cual y hay que recortar opex, subir precio o retrasar la contratacion.

Sheet Sensibilidad
A1: Sensibilidad del punto de equilibrio
A2: Cuantas cuentas hacen falta segun el opex real y la contribucion media. Sirve para responder 'si me equivoco en el gasto fijo, cuanto me duele'. La fila y la columna gris son entradas.
A4: Cuentas necesarias para equilibrio
A5: Opex \ Contribucion | B5: 20 | C5: 25 | D5: 29.36 | E5: 35 | F5: 40 | G5: 45 | H5: 50
A6: 1500 | B6: =IFERROR(ROUNDUP($A6/B$5,0),"") -> 75 | C6: =IFERROR(ROUNDUP($A6/C$5,0),"") -> 60 | D6: =IFERROR(ROUNDUP($A6/D$5,0),"") -> 52 | E6: =IFERROR(ROUNDUP($A6/E$5,0),"") -> 43 | F6: =IFERROR(ROUNDUP($A6/F$5,0),"") -> 38 | G6: =IFERROR(ROUNDUP($A6/G$5,0),"") -> 34 | H6: =IFERROR(ROUNDUP($A6/H$5,0),"") -> 30
A7: 2000 | B7: =IFERROR(ROUNDUP($A7/B$5,0),"") -> 100 | C7: =IFERROR(ROUNDUP($A7/C$5,0),"") -> 80 | D7: =IFERROR(ROUNDUP($A7/D$5,0),"") -> 69 | E7: =IFERROR(ROUNDUP($A7/E$5,0),"") -> 58 | F7: =IFERROR(ROUNDUP($A7/F$5,0),"") -> 50 | G7: =IFERROR(ROUNDUP($A7/G$5,0),"") -> 45 | H7: =IFERROR(ROUNDUP($A7/H$5,0),"") -> 40
A8: 2500 | B8: =IFERROR(ROUNDUP($A8/B$5,0),"") -> 125 | C8: =IFERROR(ROUNDUP($A8/C$5,0),"") -> 100 | D8: =IFERROR(ROUNDUP($A8/D$5,0),"") -> 86 | E8: =IFERROR(ROUNDUP($A8/E$5,0),"") -> 72 | F8: =IFERROR(ROUNDUP($A8/F$5,0),"") -> 63 | G8: =IFERROR(ROUNDUP($A8/G$5,0),"") -> 56 | H8: =IFERROR(ROUNDUP($A8/H$5,0),"") -> 50
A9: 3000 | B9: =IFERROR(ROUNDUP($A9/B$5,0),"") -> 150 | C9: =IFERROR(ROUNDUP($A9/C$5,0),"") -> 120 | D9: =IFERROR(ROUNDUP($A9/D$5,0),"") -> 103 | E9: =IFERROR(ROUNDUP($A9/E$5,0),"") -> 86 | F9: =IFERROR(ROUNDUP($A9/F$5,0),"") -> 75 | G9: =IFERROR(ROUNDUP($A9/G$5,0),"") -> 67 | H9: =IFERROR(ROUNDUP($A9/H$5,0),"") -> 60
A10: 3500 | B10: =IFERROR(ROUNDUP($A10/B$5,0),"") -> 175 | C10: =IFERROR(ROUNDUP($A10/C$5,0),"") -> 140 | D10: =IFERROR(ROUNDUP($A10/D$5,0),"") -> 120 | E10: =IFERROR(ROUNDUP($A10/E$5,0),"") -> 100 | F10: =IFERROR(ROUNDUP($A10/F$5,0),"") -> 88 | G10: =IFERROR(ROUNDUP($A10/G$5,0),"") -> 78 | H10: =IFERROR(ROUNDUP($A10/H$5,0),"") -> 70
A11: 4000 | B11: =IFERROR(ROUNDUP($A11/B$5,0),"") -> 200 | C11: =IFERROR(ROUNDUP($A11/C$5,0),"") -> 160 | D11: =IFERROR(ROUNDUP($A11/D$5,0),"") -> 137 | E11: =IFERROR(ROUNDUP($A11/E$5,0),"") -> 115 | F11: =IFERROR(ROUNDUP($A11/F$5,0),"") -> 100 | G11: =IFERROR(ROUNDUP($A11/G$5,0),"") -> 89 | H11: =IFERROR(ROUNDUP($A11/H$5,0),"") -> 80
A12: 5000 | B12: =IFERROR(ROUNDUP($A12/B$5,0),"") -> 250 | C12: =IFERROR(ROUNDUP($A12/C$5,0),"") -> 200 | D12: =IFERROR(ROUNDUP($A12/D$5,0),"") -> 171 | E12: =IFERROR(ROUNDUP($A12/E$5,0),"") -> 143 | F12: =IFERROR(ROUNDUP($A12/F$5,0),"") -> 125 | G12: =IFERROR(ROUNDUP($A12/G$5,0),"") -> 112 | H12: =IFERROR(ROUNDUP($A12/H$5,0),"") -> 100
A13: 6000 | B13: =IFERROR(ROUNDUP($A13/B$5,0),"") -> 300 | C13: =IFERROR(ROUNDUP($A13/C$5,0),"") -> 240 | D13: =IFERROR(ROUNDUP($A13/D$5,0),"") -> 205 | E13: =IFERROR(ROUNDUP($A13/E$5,0),"") -> 172 | F13: =IFERROR(ROUNDUP($A13/F$5,0),"") -> 150 | G13: =IFERROR(ROUNDUP($A13/G$5,0),"") -> 134 | H13: =IFERROR(ROUNDUP($A13/H$5,0),"") -> 120
A14: 8000 | B14: =IFERROR(ROUNDUP($A14/B$5,0),"") -> 400 | C14: =IFERROR(ROUNDUP($A14/C$5,0),"") -> 320 | D14: =IFERROR(ROUNDUP($A14/D$5,0),"") -> 273 | E14: =IFERROR(ROUNDUP($A14/E$5,0),"") -> 229 | F14: =IFERROR(ROUNDUP($A14/F$5,0),"") -> 200 | G14: =IFERROR(ROUNDUP($A14/G$5,0),"") -> 178 | H14: =IFERROR(ROUNDUP($A14/H$5,0),"") -> 160
A16: La columna de 29,36 € es la contribucion media ponderada que calcula el modelo con el mix 55/35/10. Leer la fila del opex real: cada 500 € de gasto fijo de mas son unas 17 cuentas adicionales que hay que vender solo para empatar.

Sheet Capacidad_Soporte
A1: Capacidad de soporte y cuando contratar
A2: El soporte es el coste que primero rompe el margen al crecer. Traduce cuentas en horas de persona y avisa del punto en el que una sola persona ya no llega.
A4: Parametros
A5: Horas utiles por persona y mes | B5: 130 | G5: Jornada completa descontando festivos y tareas internas
A6: Minutos de soporte Autonomo | B6: =Supuestos!B19 -> 12 | G6: De la hoja Supuestos
A7: Minutos de soporte Negocio | B7: =Supuestos!C19 -> 20 | G7: De la hoja Supuestos
A8: Minutos de soporte Premium | B8: =Supuestos!D19 -> 45 | G8: De la hoja Supuestos
A10: Carga segun tamano de cartera
A11: Cuentas | B11: Minutos/mes | C11: Horas/mes | D11: Personas necesarias | E11: Coste soporte | F11: % sobre MRR | G11: Situacion
A12: 25 | B12: =A12*($B$6*Supuestos!$B$8+$B$7*Supuestos!$C$8+$B$8*Supuestos!$D$8) -> 452.5 | C12: =B12/60 -> 7.5416667 | D12: =C12/$B$5 -> 0.058012821 | E12: =C12*Supuestos!$B$39 -> 188.54167 | F12: =IFERROR(E12/(A12*(Supuestos!$B$7*Supuestos!$B$8+Supuestos!$C$7*Supuestos!$C$8+Supuestos!$D$7*Supuestos!$D$8)),"") -> 0.1753876 | G12: =IF(D12<=0.5,"Lo lleva el founder",IF(D12<=1,"Ocupa a una persona entera",IF(D12<=2,"Hace falta una segunda persona","Equipo de soporte formal"))) -> Lo lleva el founder
A13: 50 | B13: =A13*($B$6*Supuestos!$B$8+$B$7*Supuestos!$C$8+$B$8*Supuestos!$D$8) -> 905 | C13: =B13/60 -> 15.083333 | D13: =C13/$B$5 -> 0.11602564 | E13: =C13*Supuestos!$B$39 -> 377.08333 | F13: =IFERROR(E13/(A13*(Supuestos!$B$7*Supuestos!$B$8+Supuestos!$C$7*Supuestos!$C$8+Supuestos!$D$7*Supuestos!$D$8)),"") -> 0.1753876 | G13: =IF(D13<=0.5,"Lo lleva el founder",IF(D13<=1,"Ocupa a una persona entera",IF(D13<=2,"Hace falta una segunda persona","Equipo de soporte formal"))) -> Lo lleva el founder
A14: 100 | B14: =A14*($B$6*Supuestos!$B$8+$B$7*Supuestos!$C$8+$B$8*Supuestos!$D$8) -> 1810 | C14: =B14/60 -> 30.166667 | D14: =C14/$B$5 -> 0.23205128 | E14: =C14*Supuestos!$B$39 -> 754.16667 | F14: =IFERROR(E14/(A14*(Supuestos!$B$7*Supuestos!$B$8+Supuestos!$C$7*Supuestos!$C$8+Supuestos!$D$7*Supuestos!$D$8)),"") -> 0.1753876 | G14: =IF(D14<=0.5,"Lo lleva el founder",IF(D14<=1,"Ocupa a una persona entera",IF(D14<=2,"Hace falta una segunda persona","Equipo de soporte formal"))) -> Lo lleva el founder
A15: 120 | B15: =A15*($B$6*Supuestos!$B$8+$B$7*Supuestos!$C$8+$B$8*Supuestos!$D$8) -> 2172 | C15: =B15/60 -> 36.2 | D15: =C15/$B$5 -> 0.27846154 | E15: =C15*Supuestos!$B$39 -> 905 | F15: =IFERROR(E15/(A15*(Supuestos!$B$7*Supuestos!$B$8+Supuestos!$C$7*Supuestos!$C$8+Supuestos!$D$7*Supuestos!$D$8)),"") -> 0.1753876 | G15: =IF(D15<=0.5,"Lo lleva el founder",IF(D15<=1,"Ocupa a una persona entera",IF(D15<=2,"Hace falta una segunda persona","Equipo de soporte formal"))) -> Lo lleva el founder
A16: 200 | B16: =A16*($B$6*Supuestos!$B$8+$B$7*Supuestos!$C$8+$B$8*Supuestos!$D$8) -> 3620 | C16: =B16/60 -> 60.333333 | D16: =C16/$B$5 -> 0.46410256 | E16: =C16*Supuestos!$B$39 -> 1508.3333 | F16: =IFERROR(E16/(A16*(Supuestos!$B$7*Supuestos!$B$8+Supuestos!$C$7*Supuestos!$C$8+Supuestos!$D$7*Supuestos!$D$8)),"") -> 0.1753876 | G16: =IF(D16<=0.5,"Lo lleva el founder",IF(D16<=1,"Ocupa a una persona entera",IF(D16<=2,"Hace falta una segunda persona","Equipo de soporte formal"))) -> Lo lleva el founder
A17: 300 | B17: =A17*($B$6*Supuestos!$B$8+$B$7*Supuestos!$C$8+$B$8*Supuestos!$D$8) -> 5430 | C17: =B17/60 -> 90.5 | D17: =C17/$B$5 -> 0.69615385 | E17: =C17*Supuestos!$B$39 -> 2262.5 | F17: =IFERROR(E17/(A17*(Supuestos!$B$7*Supuestos!$B$8+Supuestos!$C$7*Supuestos!$C$8+Supuestos!$D$7*Supuestos!$D$8)),"") -> 0.1753876 | G17: =IF(D17<=0.5,"Lo lleva el founder",IF(D17<=1,"Ocupa a una persona entera",IF(D17<=2,"Hace falta una segunda persona","Equipo de soporte formal"))) -> Ocupa a una persona entera
A18: 500 | B18: =A18*($B$6*Supuestos!$B$8+$B$7*Supuestos!$C$8+$B$8*Supuestos!$D$8) -> 9050 | C18: =B18/60 -> 150.83333 | D18: =C18/$B$5 -> 1.1602564 | E18: =C18*Supuestos!$B$39 -> 3770.8333 | F18: =IFERROR(E18/(A18*(Supuestos!$B$7*Supuestos!$B$8+Supuestos!$C$7*Supuestos!$C$8+Supuestos!$D$7*Supuestos!$D$8)),"") -> 0.1753876 | G18: =IF(D18<=0.5,"Lo lleva el founder",IF(D18<=1,"Ocupa a una persona entera",IF(D18<=2,"Hace falta una segunda persona","Equipo de soporte formal"))) -> Hace falta una segunda persona
A19: 750 | B19: =A19*($B$6*Supuestos!$B$8+$B$7*Supuestos!$C$8+$B$8*Supuestos!$D$8) -> 13575 | C19: =B19/60 -> 226.25 | D19: =C19/$B$5 -> 1.7403846 | E19: =C19*Supuestos!$B$39 -> 5656.25 | F19: =IFERROR(E19/(A19*(Supuestos!$B$7*Supuestos!$B$8+Supuestos!$C$7*Supuestos!$C$8+Supuestos!$D$7*Supuestos!$D$8)),"") -> 0.1753876 | G19: =IF(D19<=0.5,"Lo lleva el founder",IF(D19<=1,"Ocupa a una persona entera",IF(D19<=2,"Hace falta una segunda persona","Equipo de soporte formal"))) -> Hace falta una segunda persona
