Workbook

Sheet Panel
A1: Bynoesis · modelo economico v3 (realista)
A2: Azul = lo editas tu. Negro = formula. Este libro no pregunta «cuanto ganaria con 500 clientes»: pregunta «cuantos puedo atender yo solo, cuando dejo de perder dinero y cuanta caja necesito hasta entonces». Con cero clientes de pago hoy, todo lo de aqui es un escenario; la ultima hoja dice que cifra es un dato y cual no.
A6: 1 · Precios y mezcla
A7: Plan | B7: Precio | C7: Coste software | D7: Mezcla | F7: De donde sale
A8: Autonomo | B8: 29 | C8: 1.48 | D8: 0.55 | F8: Precio adoptado el 15/07/2026. El coste es Stripe, WhatsApp, IA, voz y almacenamiento.
A9: Negocio | B9: 49 | C9: 3.04 | D9: 0.35 | F9: Precio adoptado el 15/07/2026. El coste es Stripe, WhatsApp, IA, voz y almacenamiento.
A10: Premium | B10: 99 | C10: 18.47 | D10: 0.1 | F10: Precio adoptado el 15/07/2026. El coste es Stripe, WhatsApp, IA, voz y almacenamiento.
A11: Media ponderada | B11: =SUMPRODUCT(B8:B10,D8:D10) | C11: =SUMPRODUCT(C8:C10,D8:D10) | D11: =SUM(D8:D10) | F11: La mezcla debe sumar 100 %.
A13: 2 · Como se comporta un cliente
A14: Palanca | B14: Valor | F14: Por que importa
A15: Bajas los tres primeros meses | B15: 0.08 | F15: SUPUESTO. Una cartera nueva pierde mas al principio: el que no llega a usarlo se va pronto. El modelo anterior suponia cero bajas.
A16: Bajas a partir del cuarto mes | B16: 0.04 | F16: SUPUESTO. Quien pasa de los tres meses suele quedarse.
A17: Dias de prueba gratis | B17: 14 | F17: El primer mes de cada alta no se cobra entero.
A18: Recibos que no se cobran | B18: 0.03 | F18: SUPUESTO. Tarjetas caducadas y devoluciones.
A19: Contratan plan anual | B19: 0.2 | F19: SUPUESTO. El anual adelanta once meses de caja.
A21: 3 · Tu tiempo, que es el limite de verdad
A22: Palanca | B22: Valor | F22: Por que importa
A23: Horas al mes para vender y atender | B23: 60 | F23: Las que te quedan despues de construir producto. Es la palanca que decide todo lo demas.
A24: Horas por alta (venta y puesta en marcha) | B24: 3 | F24: Demo, alta, primera factura y acompanamiento. El analisis cifra el onboarding en 30-120 minutos; vender ocupa mas que eso.
A25: Minutos de soporte, cuenta nueva | B25: 30 | F25: Los tres primeros meses preguntan mucho mas.
A26: Minutos de soporte, cuenta asentada | B26: 12 | F26: Del analisis del 15/07/2026 para el plan Autonomo.
A27: Altas que te gustaria hacer al mes | B27: 5 | F27: Tu objetivo comercial. El modelo solo lo cumple si te quedan horas.
A28: Crecimiento mensual de ese objetivo | B28: 0.05 | F28: Boca a boca y prescriptores. Sin ads, es lento.
A30: 4 · Lo que sale de tu bolsillo cada mes
A31: Partida | B31: Valor | F31: Nota
A32: Servidores y dominio | B32: 30 | F32: Railway, dominio y correo. PENDIENTE: la factura real.
A33: Herramientas y suscripciones | B33: 40 | F33: IDE, diseno, analitica, almacenamiento.
A34: Gestoria | B34: 60 | F34: PENDIENTE: presupuesto real.
A35: Seguro y otros fijos | B35: 30 | F35: Responsabilidad civil. PENDIENTE.
A36: Presupuesto de captacion | B36: 0 | F36: Ads. A cero, captas solo con tu tiempo.
A37: Cuota de autonomos | B37: 300 | F37: PENDIENTE: depende de tarifa plana y forma juridica.
A38: Lo que quieres cobrar tu al mes | B38: 1200 | F38: La cifra que convierte esto en un trabajo y no en un hobby.
A39: Estructura (sin cuota ni retirada) | B39: =SUM($B$32:$B$36) | F39: Es el minimo que hay que pagar aunque no cobres nada.
A40: Salida total de caja al mes | B40: =SUM($B$32:$B$36)+$B$37+$B$38 | F40: Estructura, cuota y tu retirada.
A41: Caja inicial | B41: 4000 | F41: El vault cita ~4.000 EUR iniciales. PENDIENTE confirmar.
A43: 5 · Lo que contesta el modelo
A44: Pregunta | B44: Respuesta | F44: Como se calcula
A45: Contribucion por cuenta y mes | B45: =($B$11*(1-$B$18))-$C$11 | F45: Lo que deja una cuenta despues de lo que cuesta servirla en dinero. Tu tiempo no entra aqui: entra como limite de capacidad.
A46: Cuentas para cubrir solo la estructura | B46: =IF($B$45<=0,"-",ROUNDUP(SUM($B$32:$B$36)/$B$45,0)) | F46: Servidores, herramientas, gestoria y seguro.
A47: Cuentas para cubrir estructura y cuota | B47: =IF($B$45<=0,"-",ROUNDUP((SUM($B$32:$B$36)+$B$37)/$B$45,0)) | F47: El minimo para no poner dinero cada mes.
...

Sheet Horas_del_founder
A1: Tu tiempo puesto en numeros
A2: En un negocio de una persona, el limite no es el mercado: son las horas. Cada cuenta nueva consume tiempo de venta y puesta en marcha una vez, y tiempo de soporte todos los meses. Cuando el soporte se come las horas, no quedan para vender y la cartera deja de crecer sola.
A6: Concepto | B6: Valor | F6: Nota
A7: Horas al mes para vender y atender | B7: =Panel!$B$23 | F7: Del Panel.
A8: Soporte de una cuenta asentada (horas/mes) | B8: =Panel!$B$26/60 | F8: Los minutos del Panel pasados a horas.
A9: Cuentas que llenan tus horas solo con soporte | B9: =IF(B8<=0,"sin limite",ROUNDDOWN(B7/B8,0)) | F9: A partir de aqui no te queda ni una hora para vender.
A11: Cuentas atendidas | B11: Horas de soporte | C11: % de tus horas | D11: Horas libres para vender | E11: Altas que puedes cerrar | F11: Situacion
A12: 10 | B12: =A12*Panel!$B$26/60 | C12: =IF(Panel!$B$23=0,0,B12/Panel!$B$23) | D12: =MAX(0,Panel!$B$23-B12) | E12: =IF(Panel!$B$24<=0,0,ROUNDDOWN(D12/Panel!$B$24,0)) | F12: =IF(C12>=1,"Ya no puedes vender: solo atiendes",IF(C12>=0.7,"Al limite: el soporte se come el mes",IF(C12>=0.4,"Creces despacio","Tienes margen para vender")))
A13: 25 | B13: =A13*Panel!$B$26/60 | C13: =IF(Panel!$B$23=0,0,B13/Panel!$B$23) | D13: =MAX(0,Panel!$B$23-B13) | E13: =IF(Panel!$B$24<=0,0,ROUNDDOWN(D13/Panel!$B$24,0)) | F13: =IF(C13>=1,"Ya no puedes vender: solo atiendes",IF(C13>=0.7,"Al limite: el soporte se come el mes",IF(C13>=0.4,"Creces despacio","Tienes margen para vender")))
A14: 50 | B14: =A14*Panel!$B$26/60 | C14: =IF(Panel!$B$23=0,0,B14/Panel!$B$23) | D14: =MAX(0,Panel!$B$23-B14) | E14: =IF(Panel!$B$24<=0,0,ROUNDDOWN(D14/Panel!$B$24,0)) | F14: =IF(C14>=1,"Ya no puedes vender: solo atiendes",IF(C14>=0.7,"Al limite: el soporte se come el mes",IF(C14>=0.4,"Creces despacio","Tienes margen para vender")))
A15: 75 | B15: =A15*Panel!$B$26/60 | C15: =IF(Panel!$B$23=0,0,B15/Panel!$B$23) | D15: =MAX(0,Panel!$B$23-B15) | E15: =IF(Panel!$B$24<=0,0,ROUNDDOWN(D15/Panel!$B$24,0)) | F15: =IF(C15>=1,"Ya no puedes vender: solo atiendes",IF(C15>=0.7,"Al limite: el soporte se come el mes",IF(C15>=0.4,"Creces despacio","Tienes margen para vender")))
A16: 100 | B16: =A16*Panel!$B$26/60 | C16: =IF(Panel!$B$23=0,0,B16/Panel!$B$23) | D16: =MAX(0,Panel!$B$23-B16) | E16: =IF(Panel!$B$24<=0,0,ROUNDDOWN(D16/Panel!$B$24,0)) | F16: =IF(C16>=1,"Ya no puedes vender: solo atiendes",IF(C16>=0.7,"Al limite: el soporte se come el mes",IF(C16>=0.4,"Creces despacio","Tienes margen para vender")))
A17: 150 | B17: =A17*Panel!$B$26/60 | C17: =IF(Panel!$B$23=0,0,B17/Panel!$B$23) | D17: =MAX(0,Panel!$B$23-B17) | E17: =IF(Panel!$B$24<=0,0,ROUNDDOWN(D17/Panel!$B$24,0)) | F17: =IF(C17>=1,"Ya no puedes vender: solo atiendes",IF(C17>=0.7,"Al limite: el soporte se come el mes",IF(C17>=0.4,"Creces despacio","Tienes margen para vender")))
A18: 200 | B18: =A18*Panel!$B$26/60 | C18: =IF(Panel!$B$23=0,0,B18/Panel!$B$23) | D18: =MAX(0,Panel!$B$23-B18) | E18: =IF(Panel!$B$24<=0,0,ROUNDDOWN(D18/Panel!$B$24,0)) | F18: =IF(C18>=1,"Ya no puedes vender: solo atiendes",IF(C18>=0.7,"Al limite: el soporte se come el mes",IF(C18>=0.4,"Creces despacio","Tienes margen para vender")))
A19: 300 | B19: =A19*Panel!$B$26/60 | C19: =IF(Panel!$B$23=0,0,B19/Panel!$B$23) | D19: =MAX(0,Panel!$B$23-B19) | E19: =IF(Panel!$B$24<=0,0,ROUNDDOWN(D19/Panel!$B$24,0)) | F19: =IF(C19>=1,"Ya no puedes vender: solo atiendes",IF(C19>=0.7,"Al limite: el soporte se come el mes",IF(C19>=0.4,"Creces despacio","Tienes margen para vender")))
A21: Contratar no resuelve el problema por si solo: una persona de soporte cuesta desde el primer dia y la cartera crece despacio. Por eso el margen del producto tiene que venir de que el soporte por cuenta baje —cerebro local, autoexplicacion, menos dudas—, no de meter mas gente.
A24: Si contratas a media jornada | B24: Valor | F24: Nota
A25: Coste cargado al mes | B25: 900 | F25: Media jornada con seguridad social. Editable.
A26: Cuentas extra necesarias para pagarla | B26: =IF(Panel!$B$45<=0,"-",ROUNDUP($B$25/Panel!$B$45,0)) | F26: Sobre las que ya tengas: la persona no trae clientes, libera horas.
A28: Esa cifra es la trampa del crecimiento: el coste entra de golpe y las altas llegan una a una. Antes de contratar conviene que la cartera pueda pagarlo ya, no que vaya a poder.

Sheet Rampa_36m
A1: 36 meses reales: cuatro cohortes y tus horas
A2: Cada mes entran las altas que te permiten tus horas libres, no las que te gustaria. Las cuentas se siguen por edad porque las nuevas se van mas y preguntan mas. La proyeccion anterior suponia altas constantes y cero bajas; esta se frena sola cuando el soporte te ocupa el mes.
A6: Mes en que dejas de perder dinero | B6: =IFERROR(INDEX($A$10:$A$45,MATCH(TRUE,INDEX($L$10:$L$45>0,0),0)),"no llega en 36 meses")
A7: Caja minima por el camino | B7: =MIN($M$10:$M$45)
A8: Cuentas al mes 36 | B8: =$H$45 | D8: Horas disponibles | E8: =Panel!$B$23
A9: Mes | B9: Altas | C9: Mes 1 | D9: Mes 2 | E9: Mes 3 | F9: Asentadas | G9: Cuentas | H9: Horas usadas | I9: Facturado | J9: Cobrado | K9: Contribucion | L9: Resultado | M9: Caja
A10: 1 | B10: =MAX(0,MIN(ROUND(Panel!$B$27*(1+Panel!$B$28)^(A10-1),0),ROUNDDOWN(MAX(0,Panel!$B$23-0)/Panel!$B$24,0))) | C10: =B10 | D10: =0 | E10: =0 | F10: =0 | G10: =C10+D10+E10+F10 | H10: =B10*Panel!$B$24+((C10+D10+E10)*Panel!$B$25+F10*Panel!$B$26)/60 | I10: =G10*Panel!$B$11-B10*Panel!$B$11*Panel!$B$17/30 | J10: =I10*(1-Panel!$B$18) | K10: =J10-G10*Panel!$C$11 | L10: =K10-Panel!$B$40 | M10: =Panel!$B$41+L10
A11: 2 | B11: =MAX(0,MIN(ROUND(Panel!$B$27*(1+Panel!$B$28)^(A11-1),0),ROUNDDOWN(MAX(0,Panel!$B$23-((C10+D10+E10)*Panel!$B$25+F10*Panel!$B$26)/60)/Panel!$B$24,0))) | C11: =B11 | D11: =C10*(1-Panel!$B$15) | E11: =D10*(1-Panel!$B$15) | F11: =(F10+E10)*(1-Panel!$B$16) | G11: =C11+D11+E11+F11 | H11: =B11*Panel!$B$24+((C11+D11+E11)*Panel!$B$25+F11*Panel!$B$26)/60 | I11: =G11*Panel!$B$11-B11*Panel!$B$11*Panel!$B$17/30 | J11: =I11*(1-Panel!$B$18) | K11: =J11-G11*Panel!$C$11 | L11: =K11-Panel!$B$40 | M11: =M10+L11
A12: 3 | B12: =MAX(0,MIN(ROUND(Panel!$B$27*(1+Panel!$B$28)^(A12-1),0),ROUNDDOWN(MAX(0,Panel!$B$23-((C11+D11+E11)*Panel!$B$25+F11*Panel!$B$26)/60)/Panel!$B$24,0))) | C12: =B12 | D12: =C11*(1-Panel!$B$15) | E12: =D11*(1-Panel!$B$15) | F12: =(F11+E11)*(1-Panel!$B$16) | G12: =C12+D12+E12+F12 | H12: =B12*Panel!$B$24+((C12+D12+E12)*Panel!$B$25+F12*Panel!$B$26)/60 | I12: =G12*Panel!$B$11-B12*Panel!$B$11*Panel!$B$17/30 | J12: =I12*(1-Panel!$B$18) | K12: =J12-G12*Panel!$C$11 | L12: =K12-Panel!$B$40 | M12: =M11+L12
A13: 4 | B13: =MAX(0,MIN(ROUND(Panel!$B$27*(1+Panel!$B$28)^(A13-1),0),ROUNDDOWN(MAX(0,Panel!$B$23-((C12+D12+E12)*Panel!$B$25+F12*Panel!$B$26)/60)/Panel!$B$24,0))) | C13: =B13 | D13: =C12*(1-Panel!$B$15) | E13: =D12*(1-Panel!$B$15) | F13: =(F12+E12)*(1-Panel!$B$16) | G13: =C13+D13+E13+F13 | H13: =B13*Panel!$B$24+((C13+D13+E13)*Panel!$B$25+F13*Panel!$B$26)/60 | I13: =G13*Panel!$B$11-B13*Panel!$B$11*Panel!$B$17/30 | J13: =I13*(1-Panel!$B$18) | K13: =J13-G13*Panel!$C$11 | L13: =K13-Panel!$B$40 | M13: =M12+L13
A14: 5 | B14: =MAX(0,MIN(ROUND(Panel!$B$27*(1+Panel!$B$28)^(A14-1),0),ROUNDDOWN(MAX(0,Panel!$B$23-((C13+D13+E13)*Panel!$B$25+F13*Panel!$B$26)/60)/Panel!$B$24,0))) | C14: =B14 | D14: =C13*(1-Panel!$B$15) | E14: =D13*(1-Panel!$B$15) | F14: =(F13+E13)*(1-Panel!$B$16) | G14: =C14+D14+E14+F14 | H14: =B14*Panel!$B$24+((C14+D14+E14)*Panel!$B$25+F14*Panel!$B$26)/60 | I14: =G14*Panel!$B$11-B14*Panel!$B$11*Panel!$B$17/30 | J14: =I14*(1-Panel!$B$18) | K14: =J14-G14*Panel!$C$11 | L14: =K14-Panel!$B$40 | M14: =M13+L14
A15: 6 | B15: =MAX(0,MIN(ROUND(Panel!$B$27*(1+Panel!$B$28)^(A15-1),0),ROUNDDOWN(MAX(0,Panel!$B$23-((C14+D14+E14)*Panel!$B$25+F14*Panel!$B$26)/60)/Panel!$B$24,0))) | C15: =B15 | D15: =C14*(1-Panel!$B$15) | E15: =D14*(1-Panel!$B$15) | F15: =(F14+E14)*(1-Panel!$B$16) | G15: =C15+D15+E15+F15 | H15: =B15*Panel!$B$24+((C15+D15+E15)*Panel!$B$25+F15*Panel!$B$26)/60 | I15: =G15*Panel!$B$11-B15*Panel!$B$11*Panel!$B$17/30 | J15: =I15*(1-Panel!$B$18) | K15: =J15-G15*Panel!$C$11 | L15: =K15-Panel!$B$40 | M15: =M14+L15
A16: 7 | B16: =MAX(0,MIN(ROUND(Panel!$B$27*(1+Panel!$B$28)^(A16-1),0),ROUNDDOWN(MAX(0,Panel!$B$23-((C15+D15+E15)*Panel!$B$25+F15*Panel!$B$26)/60)/Panel!$B$24,0))) | C16: =B16 | D16: =C15*(1-Panel!$B$15) | E16: =D15*(1-Panel!$B$15) | F16: =(F15+E15)*(1-Panel!$B$16) | G16: =C16+D16+E16+F16 | H16: =B16*Panel!$B$24+((C16+D16+E16)*Panel!$B$25+F16*Panel!$B$26)/60 | I16: =G16*Panel!$B$11-B16*Panel!$B$11*Panel!$B$17/30 | J16: =I16*(1-Panel!$B$18) | K16: =J16-G16*Panel!$C$11 | L16: =K16-Panel!$B$40 | M16: =M15+L16
A17: 8 | B17: =MAX(0,MIN(ROUND(Panel!$B$27*(1+Panel!$B$28)^(A17-1),0),ROUNDDOWN(MAX(0,Panel!$B$23-((C16+D16+E16)*Panel!$B$25+F16*Panel!$B$26)/60)/Panel!$B$24,0))) | C17: =B17 | D17: =C16*(1-Panel!$B$15) | E17: =D16*(1-Panel!$B$15) | F17: =(F16+E16)*(1-Panel!$B$16) | G17: =C17+D17+E17+F17 | H17: =B17*Panel!$B$24+((C17+D17+E17)*Panel!$B$25+F17*Panel!$B$26)/60 | I17: =G17*Panel!$B$11-B17*Panel!$B$11*Panel!$B$17/30 | J17: =I17*(1-Panel!$B$18) | K17: =J17-G17*Panel!$C$11 | L17: =K17-Panel!$B$40 | M17: =M16+L17
A18: 9 | B18: =MAX(0,MIN(ROUND(Panel!$B$27*(1+Panel!$B$28)^(A18-1),0),ROUNDDOWN(MAX(0,Panel!$B$23-((C17+D17+E17)*Panel!$B$25+F17*Panel!$B$26)/60)/Panel!$B$24,0))) | C18: =B18 | D18: =C17*(1-Panel!$B$15) | E18: =D17*(1-Panel!$B$15) | F18: =(F17+E17)*(1-Panel!$B$16) | G18: =C18+D18+E18+F18 | H18: =B18*Panel!$B$24+((C18+D18+E18)*Panel!$B$25+F18*Panel!$B$26)/60 | I18: =G18*Panel!$B$11-B18*Panel!$B$11*Panel!$B$17/30 | J18: =I18*(1-Panel!$B$18) | K18: =J18-G18*Panel!$C$11 | L18: =K18-Panel!$B$40 | M18: =M17+L18
A19: 10 | B19: =MAX(0,MIN(ROUND(Panel!$B$27*(1+Panel!$B$28)^(A19-1),0),ROUNDDOWN(MAX(0,Panel!$B$23-((C18+D18+E18)*Panel!$B$25+F18*Panel!$B$26)/60)/Panel!$B$24,0))) | C19: =B19 | D19: =C18*(1-Panel!$B$15) | E19: =D18*(1-Panel!$B$15) | F19: =(F18+E18)*(1-Panel!$B$16) | G19: =C19+D19+E19+F19 | H19: =B19*Panel!$B$24+((C19+D19+E19)*Panel!$B$25+F19*Panel!$B$26)/60 | I19: =G19*Panel!$B$11-B19*Panel!$B$11*Panel!$B$17/30 | J19: =I19*(1-Panel!$B$18) | K19: =J19-G19*Panel!$C$11 | L19: =K19-Panel!$B$40 | M19: =M18+L19
A20: 11 | B20: =MAX(0,MIN(ROUND(Panel!$B$27*(1+Panel!$B$28)^(A20-1),0),ROUNDDOWN(MAX(0,Panel!$B$23-((C19+D19+E19)*Panel!$B$25+F19*Panel!$B$26)/60)/Panel!$B$24,0))) | C20: =B20 | D20: =C19*(1-Panel!$B$15) | E20: =D19*(1-Panel!$B$15) | F20: =(F19+E19)*(1-Panel!$B$16) | G20: =C20+D20+E20+F20 | H20: =B20*Panel!$B$24+((C20+D20+E20)*Panel!$B$25+F20*Panel!$B$26)/60 | I20: =G20*Panel!$B$11-B20*Panel!$B$11*Panel!$B$17/30 | J20: =I20*(1-Panel!$B$18) | K20: =J20-G20*Panel!$C$11 | L20: =K20-Panel!$B$40 | M20: =M19+L20
A21: 12 | B21: =MAX(0,MIN(ROUND(Panel!$B$27*(1+Panel!$B$28)^(A21-1),0),ROUNDDOWN(MAX(0,Panel!$B$23-((C20+D20+E20)*Panel!$B$25+F20*Panel!$B$26)/60)/Panel!$B$24,0))) | C21: =B21 | D21: =C20*(1-Panel!$B$15) | E21: =D20*(1-Panel!$B$15) | F21: =(F20+E20)*(1-Panel!$B$16) | G21: =C21+D21+E21+F21 | H21: =B21*Panel!$B$24+((C21+D21+E21)*Panel!$B$25+F21*Panel!$B$26)/60 | I21: =G21*Panel!$B$11-B21*Panel!$B$11*Panel!$B$17/30 | J21: =I21*(1-Panel!$B$18) | K21: =J21-G21*Panel!$C$11 | L21: =K21-Panel!$B$40 | M21: =M20+L21
A22: 13 | B22: =MAX(0,MIN(ROUND(Panel!$B$27*(1+Panel!$B$28)^(A22-1),0),ROUNDDOWN(MAX(0,Panel!$B$23-((C21+D21+E21)*Panel!$B$25+F21*Panel!$B$26)/60)/Panel!$B$24,0))) | C22: =B22 | D22: =C21*(1-Panel!$B$15) | E22: =D21*(1-Panel!$B$15) | F22: =(F21+E21)*(1-Panel!$B$16) | G22: =C22+D22+E22+F22 | H22: =B22*Panel!$B$24+((C22+D22+E22)*Panel!$B$25+F22*Panel!$B$26)/60 | I22: =G22*Panel!$B$11-B22*Panel!$B$11*Panel!$B$17/30 | J22: =I22*(1-Panel!$B$18) | K22: =J22-G22*Panel!$C$11 | L22: =K22-Panel!$B$40 | M22: =M21+L22
... A45: 36 | B45: =MAX(0,MIN(ROUND(Panel!$B$27*(1+Panel!$B$28)^(A45-1),0),ROUNDDOWN(MAX(0,Panel!$B$23-((C44+D44+E44)*Panel!$B$25+F44*Panel!$B$26)/60)/Panel!$B$24,0))) | C45: =B45 | D45: =C44*(1-Panel!$B$15) | E45: =D44*(1-Panel!$B$15) | F45: =(F44+E44)*(1-Panel!$B$16) | G45: =C45+D45+E45+F45 | H45: =B45*Panel!$B$24+((C45+D45+E45)*Panel!$B$25+F45*Panel!$B$26)/60 | I45: =G45*Panel!$B$11-B45*Panel!$B$11*Panel!$B$17/30 | J45: =I45*(1-Panel!$B$18) | K45: =J45-G45*Panel!$C$11 | L45: =K45-Panel!$B$40 | M45: =M44+L45
A47: «Horas usadas» en rojo significa que ese mes no te dio la vida: o recortas altas, o alguien mas atiende. «Mes 1/2/3» son las cuentas por edad; «Asentadas», las que pasaron de tres meses. El salto de la caja en el mes del equilibrio no es magia: es que la cartera ya paga tu retirada.

Sheet Escenarios
A1: Tres futuros, y cual de ellos aguanta
A2: Mismos costes por cuenta, distinta velocidad y distinta suerte con las bajas. Para usar uno, copia sus valores al Panel: el libro entero se recalcula. No hay selector automatico a proposito, para que quede por escrito que escenario estas mirando.
A6: Palanca | B6: Prudente | C6: Base | D6: Optimista | F6: Por que ese valor
A7: Altas objetivo al mes | B7: 3 | C7: 5 | D7: 8 | F7: El piloto comprometido son 3-5 negocios. Ocho al mes exige prescriptores funcionando.
A8: Crecimiento mensual del objetivo | B8: 0.02 | C8: 0.05 | D8: 0.1 | F8: Sin presupuesto de ads, el crecimiento es boca a boca.
A9: Bajas los tres primeros meses | B9: 0.12 | C9: 0.08 | D9: 0.05 | F9: Cuanto peor sea el arranque, mas se va la gente pronto.
A10: Bajas despues | B10: 0.06 | C10: 0.04 | D10: 0.02 | F10: Un producto que ya esta en la rutina del negocio retiene.
A11: Horas al mes para vender y atender | B11: 40 | C11: 60 | D11: 90 | F11: Depende de cuanto producto tengas que seguir construyendo.
A12: Minutos de soporte, cuenta nueva | B12: 45 | C12: 30 | D12: 20 | F12: Baja si el producto se explica solo.
A13: Retirada mensual del founder | B13: 1500 | C13: 1200 | D13: 1200 | F13: Lo prudente no es cobrar menos: es necesitar mas caja.
A15: El escenario prudente no es pesimismo: es el que hay que poder aguantar. Si solo sobrevives en el optimista, el plan no es un plan.
A18: Lo que decide cada escenario
A19: Si las bajas son del 12 % al principio | B19: La cartera se vacia casi tan rapido como entra: cada alta cuesta tres horas tuyas y dura poco mas de ocho meses.
A20: Si solo tienes 40 horas al mes | B20: El soporte alcanza tus horas mucho antes y el crecimiento se para sin que el mercado tenga nada que ver.
A21: Si el soporte baja de 30 a 20 minutos | B21: Es la palanca que mas cuentas te regala sin vender ni una mas. Ahi es donde paga el cerebro local.

Sheet Que_es_dato_y_que_no
A1: Que cifra es un dato y cual es una suposicion
A2: Con cero clientes de pago, casi todo este libro es una hipotesis. Separarlo es lo unico que impide confundir un escenario con una prevision. En rojo, lo que no esta medido y mas mueve el resultado.
A6: Cifra | B6: Valor | C6: Estado | D6: Origen o por que falta
A7: Precios 29 / 49 / 99 | B7: Adoptado | C7: DATO | D7: Decision del 15/07/2026, y coincide con el catalogo del codigo.
A8: Coste de software por cuenta | B8: 1,48 / 3,04 / 18,47 | C8: CALCULADO | D8: Analisis del 15/07/2026 sobre tarifas publicadas de Stripe, Meta, Anthropic, Groq y Railway.
A9: Plataforma fija por cuenta | B9: 0,07 EUR | C9: CALCULADO | D9: 7 EUR/mes repartidos entre 100 cuentas, segun el libro editado el 17/09/2026.
A10: Mezcla 55 / 35 / 10 | B10: Supuesto | C10: SIN MEDIR | D10: Nadie ha comprado todavia: el reparto real puede ser cualquiera.
A11: Bajas mensuales | B11: 8 % y 4 % | C11: SIN MEDIR | D11: No hay clientes de pago. Es la cifra que mas mueve el modelo.
A12: Horas disponibles al mes | B12: 60 | C12: SIN MEDIR | D12: Depende de cuanto producto sigas construyendo tu.
A13: Horas por alta | B13: 3 | C13: SIN MEDIR | D13: El analisis cifra el onboarding en 30-120 minutos; vender no esta medido.
A14: Minutos de soporte | B14: 30 y 12 | C14: SIN MEDIR | D14: Los 12 minutos salen del analisis; los 30 de cuenta nueva son una suposicion.
A15: Recibos no cobrados | B15: 3 % | C15: SIN MEDIR | D15: Se sabra con la primera remesa real de Stripe.
A16: Estructura mensual | B16: 160 EUR | C16: PENDIENTE | D16: Servidores, herramientas, gestoria y seguro: faltan las facturas reales, como recoge la hoja de datos pendientes del libro anterior.
A17: Cuota de autonomos | B17: 300 EUR | C17: PENDIENTE | D17: Depende de tarifa plana y de la forma juridica, sin decidir.
... A20: Clientes de pago hoy | B20: 0 | C20: DATO | D20: Por eso este libro es prospectivo y lo dice en la primera hoja.
A22: Lo que convierte esto en un modelo y no en un escenario: tres a cinco clientes de pago y treinta dias midiendo bajas, minutos de soporte por cuenta y cuantas horas te cuesta cerrar una venta. Con esas tres cifras medidas, las demas dejan de importar tanto.
