Workbook

Sheet Resumen
A1: Bynoesis — Modelo economico
A2: Modelo vivo: las celdas azules de la hoja Supuestos son entradas y el resto son formulas. No pregunta «cuanto ganaria con 500 clientes»: pregunta cuantos puedes atender tu solo, cuando dejas de perder dinero y cuanta caja hace falta hasta entonces. Con cero clientes de pago hoy, todo esto es un escenario; la hoja Datos_Pendientes dice que cifra es un dato y cual no.
A4: Catalogo adoptado
A5: Concepto | B5: Autonomo | C5: Negocio | D5: Premium | E5: Unidad | F5: Nota
A6: Precio mensual | B6: ='Supuestos'!B7 | C6: ='Supuestos'!C7 | D6: ='Supuestos'!D7 | E6: €/mes + IVA | F6: Decision del 15/07/2026
A7: Mezcla de clientes supuesta | B7: ='Supuestos'!B8 | C7: ='Supuestos'!C8 | D7: ='Supuestos'!D8 | E7: % | F7: SUPUESTO: nadie ha comprado todavia
A8: Precio anual (cobra 11, da 12) | B8: =Anual_vs_Mensual!C5 | C8: =Anual_vs_Mensual!C6 | D8: =Anual_vs_Mensual!C7 | E8: €/ano + IVA | F8: Descuento real del 8,3 %
A10: Lo que deja cada cuenta
A11: Metrica | B11: Autonomo | C11: Negocio | D11: Premium | E11: Media | F11: Nota
A12: COGS software | B12: ='Unit_Economics'!E13 | C12: ='Unit_Economics'!F13 | D12: ='Unit_Economics'!G13 | E12: ='Unit_Economics'!$B$33 | F12: Stripe, WhatsApp, IA, voz, almacenamiento
A13: Margen bruto | B13: ='Unit_Economics'!E14 | C13: ='Unit_Economics'!F14 | D13: ='Unit_Economics'!G14 | E13: =('Unit_Economics'!$B$32-'Unit_Economics'!$B$33)/'Unit_Economics'!$B$32 | F13: Sobre el precio de catalogo
A14: Contribucion EN CAJA | B14: ='Unit_Economics'!E21 | C14: ='Unit_Economics'!F21 | D14: ='Unit_Economics'!G21 | E14: ='Unit_Economics'!$B$35 | F14: Mientras atiendes tu. Es la que manda hoy
A15: Contribucion CARGADA | B15: ='Unit_Economics'!E18 | C15: ='Unit_Economics'!F18 | D15: ='Unit_Economics'!G18 | E15: ='Unit_Economics'!$B$36 | F15: Cuando el soporte lo paga alguien. Descuenta soporte y onboarding a 25 €/h
A17: Los tres equilibrios — la pregunta de verdad
A18: Nivel | B18: Cuentas | C18: Cuesta al mes | E18: Unidad | F18: Nota
A19: Cubrir solo la estructura | B19: ='Escala_Breakeven'!D6 | C19: ='Escala_Breakeven'!B6 | E19: cuentas | F19: Sin cobrar nada tu
A20: Cubrir estructura y cuota de autonomos | B20: ='Escala_Breakeven'!D7 | C20: ='Escala_Breakeven'!B7 | E20: cuentas | F20: Dejas de poner dinero de tu bolsillo
A21: EQUILIBRIO DE VERDAD: ademas te pagas la retirada | B21: ='Escala_Breakeven'!D8 | C21: ='Escala_Breakeven'!B8 | E21: cuentas | F21: La cifra que hay que mirar
A22: El mismo, con el soporte pagado a otra persona | B22: ='Escala_Breakeven'!D9 | C22: ='Escala_Breakeven'!B9 | E22: cuentas | F22: La contribucion baja y el equilibrio sube
A24: Tiempo y caja — lo que decide si el plan es posible
A25: Pregunta | B25: Respuesta | E25: Unidad | F25: Como se calcula
A26: Cuentas que puedes atender tu solo | B26: ='Horas_del_founder'!$B$9 | E26: cuentas | F26: Donde el soporte se come todas tus horas y no queda ninguna para vender
A27: Techo practico (soporte al 70 % de tus horas) | B27: ='Horas_del_founder'!$B$10 | E27: cuentas | F27: El punto en que hay que decidir: bajar soporte por cuenta o contratar
A28: ¿Cabe el equilibrio en tus horas? | B28: ='Escala_Breakeven'!$B$17 | F28: Compara el equilibrio de verdad con tu capacidad
A29: Mes en que dejas de perder dinero | B29: ='Rampa_36m'!$D$6 | E29: mes | F29: Primer mes con resultado positivo, con tu retirada dentro
A30: Caja minima por el camino | B30: ='Rampa_36m'!$D$7 | E30: € | F30: El punto mas bajo: el dinero que hay que poder aguantar
A31: Caja inicial disponible | B31: =Supuestos!$B$73 | E31: € | F31: PENDIENTE de confirmar. Si la caja minima la supera, el plan no es financiable
A32: Cuentas al mes 36 | B32: ='Rampa_36m'!$D$8 | E32: cuentas | F32: Hasta donde llega la rampa con tus horas
A33: Vida media del cliente | B33: ='Unit_Economics'!$E$28 | E33: meses | F33: Con bajas del 8 % los tres primeros meses y del 4 % despues
A34: LTV / CAC | B34: =IF(Supuestos!$B$77<=0,"-",'Unit_Economics'!$B$35*'Unit_Economics'!$E$28/Supuestos!$B$77) | E34: veces | F34: Referencia SaaS: 3x o mas. El CAC de 150 € esta sin validar
A36: Aviso
A37: Ninguna cifra de este libro es un resultado observado: no hay clientes de pago. Son supuestos de planificacion fechados que el piloto debe recalibrar. Lo unico auditable linea a linea es el COGS por plan, que sale de tarifas publicadas. Todo lo demas —bajas, minutos de soporte, horas por alta, mezcla de planes, CAC— es una hipotesis, y las tres primeras son las que mas mueven el resultado. Este libro sirve para decidir que medir en el piloto, no para prometer nada a nadie.

Sheet Calculadora
A1: Calculadora: escribe cuantos clientes tienes
A2: Cambia solo las tres celdas naranjas y el resto responde: ingresos, cada linea de coste, las horas que se te van en atenderlos, el resultado del mes y cuanto falta para el equilibrio. Es la hoja para jugar; las demas explican de donde sale cada cifra.
A4: 1 · Cuantos clientes de cada plan
A5: Plan | B5: Clientes | C5: Precio | D5: Facturado al mes | E5: Cobrado al mes | F5: Nota
A6: Autonomo | B6: 0 | C6: ='Supuestos'!B7 | D6: =B6*C6 | E6: =D6*(1-Supuestos!$B$45)
A7: Negocio | B7: 0 | C7: ='Supuestos'!C7 | D7: =B7*C7 | E7: =D7*(1-Supuestos!$B$45)
A8: Premium | B8: 0 | C8: ='Supuestos'!D7 | D8: =B8*C8 | E8: =D8*(1-Supuestos!$B$45)
A9: TOTAL | B9: =SUM(B6:B8) | D9: =SUM(D6:D8) | E9: =SUM(E6:E8) | F9: Sin IVA. Cobrado ya descuenta los recibos que no se cobran
A11: 2 · Lo que cuesta servirlos, en dinero
A12: Concepto | B12: Autonomo | C12: Negocio | D12: Premium | E12: Total | F12: € por cliente
A13: Comisiones de Stripe | B13: =$B$6*'Unit_Economics'!E6 | C13: =$B$7*'Unit_Economics'!F6 | D13: =$B$8*'Unit_Economics'!G6 | E13: =SUM(B13:D13) | F13: =IFERROR(E13/$B$9,"")
A14: WhatsApp (plantillas) | B14: =$B$6*'Unit_Economics'!E7 | C14: =$B$7*'Unit_Economics'!F7 | D14: =$B$8*'Unit_Economics'!G7 | E14: =SUM(B14:D14) | F14: =IFERROR(E14/$B$9,"")
A15: IA avanzada | B15: =$B$6*'Unit_Economics'!E8 | C15: =$B$7*'Unit_Economics'!F8 | D15: =$B$8*'Unit_Economics'!G8 | E15: =SUM(B15:D15) | F15: =IFERROR(E15/$B$9,"")
A16: Transcripcion de voz | B16: =$B$6*'Unit_Economics'!E9 | C16: =$B$7*'Unit_Economics'!F9 | D16: =$B$8*'Unit_Economics'!G9 | E16: =SUM(B16:D16) | F16: =IFERROR(E16/$B$9,"")
A17: Extraccion de documentos | B17: =$B$6*'Unit_Economics'!E10 | C17: =$B$7*'Unit_Economics'!F10 | D17: =$B$8*'Unit_Economics'!G10 | E17: =SUM(B17:D17) | F17: =IFERROR(E17/$B$9,"")
A18: Almacenamiento | B18: =$B$6*'Unit_Economics'!E11 | C18: =$B$7*'Unit_Economics'!F11 | D18: =$B$8*'Unit_Economics'!G11 | E18: =SUM(B18:D18) | F18: =IFERROR(E18/$B$9,"")
A19: Voz telefonica (Premium) | B19: =$B$6*'Unit_Economics'!E12 | C19: =$B$7*'Unit_Economics'!F12 | D19: =$B$8*'Unit_Economics'!G12 | E19: =SUM(B19:D19) | F19: =IFERROR(E19/$B$9,"")
A20: TOTAL COSTES VARIABLES | B20: =SUM(B13:B19) | C20: =SUM(C13:C19) | D20: =SUM(D13:D19) | E20: =SUM(E13:E19) | F20: =IFERROR(E20/$B$9,"")
A22: 3 · Lo que cuesta atenderlos, en tu tiempo
A23: Concepto | B23: Autonomo | C23: Negocio | D23: Premium | E23: Total | F23: Lectura
A24: Horas de soporte al mes | B24: =$B$6*'Supuestos'!B19/60 | C24: =$B$7*'Supuestos'!C19/60 | D24: =$B$8*'Supuestos'!D19/60 | E24: =SUM(B24:D24) | F24: Solo soporte: no incluye el tiempo de vender ni de poner en marcha
A25: Porcentaje de tus horas | E25: =IFERROR(E24/Supuestos!$B$51,"") | F25: Por encima del 70 % no queda mes para vender
A26: Horas que te quedan para vender | E26: =MAX(0,Supuestos!$B$51-E24) | F26: Lo que sobra despues de atender a esa cartera
A27: Altas que puedes cerrar con ese resto | E27: =ROUNDDOWN(E26/Supuestos!$B$52,0) | F27: A las horas por alta del panel de supuestos
A28: Si ese soporte lo pagaras a otra persona | E28: =E24*Supuestos!$B$55 | F28: No sale de caja mientras lo hagas tu, pero es lo que costaria delegarlo
A30: 4 · Lo que sale de caja, tengas los clientes que tengas
A31: Concepto | B31: Mensual | E31: Anual | F31: Nota
A32: Estructura (plataforma, herramientas, gestoria, seguro, publicidad) | B32: =Supuestos!$B$69 | E32: =B32*12 | F32: Del bloque 5 de la hoja Supuestos
A33: Cuota de autonomos | B33: =Supuestos!$B$70 | E33: =B33*12 | F33: PENDIENTE de la gestoria
A34: Lo que quieres cobrar tu | B34: =Supuestos!$B$71 | E34: =B34*12 | F34: Es una decision, no un dato. Sin esta linea el equilibrio no significa nada
A35: TOTAL SALIDA DE CAJA | B35: =SUM(B32:B34) | E35: =B35*12
A37: 5 · Resultado del mes
A38: Metrica | B38: Mensual | E38: Anual | F38: Nota
A39: Ingreso cobrado | B39: =E9 | E39: =B39*12 | F39: Facturado menos los recibos que no se cobran
A40: (-) Costes variables | B40: =-E20 | E40: =B40*12 | F40: Escalan con cada cliente nuevo
A41: MARGEN BRUTO | B41: =B39+B40 | E41: =B41*12 | F41: Lo que queda para pagar la estructura y pagarte a ti
A42: (-) Salida de caja | B42: =-B35 | E42: =B42*12 | F42: Estructura, cuota y tu retirada
A43: RESULTADO DEL MES | B43: =B41+B42 | E43: =B43*12 | F43: Lo que gana o pierde la empresa cada mes
A44: Margen sobre ingreso | B44: =IFERROR(B43/B39,"")
A46: 6 · Cuanto falta para el equilibrio
...

Sheet Supuestos
A1: Supuestos
A2: Celdas azules = entradas editables; cambiarlas recalcula todo el libro. Cada driver lleva fecha y origen. SUPUESTO en ambar significa que la cifra no esta medida: es una decision de planificacion, no un dato de la empresa. Con cero clientes de pago, casi todo lo de abajo es una hipotesis.
A4: 1 · Por plan — que incluye y cuanto se usa
A5: Driver | B5: Autonomo | C5: Negocio | D5: Premium | E5: Unidad | F5: Fuente / criterio
A6: Precio anterior | B6: 29 | C6: 39 | D6: 79 | E6: €/mes + IVA | F6: Catalogo de antes del analisis. Solo sirve para comparar
A7: Precio adoptado | B7: 29 | C7: 49 | D7: 99 | E7: €/mes + IVA | F7: DATO: decision del 15/07/2026; coincide con el catalogo del codigo
A8: Mezcla de clientes | B8: 0.55 | C8: 0.35 | D8: 0.1 | E8: % | F8: SUPUESTO: nadie ha comprado todavia. Debe sumar 100 %
A9: Creditos avanzados incluidos | B9: 75 | C9: 300 | D9: 1500 | E9: acciones/mes | F9: Catalogo actual
A10: Uso esperado del limite | B10: 0.35 | C10: 0.4 | D10: 0.25 | E10: % | F10: SUPUESTO conservador
A11: Resuelve el cerebro interno | B11: 0.6 | C11: 0.6 | D11: 0.6 | E11: % | F11: Objetivo tras el piloto. Si baja del 40 %, el coste de IA se dispara
A12: WhatsApp utility enviados | B12: 30 | C12: 80 | D12: 200 | E12: mensajes/mes | F12: SUPUESTO operativo
A13: WhatsApp service recibidos | B13: 100 | C13: 300 | D13: 1000 | E13: mensajes/mes | F13: Gratis hoy; queda para la sensibilidad futura
A14: Audio transcrito | B14: 15 | C14: 60 | D14: 200 | E14: min/mes | F14: SUPUESTO operativo
A15: Documentos procesados | B15: 15 | C15: 50 | D15: 200 | E15: docs/mes | F15: SUPUESTO operativo
A16: Documentos que escalan fuera | B16: 0.2 | C16: 0.2 | D16: 0.2 | E16: % | F16: OCR local primero
A17: Almacenamiento | B17: 0.25 | C17: 1 | D17: 3 | E17: GB/cuenta | F17: SUPUESTO operativo
... A20: Onboarding inicial | B20: 30 | C20: 60 | D20: 120 | E20: min/cuenta | F20: Amortizado en 12 meses
A21: =IF(ABS(B8+C8+D8-1)>0.0001,"AVISO: la mezcla de planes no suma 100 %","Mezcla correcta: suma 100 %")
A23: 2 · Tarifas de proveedores — lo que cobran por usarlos
A24: Driver | B24: Valor | C24: Unidad | D24: Fecha | E24: Origen | F24: Nota
A25: EUR por USD | B25: 0.87680842 | C25: EUR/USD | D25: 14/07/2026 | E25: ECB | F25: 1 EUR = 1,1405 USD
A26: Stripe Payments | B26: 0.015 | C26: % del ingreso | D26: 15/07/2026 | E26: Stripe | F26: Tarjeta EEE estandar
A27: Stripe Billing | B27: 0.007 | C27: % del ingreso | D27: 15/07/2026 | E27: Stripe | F27: Facturacion por uso
A28: Stripe fijo | B28: 0.25 | C28: €/transaccion | D28: 15/07/2026 | E28: Stripe | F28: Una renovacion al mes
A29: WhatsApp utility Espana | B29: 0.0166 | C29: €/mensaje | D29: 15/07/2026 | E29: Meta / rate card | F29: Mensaje entregado
A30: WhatsApp service futuro | B30: 0.0166 | C30: €/mensaje | D30: 15/07/2026 | E30: Sensibilidad | F30: Hoy cuesta 0 €
A31: Haiku 4.5 por interaccion | B31: 0.014 | C31: USD/interaccion | D31: 15/07/2026 | E31: Anthropic | F31: 8k de entrada y 1,2k de salida
A32: Qwen3 32B por interaccion | B32: 0.003028 | C32: USD/interaccion | D32: 15/07/2026 | E32: Groq | F32: Mismo supuesto de tokens
A33: Peso de Qwen en el respaldo | B33: 0.8 | C33: % | D33: 15/07/2026 | E33: Arquitectura hibrida | F33: El resto va a Haiku
A34: Whisper Turbo | B34: 0.04 | C34: USD/hora | D34: 15/07/2026 | E34: Groq | F34: Solo transcripcion
A35: Extraccion externa de documento | B35: 0.012 | C35: €/documento | D35: 15/07/2026 | E35: SUPUESTO | F35: Validar con un corpus real
A36: Object storage | B36: 0.015 | C36: USD/GB-mes | D36: 15/07/2026 | E36: Railway | F36: Sin egress
... A38: Numero telefonico de voz | B38: 2 | C38: USD/mes | D38: 15/07/2026 | E38: Retell | F38: Solo plan Premium
A40: 3 · Como se comporta un cliente — nada de esto esta medido
A41: Driver | B41: Valor | C41: Unidad | D41: Fecha | E41: Origen | F41: Nota
A42: Bajas los tres primeros meses | B42: 0.08 | C42: %/mes | D42: 17/09/2026 | E42: SUPUESTO | F42: Una cartera nueva pierde mas al principio: quien no llega a usarlo se va pronto
A43: Bajas a partir del cuarto mes | B43: 0.04 | C43: %/mes | D43: 17/09/2026 | E43: SUPUESTO | F43: Quien pasa de los tres meses suele quedarse
A44: Dias de prueba gratis | B44: 14 | C44: dias | D44: 15/07/2026 | E44: Producto | F44: El primer mes de cada alta no se cobra entero
A45: Recibos que no se cobran | B45: 0.03 | C45: % | D45: 17/09/2026 | E45: SUPUESTO | F45: Tarjetas caducadas y devoluciones. Se sabra con la primera remesa de Stripe
A46: Contratan plan anual | B46: 0.2 | C46: % | D46: 17/09/2026 | E46: SUPUESTO | F46: El anual adelanta once meses de caja y ahorra comisiones
...

Sheet Unit_Economics
A1: Unit economics por plan
A2: Escenario hibrido: el cerebro interno resuelve el 60 %; del resto, 80 % Qwen y 20 % Haiku. Columnas B-D = catalogo anterior (29/39/79); columnas E-G = catalogo adoptado (29/49/99). Esta hoja es lo que este libro tiene y los otros dos no: el coste sale de los drivers uno a uno, no de un total copiado.
A4: Metrica | B4: Autonomo ant. | C4: Negocio ant. | D4: Premium ant. | E4: Autonomo adop. | F4: Negocio adop. | G4: Premium adop. | H4: Unidad
A5: Precio de catalogo | B5: ='Supuestos'!B$6 | C5: ='Supuestos'!C$6 | D5: ='Supuestos'!D$6 | E5: ='Supuestos'!B$7 | F5: ='Supuestos'!C$7 | G5: ='Supuestos'!D$7 | H5: €/mes
A6: Stripe | B6: =B5*(Supuestos!$B$26+Supuestos!$B$27)+Supuestos!$B$28 | C6: =C5*(Supuestos!$B$26+Supuestos!$B$27)+Supuestos!$B$28 | D6: =D5*(Supuestos!$B$26+Supuestos!$B$27)+Supuestos!$B$28 | E6: =E5*(Supuestos!$B$26+Supuestos!$B$27)+Supuestos!$B$28 | F6: =F5*(Supuestos!$B$26+Supuestos!$B$27)+Supuestos!$B$28 | G6: =G5*(Supuestos!$B$26+Supuestos!$B$27)+Supuestos!$B$28 | H6: €/mes
A7: WhatsApp utility | B7: ='Supuestos'!B$12*Supuestos!$B$29 | C7: ='Supuestos'!C$12*Supuestos!$B$29 | D7: ='Supuestos'!D$12*Supuestos!$B$29 | E7: ='Supuestos'!B$12*Supuestos!$B$29 | F7: ='Supuestos'!C$12*Supuestos!$B$29 | G7: ='Supuestos'!D$12*Supuestos!$B$29 | H7: €/mes
A8: IA avanzada | B8: ='Supuestos'!B$9*'Supuestos'!B$10*(1-'Supuestos'!B$11)*(Supuestos!$B$33*Supuestos!$B$32+(1-Supuestos!$B$33)*Supuestos!$B$31)*Supuestos!$B$25 | C8: ='Supuestos'!C$9*'Supuestos'!C$10*(1-'Supuestos'!C$11)*(Supuestos!$B$33*Supuestos!$B$32+(1-Supuestos!$B$33)*Supuestos!$B$31)*Supuestos!$B$25 | D8: ='Supuestos'!D$9*'Supuestos'!D$10*(1-'Supuestos'!D$11)*(Supuestos!$B$33*Supuestos!$B$32+(1-Supuestos!$B$33)*Supuestos!$B$31)*Supuestos!$B$25 | E8: ='Supuestos'!B$9*'Supuestos'!B$10*(1-'Supuestos'!B$11)*(Supuestos!$B$33*Supuestos!$B$32+(1-Supuestos!$B$33)*Supuestos!$B$31)*Supuestos!$B$25 | F8: ='Supuestos'!C$9*'Supuestos'!C$10*(1-'Supuestos'!C$11)*(Supuestos!$B$33*Supuestos!$B$32+(1-Supuestos!$B$33)*Supuestos!$B$31)*Supuestos!$B$25 | G8: ='Supuestos'!D$9*'Supuestos'!D$10*(1-'Supuestos'!D$11)*(Supuestos!$B$33*Supuestos!$B$32+(1-Supuestos!$B$33)*Supuestos!$B$31)*Supuestos!$B$25 | H8: €/mes
A9: Transcripcion | B9: ='Supuestos'!B$14/60*Supuestos!$B$34*Supuestos!$B$25 | C9: ='Supuestos'!C$14/60*Supuestos!$B$34*Supuestos!$B$25 | D9: ='Supuestos'!D$14/60*Supuestos!$B$34*Supuestos!$B$25 | E9: ='Supuestos'!B$14/60*Supuestos!$B$34*Supuestos!$B$25 | F9: ='Supuestos'!C$14/60*Supuestos!$B$34*Supuestos!$B$25 | G9: ='Supuestos'!D$14/60*Supuestos!$B$34*Supuestos!$B$25 | H9: €/mes
A10: Extraccion externa | B10: ='Supuestos'!B$15*'Supuestos'!B$16*Supuestos!$B$35 | C10: ='Supuestos'!C$15*'Supuestos'!C$16*Supuestos!$B$35 | D10: ='Supuestos'!D$15*'Supuestos'!D$16*Supuestos!$B$35 | E10: ='Supuestos'!B$15*'Supuestos'!B$16*Supuestos!$B$35 | F10: ='Supuestos'!C$15*'Supuestos'!C$16*Supuestos!$B$35 | G10: ='Supuestos'!D$15*'Supuestos'!D$16*Supuestos!$B$35 | H10: €/mes
A11: Almacenamiento | B11: ='Supuestos'!B$17*Supuestos!$B$36*Supuestos!$B$25 | C11: ='Supuestos'!C$17*Supuestos!$B$36*Supuestos!$B$25 | D11: ='Supuestos'!D$17*Supuestos!$B$36*Supuestos!$B$25 | E11: ='Supuestos'!B$17*Supuestos!$B$36*Supuestos!$B$25 | F11: ='Supuestos'!C$17*Supuestos!$B$36*Supuestos!$B$25 | G11: ='Supuestos'!D$17*Supuestos!$B$36*Supuestos!$B$25 | H11: €/mes
A12: Voz Premium | B12: =IF('Supuestos'!B$18>0,'Supuestos'!B$18*Supuestos!$B$37*Supuestos!$B$25+Supuestos!$B$38*Supuestos!$B$25,0) | C12: =IF('Supuestos'!C$18>0,'Supuestos'!C$18*Supuestos!$B$37*Supuestos!$B$25+Supuestos!$B$38*Supuestos!$B$25,0) | D12: =IF('Supuestos'!D$18>0,'Supuestos'!D$18*Supuestos!$B$37*Supuestos!$B$25+Supuestos!$B$38*Supuestos!$B$25,0) | E12: =IF('Supuestos'!B$18>0,'Supuestos'!B$18*Supuestos!$B$37*Supuestos!$B$25+Supuestos!$B$38*Supuestos!$B$25,0) | F12: =IF('Supuestos'!C$18>0,'Supuestos'!C$18*Supuestos!$B$37*Supuestos!$B$25+Supuestos!$B$38*Supuestos!$B$25,0) | G12: =IF('Supuestos'!D$18>0,'Supuestos'!D$18*Supuestos!$B$37*Supuestos!$B$25+Supuestos!$B$38*Supuestos!$B$25,0) | H12: €/mes
A13: COGS software | B13: =SUM(B6:B12) | C13: =SUM(C6:C12) | D13: =SUM(D6:D12) | E13: =SUM(E6:E12) | F13: =SUM(F6:F12) | G13: =SUM(G6:G12) | H13: €/mes
A14: Margen bruto software | B14: =(B5-B13)/B5 | C14: =(C5-C13)/C5 | D14: =(D5-D13)/D5 | E14: =(E5-E13)/E5 | F14: =(F5-F13)/F5 | G14: =(G5-G13)/G5 | H14: %
A15: Soporte humano, SI lo paga alguien | B15: ='Supuestos'!B$19/60*Supuestos!$B$55 | C15: ='Supuestos'!C$19/60*Supuestos!$B$55 | D15: ='Supuestos'!D$19/60*Supuestos!$B$55 | E15: ='Supuestos'!B$19/60*Supuestos!$B$55 | F15: ='Supuestos'!C$19/60*Supuestos!$B$55 | G15: ='Supuestos'!D$19/60*Supuestos!$B$55 | H15: €/mes
A16: Onboarding amortizado, SI lo paga alguien | B16: ='Supuestos'!B$20/60*Supuestos!$B$55/12 | C16: ='Supuestos'!C$20/60*Supuestos!$B$55/12 | D16: ='Supuestos'!D$20/60*Supuestos!$B$55/12 | E16: ='Supuestos'!B$20/60*Supuestos!$B$55/12 | F16: ='Supuestos'!C$20/60*Supuestos!$B$55/12 | G16: ='Supuestos'!D$20/60*Supuestos!$B$55/12 | H16: €/mes
A17: Plataforma asignada por cuenta | B17: =Supuestos!$B$61/Supuestos!$B$89 | C17: =Supuestos!$B$61/Supuestos!$B$89 | D17: =Supuestos!$B$61/Supuestos!$B$89 | E17: =Supuestos!$B$61/Supuestos!$B$89 | F17: =Supuestos!$B$61/Supuestos!$B$89 | G17: =Supuestos!$B$61/Supuestos!$B$89 | H17: €/mes
A18: CONTRIBUCION CARGADA (soporte pagado) | B18: =B20-B13-B15-B16 | C18: =C20-C13-C15-C16 | D18: =D20-D13-D15-D16 | E18: =E20-E13-E15-E16 | F18: =F20-F13-F15-F16 | G18: =G20-G13-G15-G16 | H18: €/mes
A19: Margen de contribucion cargada | B19: =B18/B5 | C19: =C18/C5 | D19: =D18/D5 | E19: =E18/E5 | F19: =F18/F5 | G19: =G18/G5 | H19: %
A20: Precio realmente cobrado (tras impagos) | B20: =B5*(1-Supuestos!$B$45) | C20: =C5*(1-Supuestos!$B$45) | D20: =D5*(1-Supuestos!$B$45) | E20: =E5*(1-Supuestos!$B$45) | F20: =F5*(1-Supuestos!$B$45) | G20: =G5*(1-Supuestos!$B$45) | H20: €/mes
A21: CONTRIBUCION EN CAJA (atiendes tu) | B21: =B20-B13 | C21: =C20-C13 | D21: =D20-D13 | E21: =E20-E13 | F21: =F20-F13 | G21: =G20-G13 | H21: €/mes
A22: Margen de contribucion en caja | B22: =B21/B5 | C22: =C21/C5 | D22: =D21/D5 | E22: =E21/E5 | F22: =F21/F5 | G22: =G21/G5 | H22: %
A23: Ingreso si el precio incluyera IVA | B23: =B5/(1+Supuestos!$B$88) | C23: =C5/(1+Supuestos!$B$88) | D23: =D5/(1+Supuestos!$B$88) | E23: =E5/(1+Supuestos!$B$88) | F23: =F5/(1+Supuestos!$B$88) | G23: =G5/(1+Supuestos!$B$88) | H23: €/mes
A24: Contribucion en caja si incluyera IVA | B24: =B23*(1-Supuestos!$B$45)-B13 | C24: =C23*(1-Supuestos!$B$45)-C13 | D24: =D23*(1-Supuestos!$B$45)-D13 | E24: =E23*(1-Supuestos!$B$45)-E13 | F24: =F23*(1-Supuestos!$B$45)-F13 | G24: =G23*(1-Supuestos!$B$45)-G13 | H24: €/mes
A25: IA en el peor caso: 100 % Haiku | B25: ='Supuestos'!B$9*Supuestos!$B$31*Supuestos!$B$25 | C25: ='Supuestos'!C$9*Supuestos!$B$31*Supuestos!$B$25 | D25: ='Supuestos'!D$9*Supuestos!$B$31*Supuestos!$B$25 | E25: ='Supuestos'!B$9*Supuestos!$B$31*Supuestos!$B$25 | F25: ='Supuestos'!C$9*Supuestos!$B$31*Supuestos!$B$25 | G25: ='Supuestos'!D$9*Supuestos!$B$31*Supuestos!$B$25 | H25: €/mes
A26: Margen bruto en el peor caso de IA | B26: =(B5-(B13-B8+B25))/B5 | C26: =(C5-(C13-C8+C25))/C5 | D26: =(D5-(D13-D8+D25))/D5 | E26: =(E5-(E13-E8+E25))/E5 | F26: =(F5-(F13-F8+F25))/F5 | G26: =(G5-(G13-G8+G25))/G5 | H26: %
A27: Minutos de soporte al mes | B27: ='Supuestos'!B$19 | C27: ='Supuestos'!C$19 | D27: ='Supuestos'!D$19 | E27: ='Supuestos'!B$19 | F27: ='Supuestos'!C$19 | G27: ='Supuestos'!D$19 | H27: min/mes
A28: Vida media del cliente | B28: =1+(1-Supuestos!$B$42)+(1-Supuestos!$B$42)^2+(1-Supuestos!$B$42)^3/Supuestos!$B$43 | C28: =1+(1-Supuestos!$B$42)+(1-Supuestos!$B$42)^2+(1-Supuestos!$B$42)^3/Supuestos!$B$43 | D28: =1+(1-Supuestos!$B$42)+(1-Supuestos!$B$42)^2+(1-Supuestos!$B$42)^3/Supuestos!$B$43 | E28: =1+(1-Supuestos!$B$42)+(1-Supuestos!$B$42)^2+(1-Supuestos!$B$42)^3/Supuestos!$B$43 | F28: =1+(1-Supuestos!$B$42)+(1-Supuestos!$B$42)^2+(1-Supuestos!$B$42)^3/Supuestos!$B$43 | G28: =1+(1-Supuestos!$B$42)+(1-Supuestos!$B$42)^2+(1-Supuestos!$B$42)^3/Supuestos!$B$43 | H28: meses
A29: LTV sobre contribucion en caja | B29: =B21*B28 | C29: =C21*C28 | D29: =D21*D28 | E29: =E21*E28 | F29: =F21*F28 | G29: =G21*G28 | H29: €
A31: Media ponderada con la mezcla actual (catalogo adoptado)
A32: Cuota media (ARPU) | B32: =SUMPRODUCT(E5:G5,'Supuestos'!B8:D8) | C32: Precio de cada plan por su peso en la mezcla
A33: COGS medio por cuenta | B33: =SUMPRODUCT(E13:G13,'Supuestos'!B8:D8) | C33: Lo que cuesta en dinero servir una cuenta media
A34: Soporte y onboarding medios | B34: =SUMPRODUCT(E15:G15,'Supuestos'!B8:D8)+SUMPRODUCT(E16:G16,'Supuestos'!B8:D8) | C34: Solo es gasto si ese soporte lo paga alguien que no eres tu
A35: CONTRIBUCION MEDIA EN CAJA | B35: =SUMPRODUCT(E21:G21,'Supuestos'!B8:D8) | C35: La que manda mientras atiendes tu: tu tiempo entra como capacidad, no como gasto
A36: CONTRIBUCION MEDIA CARGADA | B36: =SUMPRODUCT(E18:G18,'Supuestos'!B8:D8) | C36: La que manda en cuanto el soporte lo paga alguien
A37: Minutos de soporte por cuenta | B37: =SUMPRODUCT(E27:G27,'Supuestos'!B8:D8) | C37: Ponderados por la mezcla. El libro v3 uso los 12 min del plan Autonomo para toda la cartera; con 35 % de Negocio y 10 % de Premium salen mas
A39: Las dos contribuciones no son dos opiniones: son dos negocios distintos. Mientras el founder atiende, su tiempo no sale de la caja y la buena es la contribucion EN CAJA; lo que limita entonces no es el margen sino las horas, y eso lo mide la hoja Horas_del_founder. En cuanto ese soporte lo paga alguien, la buena es la CARGADA. El libro de agosto usaba la cargada y ademas metia una retirada del founder en el opex: contaba su tiempo dos veces y por eso el equilibrio salia optimista.

Sheet Escala_Breakeven
A1: Los tres equilibrios
A2: El libro de agosto daba una sola cifra —120 cuentas con 3.500 € de opex— y al cambiar el opex a 500 € daba 17, que describe un negocio donde nadie cobra. No hay un equilibrio: hay tres, y solo el tercero significa que esto te da de comer.
A4: Los tres niveles
A5: Nivel | B5: Coste mensual | C5: Contribucion usada | D5: Cuentas necesarias | E5: Ingreso cobrado en ese punto | F5: Que significa
A6: Cubrir solo la estructura | B6: =Supuestos!$B$69 | C6: ='Unit_Economics'!$B$35 | D6: =IF(C6<=0,"-",ROUNDUP(B6/C6,0)) | E6: =IF(C6<=0,"-",D6*'Unit_Economics'!$B$32*(1-Supuestos!$B$45)) | F6: Servidores, herramientas, gestoria y seguro. No cobras nada.
A7: Cubrir estructura y cuota de autonomos | B7: =Supuestos!$B$69+Supuestos!$B$70 | C7: ='Unit_Economics'!$B$35 | D7: =IF(C7<=0,"-",ROUNDUP(B7/C7,0)) | E7: =IF(C7<=0,"-",D7*'Unit_Economics'!$B$32*(1-Supuestos!$B$45)) | F7: El minimo para no poner dinero de tu bolsillo cada mes. Sigues sin cobrar.
A8: EL EQUILIBRIO DE VERDAD: ademas te pagas la retirada | B8: =Supuestos!$B$72 | C8: ='Unit_Economics'!$B$35 | D8: =IF(C8<=0,"-",ROUNDUP(B8/C8,0)) | E8: =IF(C8<=0,"-",D8*'Unit_Economics'!$B$32*(1-Supuestos!$B$45)) | F8: Cuando esto deja de ser un hobby. Es la cifra que hay que mirar.
A9: El mismo, pero con el soporte pagado a otra persona | B9: =Supuestos!$B$72 | C9: ='Unit_Economics'!$B$36 | D9: =IF(C9<=0,"-",ROUNDUP(B9/C9,0)) | E9: =IF(C9<=0,"-",D9*'Unit_Economics'!$B$32*(1-Supuestos!$B$45)) | F9: Cuando ya no atiendes tu. La contribucion baja y el equilibrio sube.
A11: ¿Cabe ese equilibrio en tus horas?
A12: Metrica | B12: Valor | D12: Unidad | F12: Lectura
A13: Cuentas del equilibrio de verdad | B13: =D8 | D13: cuentas | F13: De la tabla de arriba
A14: Horas de soporte que exigen al mes | B14: =B13*'Unit_Economics'!$B$37/60 | D14: h/mes | F14: Con los minutos medios ponderados por la mezcla
A15: Horas que te quedan para vender | B15: =Supuestos!$B$51-B14 | D15: h/mes | F15: Lo que sobra despues de atender a esa cartera
A16: Altas que puedes cerrar con ese resto | B16: =ROUNDDOWN(MAX(0,B15)/Supuestos!$B$52,0) | D16: altas/mes | F16: A las horas por alta del panel de supuestos
A17: Veredicto | B17: =IF(B15<=0,"NO: esa cartera te ocupa el mes entero y no podrias ni venderla",IF(B15<Supuestos!$B$51*0.3,"JUSTO: llegarias, pero sin margen para vender","SI: cabe en tus horas con sitio para seguir vendiendo")) | F17: Compara el equilibrio con tu capacidad real
A19: Escala: que pasa segun el tamano de la cartera
A20: Cuentas | B20: Ingreso cobrado | C20: Contribucion en caja | D20: Salida de caja | E20: Resultado | F20: Margen | G20: Horas de soporte | H20: Situacion
A21: 10 | B21: =A21*'Unit_Economics'!$B$32*(1-Supuestos!$B$45) | C21: =A21*'Unit_Economics'!$B$35 | D21: =Supuestos!$B$72 | E21: =C21-D21 | F21: =IF(B21>0,E21/B21,"") | G21: =A21*'Unit_Economics'!$B$37/60 | H21: =IF(G21>Supuestos!$B$51,"Imposible tu solo: el soporte pasa de tus horas",IF(G21>Supuestos!$B$51*0.7,"Al limite: el soporte se come el mes",IF(G21>Supuestos!$B$51*0.4,"Creces despacio","Tienes margen para vender")))
A22: 25 | B22: =A22*'Unit_Economics'!$B$32*(1-Supuestos!$B$45) | C22: =A22*'Unit_Economics'!$B$35 | D22: =Supuestos!$B$72 | E22: =C22-D22 | F22: =IF(B22>0,E22/B22,"") | G22: =A22*'Unit_Economics'!$B$37/60 | H22: =IF(G22>Supuestos!$B$51,"Imposible tu solo: el soporte pasa de tus horas",IF(G22>Supuestos!$B$51*0.7,"Al limite: el soporte se come el mes",IF(G22>Supuestos!$B$51*0.4,"Creces despacio","Tienes margen para vender")))
A23: 44 | B23: =A23*'Unit_Economics'!$B$32*(1-Supuestos!$B$45) | C23: =A23*'Unit_Economics'!$B$35 | D23: =Supuestos!$B$72 | E23: =C23-D23 | F23: =IF(B23>0,E23/B23,"") | G23: =A23*'Unit_Economics'!$B$37/60 | H23: =IF(G23>Supuestos!$B$51,"Imposible tu solo: el soporte pasa de tus horas",IF(G23>Supuestos!$B$51*0.7,"Al limite: el soporte se come el mes",IF(G23>Supuestos!$B$51*0.4,"Creces despacio","Tienes margen para vender")))
A24: 50 | B24: =A24*'Unit_Economics'!$B$32*(1-Supuestos!$B$45) | C24: =A24*'Unit_Economics'!$B$35 | D24: =Supuestos!$B$72 | E24: =C24-D24 | F24: =IF(B24>0,E24/B24,"") | G24: =A24*'Unit_Economics'!$B$37/60 | H24: =IF(G24>Supuestos!$B$51,"Imposible tu solo: el soporte pasa de tus horas",IF(G24>Supuestos!$B$51*0.7,"Al limite: el soporte se come el mes",IF(G24>Supuestos!$B$51*0.4,"Creces despacio","Tienes margen para vender")))
A25: 75 | B25: =A25*'Unit_Economics'!$B$32*(1-Supuestos!$B$45) | C25: =A25*'Unit_Economics'!$B$35 | D25: =Supuestos!$B$72 | E25: =C25-D25 | F25: =IF(B25>0,E25/B25,"") | G25: =A25*'Unit_Economics'!$B$37/60 | H25: =IF(G25>Supuestos!$B$51,"Imposible tu solo: el soporte pasa de tus horas",IF(G25>Supuestos!$B$51*0.7,"Al limite: el soporte se come el mes",IF(G25>Supuestos!$B$51*0.4,"Creces despacio","Tienes margen para vender")))
A26: 100 | B26: =A26*'Unit_Economics'!$B$32*(1-Supuestos!$B$45) | C26: =A26*'Unit_Economics'!$B$35 | D26: =Supuestos!$B$72 | E26: =C26-D26 | F26: =IF(B26>0,E26/B26,"") | G26: =A26*'Unit_Economics'!$B$37/60 | H26: =IF(G26>Supuestos!$B$51,"Imposible tu solo: el soporte pasa de tus horas",IF(G26>Supuestos!$B$51*0.7,"Al limite: el soporte se come el mes",IF(G26>Supuestos!$B$51*0.4,"Creces despacio","Tienes margen para vender")))
A27: 150 | B27: =A27*'Unit_Economics'!$B$32*(1-Supuestos!$B$45) | C27: =A27*'Unit_Economics'!$B$35 | D27: =Supuestos!$B$72 | E27: =C27-D27 | F27: =IF(B27>0,E27/B27,"") | G27: =A27*'Unit_Economics'!$B$37/60 | H27: =IF(G27>Supuestos!$B$51,"Imposible tu solo: el soporte pasa de tus horas",IF(G27>Supuestos!$B$51*0.7,"Al limite: el soporte se come el mes",IF(G27>Supuestos!$B$51*0.4,"Creces despacio","Tienes margen para vender")))
A28: 200 | B28: =A28*'Unit_Economics'!$B$32*(1-Supuestos!$B$45) | C28: =A28*'Unit_Economics'!$B$35 | D28: =Supuestos!$B$72 | E28: =C28-D28 | F28: =IF(B28>0,E28/B28,"") | G28: =A28*'Unit_Economics'!$B$37/60 | H28: =IF(G28>Supuestos!$B$51,"Imposible tu solo: el soporte pasa de tus horas",IF(G28>Supuestos!$B$51*0.7,"Al limite: el soporte se come el mes",IF(G28>Supuestos!$B$51*0.4,"Creces despacio","Tienes margen para vender")))
A29: 300 | B29: =A29*'Unit_Economics'!$B$32*(1-Supuestos!$B$45) | C29: =A29*'Unit_Economics'!$B$35 | D29: =Supuestos!$B$72 | E29: =C29-D29 | F29: =IF(B29>0,E29/B29,"") | G29: =A29*'Unit_Economics'!$B$37/60 | H29: =IF(G29>Supuestos!$B$51,"Imposible tu solo: el soporte pasa de tus horas",IF(G29>Supuestos!$B$51*0.7,"Al limite: el soporte se come el mes",IF(G29>Supuestos!$B$51*0.4,"Creces despacio","Tienes margen para vender")))
A30: 500 | B30: =A30*'Unit_Economics'!$B$32*(1-Supuestos!$B$45) | C30: =A30*'Unit_Economics'!$B$35 | D30: =Supuestos!$B$72 | E30: =C30-D30 | F30: =IF(B30>0,E30/B30,"") | G30: =A30*'Unit_Economics'!$B$37/60 | H30: =IF(G30>Supuestos!$B$51,"Imposible tu solo: el soporte pasa de tus horas",IF(G30>Supuestos!$B$51*0.7,"Al limite: el soporte se come el mes",IF(G30>Supuestos!$B$51*0.4,"Creces despacio","Tienes margen para vender")))
A31: 1000 | B31: =A31*'Unit_Economics'!$B$32*(1-Supuestos!$B$45) | C31: =A31*'Unit_Economics'!$B$35 | D31: =Supuestos!$B$72 | E31: =C31-D31 | F31: =IF(B31>0,E31/B31,"") | G31: =A31*'Unit_Economics'!$B$37/60 | H31: =IF(G31>Supuestos!$B$51,"Imposible tu solo: el soporte pasa de tus horas",IF(G31>Supuestos!$B$51*0.7,"Al limite: el soporte se come el mes",IF(G31>Supuestos!$B$51*0.4,"Creces despacio","Tienes margen para vender")))
A33: Cuantos clientes de cada plan hacen falta en el equilibrio
A34: Plan | B34: Mezcla | C34: Clientes | D34: Precio | E34: Ingreso mensual | F34: Contribucion en caja
A35: Autonomo | B35: ='Supuestos'!B8 | C35: =ROUND($D$8*B35,0) | D35: ='Supuestos'!B7 | E35: =C35*D35 | F35: =C35*'Unit_Economics'!E21
A36: Negocio | B36: ='Supuestos'!C8 | C36: =ROUND($D$8*B36,0) | D36: ='Supuestos'!C7 | E36: =C36*D36 | F36: =C36*'Unit_Economics'!F21
A37: Premium | B37: ='Supuestos'!D8 | C37: =ROUND($D$8*B37,0) | D37: ='Supuestos'!D7 | E37: =C37*D37 | F37: =C37*'Unit_Economics'!G21
A38: TOTAL | B38: =SUM(B35:B37) | C38: =SUM(C35:C37) | E38: =SUM(E35:E37) | F38: =SUM(F35:F37)
A40: Y si toda la cartera fuera de un solo plan
A41: Plan | B41: Contribucion en caja | C41: Clientes para el equilibrio | D41: Ingreso mensual
A42: Autonomo | B42: ='Unit_Economics'!E21 | C42: =IFERROR(ROUNDUP(Supuestos!$B$72/B42,0),"") | D42: =IFERROR(C42*'Supuestos'!B7,"")
A43: Negocio | B43: ='Unit_Economics'!F21 | C43: =IFERROR(ROUNDUP(Supuestos!$B$72/B43,0),"") | D43: =IFERROR(C43*'Supuestos'!C7,"")
A44: Premium | B44: ='Unit_Economics'!G21 | C44: =IFERROR(ROUNDUP(Supuestos!$B$72/B44,0),"") | D44: =IFERROR(C44*'Supuestos'!D7,"")
A46: Leer las tres tablas juntas. La primera dice cuanto hay que cubrir y con que contribucion; la segunda, cuantos clientes de cada plan lo componen; la tercera, cuantos harian falta vendiendo un solo plan. La distancia entre ellas es el valor real de vender el plan caro, y es toda la conversacion comercial en una cifra. Lo que ninguna dice es cuantos meses cuesta llegar: eso esta en Rampa_36m.

Sheet Vida_y_LTV
A1: Cuanto dura un cliente y cuanto deja
A2: Sin bajas no hay vida media, y sin vida media no hay LTV: el libro de agosto describia un cliente que se queda para siempre. Aqui la vida se calcula con dos tramos —los tres primeros meses se va mas gente— en vez de con un churn plano, que es como se comporta de verdad una cartera nueva.
A4: Con los supuestos del panel
A5: Metrica | B5: Valor | C5: Unidad | G5: Como se calcula
A6: Bajas los tres primeros meses | B6: =Supuestos!$B$42 | C6: %/mes | G6: Del panel de supuestos.
A7: Bajas despues | B7: =Supuestos!$B$43 | C7: %/mes | G7: Del panel de supuestos.
A8: Vida media resultante | B8: ='Unit_Economics'!$E$28 | C8: meses | G8: Suma de la supervivencia mes a mes: 1 + 0,92 + 0,92² + 0,92³/0,04. Con un churn plano del 4 % saldrian 25 meses; con dos tramos, menos.
A9: LTV en caja | B9: ='Unit_Economics'!$B$35*'Unit_Economics'!$E$28 | C9: € | G9: Contribucion en caja por la vida media. No es facturacion: es lo que deja.
A10: LTV cargada | B10: ='Unit_Economics'!$B$36*'Unit_Economics'!$E$28 | C10: € | G10: La misma cuenta con el soporte pagado a otra persona.
A11: LTV / CAC (en caja) | B11: =IF(Supuestos!$B$77<=0,"-",B9/Supuestos!$B$77) | C11: veces | G11: Referencia habitual en SaaS: 3x o mas.
A12: Meses para recuperar el CAC | B12: =IF('Unit_Economics'!$B$35<=0,"-",Supuestos!$B$77/'Unit_Economics'!$B$35) | C12: meses | G12: Payback. Por encima de 12 meses la caja sufre aunque el LTV sea bueno.
A14: Y si las bajas fueran otras
A15: Bajas despues del 3er mes | B15: Vida media | C15: LTV en caja | D15: LTV cargada | E15: LTV / CAC | F15: Recupera el CAC en | G15: Lectura
A16: 0.02 | B16: =1+(1-Supuestos!$B$42)+(1-Supuestos!$B$42)^2+(1-Supuestos!$B$42)^3/A16 | C16: ='Unit_Economics'!$B$35*B16 | D16: ='Unit_Economics'!$B$36*B16 | E16: =IF(Supuestos!$B$77<=0,"-",C16/Supuestos!$B$77) | F16: =IF('Unit_Economics'!$B$35<=0,"-",Supuestos!$B$77/'Unit_Economics'!$B$35) | G16: =IF(E16="","",IF(E16>=3,"Sostenible",IF(E16>=1,"Justo: el cliente apenas paga su captacion","Cada alta destruye valor")))
A17: 0.03 | B17: =1+(1-Supuestos!$B$42)+(1-Supuestos!$B$42)^2+(1-Supuestos!$B$42)^3/A17 | C17: ='Unit_Economics'!$B$35*B17 | D17: ='Unit_Economics'!$B$36*B17 | E17: =IF(Supuestos!$B$77<=0,"-",C17/Supuestos!$B$77) | F17: =IF('Unit_Economics'!$B$35<=0,"-",Supuestos!$B$77/'Unit_Economics'!$B$35) | G17: =IF(E17="","",IF(E17>=3,"Sostenible",IF(E17>=1,"Justo: el cliente apenas paga su captacion","Cada alta destruye valor")))
A18: 0.04 | B18: =1+(1-Supuestos!$B$42)+(1-Supuestos!$B$42)^2+(1-Supuestos!$B$42)^3/A18 | C18: ='Unit_Economics'!$B$35*B18 | D18: ='Unit_Economics'!$B$36*B18 | E18: =IF(Supuestos!$B$77<=0,"-",C18/Supuestos!$B$77) | F18: =IF('Unit_Economics'!$B$35<=0,"-",Supuestos!$B$77/'Unit_Economics'!$B$35) | G18: =IF(E18="","",IF(E18>=3,"Sostenible",IF(E18>=1,"Justo: el cliente apenas paga su captacion","Cada alta destruye valor")))
A19: 0.05 | B19: =1+(1-Supuestos!$B$42)+(1-Supuestos!$B$42)^2+(1-Supuestos!$B$42)^3/A19 | C19: ='Unit_Economics'!$B$35*B19 | D19: ='Unit_Economics'!$B$36*B19 | E19: =IF(Supuestos!$B$77<=0,"-",C19/Supuestos!$B$77) | F19: =IF('Unit_Economics'!$B$35<=0,"-",Supuestos!$B$77/'Unit_Economics'!$B$35) | G19: =IF(E19="","",IF(E19>=3,"Sostenible",IF(E19>=1,"Justo: el cliente apenas paga su captacion","Cada alta destruye valor")))
A20: 0.08 | B20: =1+(1-Supuestos!$B$42)+(1-Supuestos!$B$42)^2+(1-Supuestos!$B$42)^3/A20 | C20: ='Unit_Economics'!$B$35*B20 | D20: ='Unit_Economics'!$B$36*B20 | E20: =IF(Supuestos!$B$77<=0,"-",C20/Supuestos!$B$77) | F20: =IF('Unit_Economics'!$B$35<=0,"-",Supuestos!$B$77/'Unit_Economics'!$B$35) | G20: =IF(E20="","",IF(E20>=3,"Sostenible",IF(E20>=1,"Justo: el cliente apenas paga su captacion","Cada alta destruye valor")))
A21: 0.1 | B21: =1+(1-Supuestos!$B$42)+(1-Supuestos!$B$42)^2+(1-Supuestos!$B$42)^3/A21 | C21: ='Unit_Economics'!$B$35*B21 | D21: ='Unit_Economics'!$B$36*B21 | E21: =IF(Supuestos!$B$77<=0,"-",C21/Supuestos!$B$77) | F21: =IF('Unit_Economics'!$B$35<=0,"-",Supuestos!$B$77/'Unit_Economics'!$B$35) | G21: =IF(E21="","",IF(E21>=3,"Sostenible",IF(E21>=1,"Justo: el cliente apenas paga su captacion","Cada alta destruye valor")))
A23: Ninguna fila de esta hoja es un dato: no hay todavia clientes de pago que permitan medir las bajas. El CAC de 150 € aguanta bien salvo con bajas altas, pero tanto el CAC como las bajas son supuestos. Y ojo con el LTV: describe el valor de un cliente a lo largo de dos anos, no dinero disponible este mes. La pregunta que limita de verdad es la caja, y esa la contesta Rampa_36m.

Sheet Horas_del_founder
A1: Tu tiempo puesto en numeros
A2: En un negocio de una persona el limite no es el mercado: son las horas. Cada cuenta nueva consume tiempo de venta y puesta en marcha una vez, y tiempo de soporte todos los meses. Cuando el soporte se come las horas, no quedan para vender y la cartera deja de crecer sola — sin que el mercado tenga nada que ver.
A4: Concepto | B4: Valor | F4: Nota
A5: Horas al mes para vender y atender | B5: =Supuestos!$B$51 | F5: Del panel de supuestos.
A6: Soporte de una cuenta asentada | B6: ='Unit_Economics'!$B$37/60 | F6: Los minutos medios ponderados por la mezcla, pasados a horas.
A7: Soporte de una cuenta nueva | B7: ='Unit_Economics'!$B$37*Supuestos!$B$47/60 | F7: Los tres primeros meses preguntan mas.
A8: Horas por alta | B8: =Supuestos!$B$52 | F8: Venta y puesta en marcha.
A9: Cuentas que llenan tus horas solo con soporte | B9: =ROUNDDOWN(B5/B6,0) | F9: El techo absoluto: a partir de aqui no te queda ni una hora para vender.
A10: Techo practico (soporte al 70 % de tus horas) | B10: =ROUNDDOWN(B5*0.7/B6,0) | F10: El punto en el que conviene decidir: o baja el soporte por cuenta, o entra alguien.
A12: Carga segun el tamano de la cartera
A13: Cuentas atendidas | B13: Horas de soporte | C13: % de tus horas | D13: Horas libres para vender | E13: Altas que puedes cerrar | F13: Situacion
A14: 10 | B14: =A14*$B$6 | C14: =IF($B$5=0,0,B14/$B$5) | D14: =MAX(0,$B$5-B14) | E14: =IF($B$8<=0,0,ROUNDDOWN(D14/$B$8,0)) | F14: =IF(C14>=1,"Ya no puedes vender: solo atiendes",IF(C14>=0.7,"Al limite: el soporte se come el mes",IF(C14>=0.4,"Creces despacio","Tienes margen para vender")))
A15: 25 | B15: =A15*$B$6 | C15: =IF($B$5=0,0,B15/$B$5) | D15: =MAX(0,$B$5-B15) | E15: =IF($B$8<=0,0,ROUNDDOWN(D15/$B$8,0)) | F15: =IF(C15>=1,"Ya no puedes vender: solo atiendes",IF(C15>=0.7,"Al limite: el soporte se come el mes",IF(C15>=0.4,"Creces despacio","Tienes margen para vender")))
A16: 44 | B16: =A16*$B$6 | C16: =IF($B$5=0,0,B16/$B$5) | D16: =MAX(0,$B$5-B16) | E16: =IF($B$8<=0,0,ROUNDDOWN(D16/$B$8,0)) | F16: =IF(C16>=1,"Ya no puedes vender: solo atiendes",IF(C16>=0.7,"Al limite: el soporte se come el mes",IF(C16>=0.4,"Creces despacio","Tienes margen para vender")))
A17: 75 | B17: =A17*$B$6 | C17: =IF($B$5=0,0,B17/$B$5) | D17: =MAX(0,$B$5-B17) | E17: =IF($B$8<=0,0,ROUNDDOWN(D17/$B$8,0)) | F17: =IF(C17>=1,"Ya no puedes vender: solo atiendes",IF(C17>=0.7,"Al limite: el soporte se come el mes",IF(C17>=0.4,"Creces despacio","Tienes margen para vender")))
A18: 100 | B18: =A18*$B$6 | C18: =IF($B$5=0,0,B18/$B$5) | D18: =MAX(0,$B$5-B18) | E18: =IF($B$8<=0,0,ROUNDDOWN(D18/$B$8,0)) | F18: =IF(C18>=1,"Ya no puedes vender: solo atiendes",IF(C18>=0.7,"Al limite: el soporte se come el mes",IF(C18>=0.4,"Creces despacio","Tienes margen para vender")))
A19: 150 | B19: =A19*$B$6 | C19: =IF($B$5=0,0,B19/$B$5) | D19: =MAX(0,$B$5-B19) | E19: =IF($B$8<=0,0,ROUNDDOWN(D19/$B$8,0)) | F19: =IF(C19>=1,"Ya no puedes vender: solo atiendes",IF(C19>=0.7,"Al limite: el soporte se come el mes",IF(C19>=0.4,"Creces despacio","Tienes margen para vender")))
A20: 200 | B20: =A20*$B$6 | C20: =IF($B$5=0,0,B20/$B$5) | D20: =MAX(0,$B$5-B20) | E20: =IF($B$8<=0,0,ROUNDDOWN(D20/$B$8,0)) | F20: =IF(C20>=1,"Ya no puedes vender: solo atiendes",IF(C20>=0.7,"Al limite: el soporte se come el mes",IF(C20>=0.4,"Creces despacio","Tienes margen para vender")))
A21: 300 | B21: =A21*$B$6 | C21: =IF($B$5=0,0,B21/$B$5) | D21: =MAX(0,$B$5-B21) | E21: =IF($B$8<=0,0,ROUNDDOWN(D21/$B$8,0)) | F21: =IF(C21>=1,"Ya no puedes vender: solo atiendes",IF(C21>=0.7,"Al limite: el soporte se come el mes",IF(C21>=0.4,"Creces despacio","Tienes margen para vender")))
A23: Contratar no resuelve el problema por si solo: una persona de soporte cuesta desde el primer dia y la cartera crece de una en una. Por eso el margen tiene que venir de que el soporte por cuenta baje —cerebro local, autoexplicacion, menos dudas— y no de meter mas gente. Bajar el soporte de 18 a 12 minutos regala mas cuentas que cualquier campana.
A27: Si hay que contratar
A28: Concepto | B28: Valor | F28: Nota
A29: Coste cargado de media jornada | B29: =Supuestos!$B$57 | F29: Media jornada con seguridad social.
A30: Cuentas extra que hacen falta para pagarla | B30: =IF('Unit_Economics'!$B$36<=0,"-",ROUNDUP(Supuestos!$B$57/'Unit_Economics'!$B$36,0)) | F30: Sobre las que ya tengas. La persona no trae clientes: libera horas.
A31: Horas que aporta media jornada | B31: =Supuestos!$B$56/2 | F31: Sobre las horas utiles de una jornada completa del panel.
A32: Cuentas que esas horas permiten atender | B32: =ROUNDDOWN(B31/$B$6,0) | F32: Capacidad que compras con ese sueldo.
A34: Esa cifra es la trampa del crecimiento: el coste entra de golpe y las altas llegan una a una. Antes de contratar conviene que la cartera pueda pagarlo ya, no que vaya a poder. Y fijarse en el cambio de contribucion: en cuanto el soporte se paga, la que manda es la CARGADA y el equilibrio sube de golpe.

Sheet Rampa_36m
A1: 36 meses: cuatro cohortes y tus horas
A2: Cada mes entran las altas que permiten tus horas libres, no las que te gustaria. Las cuentas se siguen por edad porque las nuevas se van mas y preguntan mas. La proyeccion de agosto suponia altas constantes y cero bajas durante dos anos; esta se frena sola cuando el soporte te ocupa el mes.
A5: Resumen
A6: Mes en que dejas de perder dinero | D6: =IFERROR(INDEX($A$12:$A$47,MATCH(TRUE,INDEX($O$12:$O$47>0,0),0)),"no llega en 36 meses") | E6: Horas disponibles | F6: =Supuestos!$B$51
A7: Caja minima por el camino | D7: =MIN($P$12:$P$47) | E7: Min. soporte asentada | F7: ='Unit_Economics'!$B$37
A8: Cuentas al mes 36 | D8: =$H$47 | E8: Min. soporte nueva | F8: ='Unit_Economics'!$B$37*Supuestos!$B$47
A9: Mes en que el soporte pasa del 70 % de tus horas | D9: =IFERROR(INDEX($A$12:$A$47,MATCH(TRUE,INDEX($I$12:$I$47>=$F$6*0.7,0),0)),"no llega en 36 meses") | E9: Horas por alta | F9: =Supuestos!$B$52
A11: Mes | B11: Altas objetivo | C11: Altas reales | D11: Mes 1 | E11: Mes 2 | F11: Mes 3 | G11: Asentadas | H11: Cuentas | I11: Horas usadas | J11: Facturado | K11: Cobrado | L11: Implantacion | M11: Comision canal | N11: Contribucion | O11: Resultado | P11: Caja
A12: 1 | B12: =ROUND(Supuestos!$B$53*(1+Supuestos!$B$54)^(A12-1),0) | C12: =MAX(0,MIN(B12,ROUNDDOWN(MAX(0,$F$6-0)/$F$9,0))) | D12: =C12 | E12: =0 | F12: =0 | G12: =0 | H12: =D12+E12+F12+G12 | I12: =C12*$F$9+((D12+E12+F12)*$F$8+G12*$F$7)/60 | J12: =H12*'Unit_Economics'!$B$32-C12*'Unit_Economics'!$B$32*Supuestos!$B$44/30 | K12: =J12*(1-Supuestos!$B$45) | L12: =C12*Supuestos!$B$78*Supuestos!$B$79 | M12: =-Supuestos!$B$83*(C12*Supuestos!$B$80*'Unit_Economics'!$B$32+Supuestos!$B$81*'Unit_Economics'!$B$32*MIN(H12,SUM(C12:C12))) | N12: =K12+L12+M12-H12*'Unit_Economics'!$B$33 | O12: =N12-Supuestos!$B$72 | P12: =Supuestos!$B$73+O12
A13: 2 | B13: =ROUND(Supuestos!$B$53*(1+Supuestos!$B$54)^(A13-1),0) | C13: =MAX(0,MIN(B13,ROUNDDOWN(MAX(0,$F$6-((D12+E12+F12)*$F$8+G12*$F$7)/60)/$F$9,0))) | D13: =C13 | E13: =D12*(1-Supuestos!$B$42) | F13: =E12*(1-Supuestos!$B$42) | G13: =(G12+F12)*(1-Supuestos!$B$43) | H13: =D13+E13+F13+G13 | I13: =C13*$F$9+((D13+E13+F13)*$F$8+G13*$F$7)/60 | J13: =H13*'Unit_Economics'!$B$32-C13*'Unit_Economics'!$B$32*Supuestos!$B$44/30 | K13: =J13*(1-Supuestos!$B$45) | L13: =C13*Supuestos!$B$78*Supuestos!$B$79 | M13: =-Supuestos!$B$83*(C13*Supuestos!$B$80*'Unit_Economics'!$B$32+Supuestos!$B$81*'Unit_Economics'!$B$32*MIN(H13,SUM(C12:C13))) | N13: =K13+L13+M13-H13*'Unit_Economics'!$B$33 | O13: =N13-Supuestos!$B$72 | P13: =P12+O13
A14: 3 | B14: =ROUND(Supuestos!$B$53*(1+Supuestos!$B$54)^(A14-1),0) | C14: =MAX(0,MIN(B14,ROUNDDOWN(MAX(0,$F$6-((D13+E13+F13)*$F$8+G13*$F$7)/60)/$F$9,0))) | D14: =C14 | E14: =D13*(1-Supuestos!$B$42) | F14: =E13*(1-Supuestos!$B$42) | G14: =(G13+F13)*(1-Supuestos!$B$43) | H14: =D14+E14+F14+G14 | I14: =C14*$F$9+((D14+E14+F14)*$F$8+G14*$F$7)/60 | J14: =H14*'Unit_Economics'!$B$32-C14*'Unit_Economics'!$B$32*Supuestos!$B$44/30 | K14: =J14*(1-Supuestos!$B$45) | L14: =C14*Supuestos!$B$78*Supuestos!$B$79 | M14: =-Supuestos!$B$83*(C14*Supuestos!$B$80*'Unit_Economics'!$B$32+Supuestos!$B$81*'Unit_Economics'!$B$32*MIN(H14,SUM(C12:C14))) | N14: =K14+L14+M14-H14*'Unit_Economics'!$B$33 | O14: =N14-Supuestos!$B$72 | P14: =P13+O14
A15: 4 | B15: =ROUND(Supuestos!$B$53*(1+Supuestos!$B$54)^(A15-1),0) | C15: =MAX(0,MIN(B15,ROUNDDOWN(MAX(0,$F$6-((D14+E14+F14)*$F$8+G14*$F$7)/60)/$F$9,0))) | D15: =C15 | E15: =D14*(1-Supuestos!$B$42) | F15: =E14*(1-Supuestos!$B$42) | G15: =(G14+F14)*(1-Supuestos!$B$43) | H15: =D15+E15+F15+G15 | I15: =C15*$F$9+((D15+E15+F15)*$F$8+G15*$F$7)/60 | J15: =H15*'Unit_Economics'!$B$32-C15*'Unit_Economics'!$B$32*Supuestos!$B$44/30 | K15: =J15*(1-Supuestos!$B$45) | L15: =C15*Supuestos!$B$78*Supuestos!$B$79 | M15: =-Supuestos!$B$83*(C15*Supuestos!$B$80*'Unit_Economics'!$B$32+Supuestos!$B$81*'Unit_Economics'!$B$32*MIN(H15,SUM(C12:C15))) | N15: =K15+L15+M15-H15*'Unit_Economics'!$B$33 | O15: =N15-Supuestos!$B$72 | P15: =P14+O15
A16: 5 | B16: =ROUND(Supuestos!$B$53*(1+Supuestos!$B$54)^(A16-1),0) | C16: =MAX(0,MIN(B16,ROUNDDOWN(MAX(0,$F$6-((D15+E15+F15)*$F$8+G15*$F$7)/60)/$F$9,0))) | D16: =C16 | E16: =D15*(1-Supuestos!$B$42) | F16: =E15*(1-Supuestos!$B$42) | G16: =(G15+F15)*(1-Supuestos!$B$43) | H16: =D16+E16+F16+G16 | I16: =C16*$F$9+((D16+E16+F16)*$F$8+G16*$F$7)/60 | J16: =H16*'Unit_Economics'!$B$32-C16*'Unit_Economics'!$B$32*Supuestos!$B$44/30 | K16: =J16*(1-Supuestos!$B$45) | L16: =C16*Supuestos!$B$78*Supuestos!$B$79 | M16: =-Supuestos!$B$83*(C16*Supuestos!$B$80*'Unit_Economics'!$B$32+Supuestos!$B$81*'Unit_Economics'!$B$32*MIN(H16,SUM(C12:C16))) | N16: =K16+L16+M16-H16*'Unit_Economics'!$B$33 | O16: =N16-Supuestos!$B$72 | P16: =P15+O16
A17: 6 | B17: =ROUND(Supuestos!$B$53*(1+Supuestos!$B$54)^(A17-1),0) | C17: =MAX(0,MIN(B17,ROUNDDOWN(MAX(0,$F$6-((D16+E16+F16)*$F$8+G16*$F$7)/60)/$F$9,0))) | D17: =C17 | E17: =D16*(1-Supuestos!$B$42) | F17: =E16*(1-Supuestos!$B$42) | G17: =(G16+F16)*(1-Supuestos!$B$43) | H17: =D17+E17+F17+G17 | I17: =C17*$F$9+((D17+E17+F17)*$F$8+G17*$F$7)/60 | J17: =H17*'Unit_Economics'!$B$32-C17*'Unit_Economics'!$B$32*Supuestos!$B$44/30 | K17: =J17*(1-Supuestos!$B$45) | L17: =C17*Supuestos!$B$78*Supuestos!$B$79 | M17: =-Supuestos!$B$83*(C17*Supuestos!$B$80*'Unit_Economics'!$B$32+Supuestos!$B$81*'Unit_Economics'!$B$32*MIN(H17,SUM(C12:C17))) | N17: =K17+L17+M17-H17*'Unit_Economics'!$B$33 | O17: =N17-Supuestos!$B$72 | P17: =P16+O17
A18: 7 | B18: =ROUND(Supuestos!$B$53*(1+Supuestos!$B$54)^(A18-1),0) | C18: =MAX(0,MIN(B18,ROUNDDOWN(MAX(0,$F$6-((D17+E17+F17)*$F$8+G17*$F$7)/60)/$F$9,0))) | D18: =C18 | E18: =D17*(1-Supuestos!$B$42) | F18: =E17*(1-Supuestos!$B$42) | G18: =(G17+F17)*(1-Supuestos!$B$43) | H18: =D18+E18+F18+G18 | I18: =C18*$F$9+((D18+E18+F18)*$F$8+G18*$F$7)/60 | J18: =H18*'Unit_Economics'!$B$32-C18*'Unit_Economics'!$B$32*Supuestos!$B$44/30 | K18: =J18*(1-Supuestos!$B$45) | L18: =C18*Supuestos!$B$78*Supuestos!$B$79 | M18: =-Supuestos!$B$83*(C18*Supuestos!$B$80*'Unit_Economics'!$B$32+Supuestos!$B$81*'Unit_Economics'!$B$32*MIN(H18,SUM(C12:C18))) | N18: =K18+L18+M18-H18*'Unit_Economics'!$B$33 | O18: =N18-Supuestos!$B$72 | P18: =P17+O18
A19: 8 | B19: =ROUND(Supuestos!$B$53*(1+Supuestos!$B$54)^(A19-1),0) | C19: =MAX(0,MIN(B19,ROUNDDOWN(MAX(0,$F$6-((D18+E18+F18)*$F$8+G18*$F$7)/60)/$F$9,0))) | D19: =C19 | E19: =D18*(1-Supuestos!$B$42) | F19: =E18*(1-Supuestos!$B$42) | G19: =(G18+F18)*(1-Supuestos!$B$43) | H19: =D19+E19+F19+G19 | I19: =C19*$F$9+((D19+E19+F19)*$F$8+G19*$F$7)/60 | J19: =H19*'Unit_Economics'!$B$32-C19*'Unit_Economics'!$B$32*Supuestos!$B$44/30 | K19: =J19*(1-Supuestos!$B$45) | L19: =C19*Supuestos!$B$78*Supuestos!$B$79 | M19: =-Supuestos!$B$83*(C19*Supuestos!$B$80*'Unit_Economics'!$B$32+Supuestos!$B$81*'Unit_Economics'!$B$32*MIN(H19,SUM(C12:C19))) | N19: =K19+L19+M19-H19*'Unit_Economics'!$B$33 | O19: =N19-Supuestos!$B$72 | P19: =P18+O19
A20: 9 | B20: =ROUND(Supuestos!$B$53*(1+Supuestos!$B$54)^(A20-1),0) | C20: =MAX(0,MIN(B20,ROUNDDOWN(MAX(0,$F$6-((D19+E19+F19)*$F$8+G19*$F$7)/60)/$F$9,0))) | D20: =C20 | E20: =D19*(1-Supuestos!$B$42) | F20: =E19*(1-Supuestos!$B$42) | G20: =(G19+F19)*(1-Supuestos!$B$43) | H20: =D20+E20+F20+G20 | I20: =C20*$F$9+((D20+E20+F20)*$F$8+G20*$F$7)/60 | J20: =H20*'Unit_Economics'!$B$32-C20*'Unit_Economics'!$B$32*Supuestos!$B$44/30 | K20: =J20*(1-Supuestos!$B$45) | L20: =C20*Supuestos!$B$78*Supuestos!$B$79 | M20: =-Supuestos!$B$83*(C20*Supuestos!$B$80*'Unit_Economics'!$B$32+Supuestos!$B$81*'Unit_Economics'!$B$32*MIN(H20,SUM(C12:C20))) | N20: =K20+L20+M20-H20*'Unit_Economics'!$B$33 | O20: =N20-Supuestos!$B$72 | P20: =P19+O20
A21: 10 | B21: =ROUND(Supuestos!$B$53*(1+Supuestos!$B$54)^(A21-1),0) | C21: =MAX(0,MIN(B21,ROUNDDOWN(MAX(0,$F$6-((D20+E20+F20)*$F$8+G20*$F$7)/60)/$F$9,0))) | D21: =C21 | E21: =D20*(1-Supuestos!$B$42) | F21: =E20*(1-Supuestos!$B$42) | G21: =(G20+F20)*(1-Supuestos!$B$43) | H21: =D21+E21+F21+G21 | I21: =C21*$F$9+((D21+E21+F21)*$F$8+G21*$F$7)/60 | J21: =H21*'Unit_Economics'!$B$32-C21*'Unit_Economics'!$B$32*Supuestos!$B$44/30 | K21: =J21*(1-Supuestos!$B$45) | L21: =C21*Supuestos!$B$78*Supuestos!$B$79 | M21: =-Supuestos!$B$83*(C21*Supuestos!$B$80*'Unit_Economics'!$B$32+Supuestos!$B$81*'Unit_Economics'!$B$32*MIN(H21,SUM(C12:C21))) | N21: =K21+L21+M21-H21*'Unit_Economics'!$B$33 | O21: =N21-Supuestos!$B$72 | P21: =P20+O21
A22: 11 | B22: =ROUND(Supuestos!$B$53*(1+Supuestos!$B$54)^(A22-1),0) | C22: =MAX(0,MIN(B22,ROUNDDOWN(MAX(0,$F$6-((D21+E21+F21)*$F$8+G21*$F$7)/60)/$F$9,0))) | D22: =C22 | E22: =D21*(1-Supuestos!$B$42) | F22: =E21*(1-Supuestos!$B$42) | G22: =(G21+F21)*(1-Supuestos!$B$43) | H22: =D22+E22+F22+G22 | I22: =C22*$F$9+((D22+E22+F22)*$F$8+G22*$F$7)/60 | J22: =H22*'Unit_Economics'!$B$32-C22*'Unit_Economics'!$B$32*Supuestos!$B$44/30 | K22: =J22*(1-Supuestos!$B$45) | L22: =C22*Supuestos!$B$78*Supuestos!$B$79 | M22: =-Supuestos!$B$83*(C22*Supuestos!$B$80*'Unit_Economics'!$B$32+Supuestos!$B$81*'Unit_Economics'!$B$32*MIN(H22,SUM(C12:C22))) | N22: =K22+L22+M22-H22*'Unit_Economics'!$B$33 | O22: =N22-Supuestos!$B$72 | P22: =P21+O22
A23: 12 | B23: =ROUND(Supuestos!$B$53*(1+Supuestos!$B$54)^(A23-1),0) | C23: =MAX(0,MIN(B23,ROUNDDOWN(MAX(0,$F$6-((D22+E22+F22)*$F$8+G22*$F$7)/60)/$F$9,0))) | D23: =C23 | E23: =D22*(1-Supuestos!$B$42) | F23: =E22*(1-Supuestos!$B$42) | G23: =(G22+F22)*(1-Supuestos!$B$43) | H23: =D23+E23+F23+G23 | I23: =C23*$F$9+((D23+E23+F23)*$F$8+G23*$F$7)/60 | J23: =H23*'Unit_Economics'!$B$32-C23*'Unit_Economics'!$B$32*Supuestos!$B$44/30 | K23: =J23*(1-Supuestos!$B$45) | L23: =C23*Supuestos!$B$78*Supuestos!$B$79 | M23: =-Supuestos!$B$83*(C23*Supuestos!$B$80*'Unit_Economics'!$B$32+Supuestos!$B$81*'Unit_Economics'!$B$32*MIN(H23,SUM(C12:C23))) | N23: =K23+L23+M23-H23*'Unit_Economics'!$B$33 | O23: =N23-Supuestos!$B$72 | P23: =P22+O23
A24: 13 | B24: =ROUND(Supuestos!$B$53*(1+Supuestos!$B$54)^(A24-1),0) | C24: =MAX(0,MIN(B24,ROUNDDOWN(MAX(0,$F$6-((D23+E23+F23)*$F$8+G23*$F$7)/60)/$F$9,0))) | D24: =C24 | E24: =D23*(1-Supuestos!$B$42) | F24: =E23*(1-Supuestos!$B$42) | G24: =(G23+F23)*(1-Supuestos!$B$43) | H24: =D24+E24+F24+G24 | I24: =C24*$F$9+((D24+E24+F24)*$F$8+G24*$F$7)/60 | J24: =H24*'Unit_Economics'!$B$32-C24*'Unit_Economics'!$B$32*Supuestos!$B$44/30 | K24: =J24*(1-Supuestos!$B$45) | L24: =C24*Supuestos!$B$78*Supuestos!$B$79 | M24: =-Supuestos!$B$83*(C24*Supuestos!$B$80*'Unit_Economics'!$B$32+Supuestos!$B$81*'Unit_Economics'!$B$32*MIN(H24,SUM(C13:C24))) | N24: =K24+L24+M24-H24*'Unit_Economics'!$B$33 | O24: =N24-Supuestos!$B$72 | P24: =P23+O24
A25: 14 | B25: =ROUND(Supuestos!$B$53*(1+Supuestos!$B$54)^(A25-1),0) | C25: =MAX(0,MIN(B25,ROUNDDOWN(MAX(0,$F$6-((D24+E24+F24)*$F$8+G24*$F$7)/60)/$F$9,0))) | D25: =C25 | E25: =D24*(1-Supuestos!$B$42) | F25: =E24*(1-Supuestos!$B$42) | G25: =(G24+F24)*(1-Supuestos!$B$43) | H25: =D25+E25+F25+G25 | I25: =C25*$F$9+((D25+E25+F25)*$F$8+G25*$F$7)/60 | J25: =H25*'Unit_Economics'!$B$32-C25*'Unit_Economics'!$B$32*Supuestos!$B$44/30 | K25: =J25*(1-Supuestos!$B$45) | L25: =C25*Supuestos!$B$78*Supuestos!$B$79 | M25: =-Supuestos!$B$83*(C25*Supuestos!$B$80*'Unit_Economics'!$B$32+Supuestos!$B$81*'Unit_Economics'!$B$32*MIN(H25,SUM(C14:C25))) | N25: =K25+L25+M25-H25*'Unit_Economics'!$B$33 | O25: =N25-Supuestos!$B$72 | P25: =P24+O25
A26: 15 | B26: =ROUND(Supuestos!$B$53*(1+Supuestos!$B$54)^(A26-1),0) | C26: =MAX(0,MIN(B26,ROUNDDOWN(MAX(0,$F$6-((D25+E25+F25)*$F$8+G25*$F$7)/60)/$F$9,0))) | D26: =C26 | E26: =D25*(1-Supuestos!$B$42) | F26: =E25*(1-Supuestos!$B$42) | G26: =(G25+F25)*(1-Supuestos!$B$43) | H26: =D26+E26+F26+G26 | I26: =C26*$F$9+((D26+E26+F26)*$F$8+G26*$F$7)/60 | J26: =H26*'Unit_Economics'!$B$32-C26*'Unit_Economics'!$B$32*Supuestos!$B$44/30 | K26: =J26*(1-Supuestos!$B$45) | L26: =C26*Supuestos!$B$78*Supuestos!$B$79 | M26: =-Supuestos!$B$83*(C26*Supuestos!$B$80*'Unit_Economics'!$B$32+Supuestos!$B$81*'Unit_Economics'!$B$32*MIN(H26,SUM(C15:C26))) | N26: =K26+L26+M26-H26*'Unit_Economics'!$B$33 | O26: =N26-Supuestos!$B$72 | P26: =P25+O26
A27: 16 | B27: =ROUND(Supuestos!$B$53*(1+Supuestos!$B$54)^(A27-1),0) | C27: =MAX(0,MIN(B27,ROUNDDOWN(MAX(0,$F$6-((D26+E26+F26)*$F$8+G26*$F$7)/60)/$F$9,0))) | D27: =C27 | E27: =D26*(1-Supuestos!$B$42) | F27: =E26*(1-Supuestos!$B$42) | G27: =(G26+F26)*(1-Supuestos!$B$43) | H27: =D27+E27+F27+G27 | I27: =C27*$F$9+((D27+E27+F27)*$F$8+G27*$F$7)/60 | J27: =H27*'Unit_Economics'!$B$32-C27*'Unit_Economics'!$B$32*Supuestos!$B$44/30 | K27: =J27*(1-Supuestos!$B$45) | L27: =C27*Supuestos!$B$78*Supuestos!$B$79 | M27: =-Supuestos!$B$83*(C27*Supuestos!$B$80*'Unit_Economics'!$B$32+Supuestos!$B$81*'Unit_Economics'!$B$32*MIN(H27,SUM(C16:C27))) | N27: =K27+L27+M27-H27*'Unit_Economics'!$B$33 | O27: =N27-Supuestos!$B$72 | P27: =P26+O27
A28: 17 | B28: =ROUND(Supuestos!$B$53*(1+Supuestos!$B$54)^(A28-1),0) | C28: =MAX(0,MIN(B28,ROUNDDOWN(MAX(0,$F$6-((D27+E27+F27)*$F$8+G27*$F$7)/60)/$F$9,0))) | D28: =C28 | E28: =D27*(1-Supuestos!$B$42) | F28: =E27*(1-Supuestos!$B$42) | G28: =(G27+F27)*(1-Supuestos!$B$43) | H28: =D28+E28+F28+G28 | I28: =C28*$F$9+((D28+E28+F28)*$F$8+G28*$F$7)/60 | J28: =H28*'Unit_Economics'!$B$32-C28*'Unit_Economics'!$B$32*Supuestos!$B$44/30 | K28: =J28*(1-Supuestos!$B$45) | L28: =C28*Supuestos!$B$78*Supuestos!$B$79 | M28: =-Supuestos!$B$83*(C28*Supuestos!$B$80*'Unit_Economics'!$B$32+Supuestos!$B$81*'Unit_Economics'!$B$32*MIN(H28,SUM(C17:C28))) | N28: =K28+L28+M28-H28*'Unit_Economics'!$B$33 | O28: =N28-Supuestos!$B$72 | P28: =P27+O28
A29: 18 | B29: =ROUND(Supuestos!$B$53*(1+Supuestos!$B$54)^(A29-1),0) | C29: =MAX(0,MIN(B29,ROUNDDOWN(MAX(0,$F$6-((D28+E28+F28)*$F$8+G28*$F$7)/60)/$F$9,0))) | D29: =C29 | E29: =D28*(1-Supuestos!$B$42) | F29: =E28*(1-Supuestos!$B$42) | G29: =(G28+F28)*(1-Supuestos!$B$43) | H29: =D29+E29+F29+G29 | I29: =C29*$F$9+((D29+E29+F29)*$F$8+G29*$F$7)/60 | J29: =H29*'Unit_Economics'!$B$32-C29*'Unit_Economics'!$B$32*Supuestos!$B$44/30 | K29: =J29*(1-Supuestos!$B$45) | L29: =C29*Supuestos!$B$78*Supuestos!$B$79 | M29: =-Supuestos!$B$83*(C29*Supuestos!$B$80*'Unit_Economics'!$B$32+Supuestos!$B$81*'Unit_Economics'!$B$32*MIN(H29,SUM(C18:C29))) | N29: =K29+L29+M29-H29*'Unit_Economics'!$B$33 | O29: =N29-Supuestos!$B$72 | P29: =P28+O29
A30: 19 | B30: =ROUND(Supuestos!$B$53*(1+Supuestos!$B$54)^(A30-1),0) | C30: =MAX(0,MIN(B30,ROUNDDOWN(MAX(0,$F$6-((D29+E29+F29)*$F$8+G29*$F$7)/60)/$F$9,0))) | D30: =C30 | E30: =D29*(1-Supuestos!$B$42) | F30: =E29*(1-Supuestos!$B$42) | G30: =(G29+F29)*(1-Supuestos!$B$43) | H30: =D30+E30+F30+G30 | I30: =C30*$F$9+((D30+E30+F30)*$F$8+G30*$F$7)/60 | J30: =H30*'Unit_Economics'!$B$32-C30*'Unit_Economics'!$B$32*Supuestos!$B$44/30 | K30: =J30*(1-Supuestos!$B$45) | L30: =C30*Supuestos!$B$78*Supuestos!$B$79 | M30: =-Supuestos!$B$83*(C30*Supuestos!$B$80*'Unit_Economics'!$B$32+Supuestos!$B$81*'Unit_Economics'!$B$32*MIN(H30,SUM(C19:C30))) | N30: =K30+L30+M30-H30*'Unit_Economics'!$B$33 | O30: =N30-Supuestos!$B$72 | P30: =P29+O30
A31: 20 | B31: =ROUND(Supuestos!$B$53*(1+Supuestos!$B$54)^(A31-1),0) | C31: =MAX(0,MIN(B31,ROUNDDOWN(MAX(0,$F$6-((D30+E30+F30)*$F$8+G30*$F$7)/60)/$F$9,0))) | D31: =C31 | E31: =D30*(1-Supuestos!$B$42) | F31: =E30*(1-Supuestos!$B$42) | G31: =(G30+F30)*(1-Supuestos!$B$43) | H31: =D31+E31+F31+G31 | I31: =C31*$F$9+((D31+E31+F31)*$F$8+G31*$F$7)/60 | J31: =H31*'Unit_Economics'!$B$32-C31*'Unit_Economics'!$B$32*Supuestos!$B$44/30 | K31: =J31*(1-Supuestos!$B$45) | L31: =C31*Supuestos!$B$78*Supuestos!$B$79 | M31: =-Supuestos!$B$83*(C31*Supuestos!$B$80*'Unit_Economics'!$B$32+Supuestos!$B$81*'Unit_Economics'!$B$32*MIN(H31,SUM(C20:C31))) | N31: =K31+L31+M31-H31*'Unit_Economics'!$B$33 | O31: =N31-Supuestos!$B$72 | P31: =P30+O31
A32: 21 | B32: =ROUND(Supuestos!$B$53*(1+Supuestos!$B$54)^(A32-1),0) | C32: =MAX(0,MIN(B32,ROUNDDOWN(MAX(0,$F$6-((D31+E31+F31)*$F$8+G31*$F$7)/60)/$F$9,0))) | D32: =C32 | E32: =D31*(1-Supuestos!$B$42) | F32: =E31*(1-Supuestos!$B$42) | G32: =(G31+F31)*(1-Supuestos!$B$43) | H32: =D32+E32+F32+G32 | I32: =C32*$F$9+((D32+E32+F32)*$F$8+G32*$F$7)/60 | J32: =H32*'Unit_Economics'!$B$32-C32*'Unit_Economics'!$B$32*Supuestos!$B$44/30 | K32: =J32*(1-Supuestos!$B$45) | L32: =C32*Supuestos!$B$78*Supuestos!$B$79 | M32: =-Supuestos!$B$83*(C32*Supuestos!$B$80*'Unit_Economics'!$B$32+Supuestos!$B$81*'Unit_Economics'!$B$32*MIN(H32,SUM(C21:C32))) | N32: =K32+L32+M32-H32*'Unit_Economics'!$B$33 | O32: =N32-Supuestos!$B$72 | P32: =P31+O32
A33: 22 | B33: =ROUND(Supuestos!$B$53*(1+Supuestos!$B$54)^(A33-1),0) | C33: =MAX(0,MIN(B33,ROUNDDOWN(MAX(0,$F$6-((D32+E32+F32)*$F$8+G32*$F$7)/60)/$F$9,0))) | D33: =C33 | E33: =D32*(1-Supuestos!$B$42) | F33: =E32*(1-Supuestos!$B$42) | G33: =(G32+F32)*(1-Supuestos!$B$43) | H33: =D33+E33+F33+G33 | I33: =C33*$F$9+((D33+E33+F33)*$F$8+G33*$F$7)/60 | J33: =H33*'Unit_Economics'!$B$32-C33*'Unit_Economics'!$B$32*Supuestos!$B$44/30 | K33: =J33*(1-Supuestos!$B$45) | L33: =C33*Supuestos!$B$78*Supuestos!$B$79 | M33: =-Supuestos!$B$83*(C33*Supuestos!$B$80*'Unit_Economics'!$B$32+Supuestos!$B$81*'Unit_Economics'!$B$32*MIN(H33,SUM(C22:C33))) | N33: =K33+L33+M33-H33*'Unit_Economics'!$B$33 | O33: =N33-Supuestos!$B$72 | P33: =P32+O33
A34: 23 | B34: =ROUND(Supuestos!$B$53*(1+Supuestos!$B$54)^(A34-1),0) | C34: =MAX(0,MIN(B34,ROUNDDOWN(MAX(0,$F$6-((D33+E33+F33)*$F$8+G33*$F$7)/60)/$F$9,0))) | D34: =C34 | E34: =D33*(1-Supuestos!$B$42) | F34: =E33*(1-Supuestos!$B$42) | G34: =(G33+F33)*(1-Supuestos!$B$43) | H34: =D34+E34+F34+G34 | I34: =C34*$F$9+((D34+E34+F34)*$F$8+G34*$F$7)/60 | J34: =H34*'Unit_Economics'!$B$32-C34*'Unit_Economics'!$B$32*Supuestos!$B$44/30 | K34: =J34*(1-Supuestos!$B$45) | L34: =C34*Supuestos!$B$78*Supuestos!$B$79 | M34: =-Supuestos!$B$83*(C34*Supuestos!$B$80*'Unit_Economics'!$B$32+Supuestos!$B$81*'Unit_Economics'!$B$32*MIN(H34,SUM(C23:C34))) | N34: =K34+L34+M34-H34*'Unit_Economics'!$B$33 | O34: =N34-Supuestos!$B$72 | P34: =P33+O34
